Workbook

Sheet Overview
A1: EVAL AI (ADEM) — INSTITUTION MARK SHEET OVERVIEW
A2: Academic Year: 2025–2026 | Total Classes: 32 | Total Subjects: 30 | Auto-Consolidated Dashboard
A4: CLASS-WISE CONSOLIDATED PERFORMANCE SUMMARY
A5: S.No | B5: Class / Section | C5: Total Enrolled | D5: Passed | E5: Failed | F5: Pass Percentage | G5: Class Average (%)
A6: 1 | B6: 10-A | C6: =COUNTA('10-A'!C6:C20) | D6: =COUNTIF('10-A'!CR6:CR20, "PASS") | E6: =COUNTIF('10-A'!CR6:CR20, "FAIL") | F6: =IF(C6>0, ROUND((D6/C6)*100, 1), 0) | G6: =IF(C6>0, ROUND(AVERAGE('10-A'!CQ6:CQ20), 1), 0)
A7: 2 | B7: 10-A | C7: =COUNTA('10-A_2'!C6:C20) | D7: =COUNTIF('10-A_2'!CR6:CR20, "PASS") | E7: =COUNTIF('10-A_2'!CR6:CR20, "FAIL") | F7: =IF(C7>0, ROUND((D7/C7)*100, 1), 0) | G7: =IF(C7>0, ROUND(AVERAGE('10-A_2'!CQ6:CQ20), 1), 0)
A8: 3 | B8: 10-B | C8: =COUNTA('10-B'!C6:C20) | D8: =COUNTIF('10-B'!CR6:CR20, "PASS") | E8: =COUNTIF('10-B'!CR6:CR20, "FAIL") | F8: =IF(C8>0, ROUND((D8/C8)*100, 1), 0) | G8: =IF(C8>0, ROUND(AVERAGE('10-B'!CQ6:CQ20), 1), 0)
A9: 4 | B9: 10-B | C9: =COUNTA('10-B_2'!C6:C20) | D9: =COUNTIF('10-B_2'!CR6:CR20, "PASS") | E9: =COUNTIF('10-B_2'!CR6:CR20, "FAIL") | F9: =IF(C9>0, ROUND((D9/C9)*100, 1), 0) | G9: =IF(C9>0, ROUND(AVERAGE('10-B_2'!CQ6:CQ20), 1), 0)
A10: 5 | B10: 11-A | C10: =COUNTA('11-A'!C6:C20) | D10: =COUNTIF('11-A'!CR6:CR20, "PASS") | E10: =COUNTIF('11-A'!CR6:CR20, "FAIL") | F10: =IF(C10>0, ROUND((D10/C10)*100, 1), 0) | G10: =IF(C10>0, ROUND(AVERAGE('11-A'!CQ6:CQ20), 1), 0)
A11: 6 | B11: 11-A | C11: =COUNTA('11-A_2'!C6:C20) | D11: =COUNTIF('11-A_2'!CR6:CR20, "PASS") | E11: =COUNTIF('11-A_2'!CR6:CR20, "FAIL") | F11: =IF(C11>0, ROUND((D11/C11)*100, 1), 0) | G11: =IF(C11>0, ROUND(AVERAGE('11-A_2'!CQ6:CQ20), 1), 0)
A12: 7 | B12: 12-A | C12: =COUNTA('12-A'!C6:C20) | D12: =COUNTIF('12-A'!CR6:CR20, "PASS") | E12: =COUNTIF('12-A'!CR6:CR20, "FAIL") | F12: =IF(C12>0, ROUND((D12/C12)*100, 1), 0) | G12: =IF(C12>0, ROUND(AVERAGE('12-A'!CQ6:CQ20), 1), 0)
A13: 8 | B13: 12-A | C13: =COUNTA('12-A_2'!C6:C20) | D13: =COUNTIF('12-A_2'!CR6:CR20, "PASS") | E13: =COUNTIF('12-A_2'!CR6:CR20, "FAIL") | F13: =IF(C13>0, ROUND((D13/C13)*100, 1), 0) | G13: =IF(C13>0, ROUND(AVERAGE('12-A_2'!CQ6:CQ20), 1), 0)
A14: 9 | B14: 12-B | C14: =COUNTA('12-B'!C6:C20) | D14: =COUNTIF('12-B'!CR6:CR20, "PASS") | E14: =COUNTIF('12-B'!CR6:CR20, "FAIL") | F14: =IF(C14>0, ROUND((D14/C14)*100, 1), 0) | G14: =IF(C14>0, ROUND(AVERAGE('12-B'!CQ6:CQ20), 1), 0)
A15: 10 | B15: 8-A | C15: =COUNTA('8-A'!C6:C20) | D15: =COUNTIF('8-A'!CR6:CR20, "PASS") | E15: =COUNTIF('8-A'!CR6:CR20, "FAIL") | F15: =IF(C15>0, ROUND((D15/C15)*100, 1), 0) | G15: =IF(C15>0, ROUND(AVERAGE('8-A'!CQ6:CQ20), 1), 0)
A16: 11 | B16: 8-A | C16: =COUNTA('8-A_2'!C6:C20) | D16: =COUNTIF('8-A_2'!CR6:CR20, "PASS") | E16: =COUNTIF('8-A_2'!CR6:CR20, "FAIL") | F16: =IF(C16>0, ROUND((D16/C16)*100, 1), 0) | G16: =IF(C16>0, ROUND(AVERAGE('8-A_2'!CQ6:CQ20), 1), 0)
A17: 12 | B17: 8-A | C17: =COUNTA('8-A_3'!C6:C20) | D17: =COUNTIF('8-A_3'!CR6:CR20, "PASS") | E17: =COUNTIF('8-A_3'!CR6:CR20, "FAIL") | F17: =IF(C17>0, ROUND((D17/C17)*100, 1), 0) | G17: =IF(C17>0, ROUND(AVERAGE('8-A_3'!CQ6:CQ20), 1), 0)
A18: 13 | B18: 8-B | C18: =COUNTA('8-B'!C6:C20) | D18: =COUNTIF('8-B'!CR6:CR20, "PASS") | E18: =COUNTIF('8-B'!CR6:CR20, "FAIL") | F18: =IF(C18>0, ROUND((D18/C18)*100, 1), 0) | G18: =IF(C18>0, ROUND(AVERAGE('8-B'!CQ6:CQ20), 1), 0)
A19: 14 | B19: 8-C | C19: =COUNTA('8-C'!C6:C20) | D19: =COUNTIF('8-C'!CR6:CR20, "PASS") | E19: =COUNTIF('8-C'!CR6:CR20, "FAIL") | F19: =IF(C19>0, ROUND((D19/C19)*100, 1), 0) | G19: =IF(C19>0, ROUND(AVERAGE('8-C'!CQ6:CQ20), 1), 0)
A20: 15 | B20: 9-B | C20: =COUNTA('9-B'!C6:C20) | D20: =COUNTIF('9-B'!CR6:CR20, "PASS") | E20: =COUNTIF('9-B'!CR6:CR20, "FAIL") | F20: =IF(C20>0, ROUND((D20/C20)*100, 1), 0) | G20: =IF(C20>0, ROUND(AVERAGE('9-B'!CQ6:CQ20), 1), 0)
A21: 16 | B21: 9-B | C21: =COUNTA('9-B_2'!C6:C20) | D21: =COUNTIF('9-B_2'!CR6:CR20, "PASS") | E21: =COUNTIF('9-B_2'!CR6:CR20, "FAIL") | F21: =IF(C21>0, ROUND((D21/C21)*100, 1), 0) | G21: =IF(C21>0, ROUND(AVERAGE('9-B_2'!CQ6:CQ20), 1), 0)
A22: 17 | B22: 9-B | C22: =COUNTA('9-B_3'!C6:C20) | D22: =COUNTIF('9-B_3'!CR6:CR20, "PASS") | E22: =COUNTIF('9-B_3'!CR6:CR20, "FAIL") | F22: =IF(C22>0, ROUND((D22/C22)*100, 1), 0) | G22: =IF(C22>0, ROUND(AVERAGE('9-B_3'!CQ6:CQ20), 1), 0)
A23: 18 | B23: 9-B | C23: =COUNTA('9-B_4'!C6:C20) | D23: =COUNTIF('9-B_4'!CR6:CR20, "PASS") | E23: =COUNTIF('9-B_4'!CR6:CR20, "FAIL") | F23: =IF(C23>0, ROUND((D23/C23)*100, 1), 0) | G23: =IF(C23>0, ROUND(AVERAGE('9-B_4'!CQ6:CQ20), 1), 0)
A24: 19 | B24: 9-B | C24: =COUNTA('9-B_5'!C6:C20) | D24: =COUNTIF('9-B_5'!CR6:CR20, "PASS") | E24: =COUNTIF('9-B_5'!CR6:CR20, "FAIL") | F24: =IF(C24>0, ROUND((D24/C24)*100, 1), 0) | G24: =IF(C24>0, ROUND(AVERAGE('9-B_5'!CQ6:CQ20), 1), 0)
A25: 20 | B25: 9-B | C25: =COUNTA('9-B_6'!C6:C20) | D25: =COUNTIF('9-B_6'!CR6:CR20, "PASS") | E25: =COUNTIF('9-B_6'!CR6:CR20, "FAIL") | F25: =IF(C25>0, ROUND((D25/C25)*100, 1), 0) | G25: =IF(C25>0, ROUND(AVERAGE('9-B_6'!CQ6:CQ20), 1), 0)
A26: 21 | B26: Class EvalSplit | C26: =COUNTA('Class EvalSplit'!C6:C20) | D26: =COUNTIF('Class EvalSplit'!CR6:CR20, "PASS") | E26: =COUNTIF('Class EvalSplit'!CR6:CR20, "FAIL") | F26: =IF(C26>0, ROUND((D26/C26)*100, 1), 0) | G26: =IF(C26>0, ROUND(AVERAGE('Class EvalSplit'!CQ6:CQ20), 1), 0)
A27: 22 | B27: Class EvalSplit | C27: =COUNTA('Class EvalSplit_2'!C6:C20) | D27: =COUNTIF('Class EvalSplit_2'!CR6:CR20, "PASS") | E27: =COUNTIF('Class EvalSplit_2'!CR6:CR20, "FAIL") | F27: =IF(C27>0, ROUND((D27/C27)*100, 1), 0) | G27: =IF(C27>0, ROUND(AVERAGE('Class EvalSplit_2'!CQ6:CQ20), 1), 0)
A28: 23 | B28: Class SplitKey | C28: =COUNTA('Class SplitKey'!C6:C20) | D28: =COUNTIF('Class SplitKey'!CR6:CR20, "PASS") | E28: =COUNTIF('Class SplitKey'!CR6:CR20, "FAIL") | F28: =IF(C28>0, ROUND((D28/C28)*100, 1), 0) | G28: =IF(C28>0, ROUND(AVERAGE('Class SplitKey'!CQ6:CQ20), 1), 0)
A29: 24 | B29: Class SplitKey | C29: =COUNTA('Class SplitKey_2'!C6:C20) | D29: =COUNTIF('Class SplitKey_2'!CR6:CR20, "PASS") | E29: =COUNTIF('Class SplitKey_2'!CR6:CR20, "FAIL") | F29: =IF(C29>0, ROUND((D29/C29)*100, 1), 0) | G29: =IF(C29>0, ROUND(AVERAGE('Class SplitKey_2'!CQ6:CQ20), 1), 0)
A30: 25 | B30: Grade 10 | C30: =COUNTA('Grade 10'!C6:C20) | D30: =COUNTIF('Grade 10'!CR6:CR20, "PASS") | E30: =COUNTIF('Grade 10'!CR6:CR20, "FAIL") | F30: =IF(C30>0, ROUND((D30/C30)*100, 1), 0) | G30: =IF(C30>0, ROUND(AVERAGE('Grade 10'!CQ6:CQ20), 1), 0)
A31: 26 | B31: Grade 10 | C31: =COUNTA('Grade 10_2'!C6:C20) | D31: =COUNTIF('Grade 10_2'!CR6:CR20, "PASS") | E31: =COUNTIF('Grade 10_2'!CR6:CR20, "FAIL") | F31: =IF(C31>0, ROUND((D31/C31)*100, 1), 0) | G31: =IF(C31>0, ROUND(AVERAGE('Grade 10_2'!CQ6:CQ20), 1), 0)
A32: 27 | B32: Grade 11 | C32: =COUNTA('Grade 11'!C6:C20) | D32: =COUNTIF('Grade 11'!CR6:CR20, "PASS") | E32: =COUNTIF('Grade 11'!CR6:CR20, "FAIL") | F32: =IF(C32>0, ROUND((D32/C32)*100, 1), 0) | G32: =IF(C32>0, ROUND(AVERAGE('Grade 11'!CQ6:CQ20), 1), 0)
A33: 28 | B33: Grade 11 | C33: =COUNTA('Grade 11_2'!C6:C20) | D33: =COUNTIF('Grade 11_2'!CR6:CR20, "PASS") | E33: =COUNTIF('Grade 11_2'!CR6:CR20, "FAIL") | F33: =IF(C33>0, ROUND((D33/C33)*100, 1), 0) | G33: =IF(C33>0, ROUND(AVERAGE('Grade 11_2'!CQ6:CQ20), 1), 0)
A34: 29 | B34: Grade 12 | C34: =COUNTA('Grade 12'!C6:C20) | D34: =COUNTIF('Grade 12'!CR6:CR20, "PASS") | E34: =COUNTIF('Grade 12'!CR6:CR20, "FAIL") | F34: =IF(C34>0, ROUND((D34/C34)*100, 1), 0) | G34: =IF(C34>0, ROUND(AVERAGE('Grade 12'!CQ6:CQ20), 1), 0)
A35: 30 | B35: Grade 12 | C35: =COUNTA('Grade 12_2'!C6:C20) | D35: =COUNTIF('Grade 12_2'!CR6:CR20, "PASS") | E35: =COUNTIF('Grade 12_2'!CR6:CR20, "FAIL") | F35: =IF(C35>0, ROUND((D35/C35)*100, 1), 0) | G35: =IF(C35>0, ROUND(AVERAGE('Grade 12_2'!CQ6:CQ20), 1), 0)
A36: 31 | B36: Grade 9 | C36: =COUNTA('Grade 9'!C6:C20) | D36: =COUNTIF('Grade 9'!CR6:CR20, "PASS") | E36: =COUNTIF('Grade 9'!CR6:CR20, "FAIL") | F36: =IF(C36>0, ROUND((D36/C36)*100, 1), 0) | G36: =IF(C36>0, ROUND(AVERAGE('Grade 9'!CQ6:CQ20), 1), 0)
A37: 32 | B37: Grade 9 | C37: =COUNTA('Grade 9_2'!C6:C20) | D37: =COUNTIF('Grade 9_2'!CR6:CR20, "PASS") | E37: =COUNTIF('Grade 9_2'!CR6:CR20, "FAIL") | F37: =IF(C37>0, ROUND((D37/C37)*100, 1), 0) | G37: =IF(C37>0, ROUND(AVERAGE('Grade 9_2'!CQ6:CQ20), 1), 0)

Sheet 10-A
A1: EVAL AI (ADEM) — 10-A EXAMINATION MARK SHEET
A2: Academic Year: 2025–2026 | Class: 10-A | Total Subjects: 30 | Max Marks: 3000 | Pass: Min 35% in each subject
A4: S.No | B4: Roll No | C4: Student Name | D4: ART (100) | G4: ART (100) | J4: BIOLOGY (100) | M4: BIOLOGY (100) | P4: BIOLOGY (100) | S4: BIOLOGY (100) | V4: BOTANY (100) | Y4: BOTANY (100) | AB4: CHEMISTRY (100) | AE4: CHEMISTRY (100) | AH4: CHEMISTRY (100) | AK4: CHEMISTRY (100) | AN4: ENGLISH (100) | AQ4: HISTORY (100) | AT4: HISTORY (100) | AW4: MATH (100) | AZ4: MATH (100) | BC4: MATHEMATICS (100) | BF4: MATHEMATICS (100) | BI4: MATHS (100) | BL4: MATHS (100) | BO4: PHYSICS (100) | BR4: PHYSICS (100) | BU4: PHYSICS (100) | BX4: PHYSICS (100) | CA4: SUBJECT EVALSPLIT (100) | CD4: SUBJECT EVALSPLIT (100) | CG4: SUBJECT SPLITKEY (100) | CJ4: SUBJECT SPLITKEY (100) | CM4: MATH (100) | CP4: Grand Total (3000) | CQ4: Percentage (%) | CR4: Result | CS4: Grade | CT4: Class Rank
D5: Theory (80) | E5: Internal (20) | F5: Total (100) | G5: Theory (80) | H5: Internal (20) | I5: Total (100) | J5: Theory (80) | K5: Internal (20) | L5: Total (100) | M5: Theory (80) | N5: Internal (20) | O5: Total (100) | P5: Theory (80) | Q5: Internal (20) | R5: Total (100) | S5: Theory (80) | T5: Internal (20) | U5: Total (100) | V5: Theory (80) | W5: Internal (20) | X5: Total (100) | Y5: Theory (80) | Z5: Internal (20) | AA5: Total (100) | AB5: Theory (80) | AC5: Internal (20) | AD5: Total (100) | AE5: Theory (80) | AF5: Internal (20) | AG5: Total (100) | AH5: Theory (80) | AI5: Internal (20) | AJ5: Total (100) | AK5: Theory (80) | AL5: Internal (20) | AM5: Total (100) | AN5: Theory (80) | AO5: Internal (20) | AP5: Total (100) | AQ5: Theory (80) | AR5: Internal (20) | AS5: Total (100) | AT5: Theory (80) | AU5: Internal (20) | AV5: Total (100) | AW5: Theory (80) | AX5: Internal (20) | AY5: Total (100) | AZ5: Theory (80) | BA5: Internal (20) | BB5: Total (100) | BC5: Theory (80) | BD5: Internal (20) | BE5: Total (100) | BF5: Theory (80) | BG5: Internal (20) | BH5: Total (100) | BI5: Theory (80) | BJ5: Internal (20) | BK5: Total (100) | BL5: Theory (80) | BM5: Internal (20) | BN5: Total (100) | BO5: Theory (80) | BP5: Internal (20) | BQ5: Total (100) | BR5: Theory (80) | BS5: Internal (20) | BT5: Total (100) | BU5: Theory (80) | BV5: Internal (20) | BW5: Total (100) | BX5: Theory (80) | BY5: Internal (20) | BZ5: Total (100) | CA5: Theory (80) | CB5: Internal (20) | CC5: Total (100) | CD5: Theory (80) | CE5: Internal (20) | CF5: Total (100) | CG5: Theory (80) | CH5: Internal (20) | CI5: Total (100) | CJ5: Theory (80) | CK5: Internal (20) | CL5: Total (100) | CM5: Theory (80) | CN5: Internal (20) | CO5: Total (100)
A6: 1 | B6: 7 | C6: Asha | F6: =IF(ISBLANK(C6), "", D6+E6) | I6: =IF(ISBLANK(C6), "", G6+H6) | L6: =IF(ISBLANK(C6), "", J6+K6) | M6: 9 | N6: 2 | O6: =IF(ISBLANK(C6), "", M6+N6) | R6: =IF(ISBLANK(C6), "", P6+Q6) | U6: =IF(ISBLANK(C6), "", S6+T6) | X6: =IF(ISBLANK(C6), "", V6+W6) | AA6: =IF(ISBLANK(C6), "", Y6+Z6) | AD6: =IF(ISBLANK(C6), "", AB6+AC6) | AG6: =IF(ISBLANK(C6), "", AE6+AF6) | AJ6: =IF(ISBLANK(C6), "", AH6+AI6) | AM6: =IF(ISBLANK(C6), "", AK6+AL6) | AP6: =IF(ISBLANK(C6), "", AN6+AO6) | AS6: =IF(ISBLANK(C6), "", AQ6+AR6) | AV6: =IF(ISBLANK(C6), "", AT6+AU6) | AY6: =IF(ISBLANK(C6), "", AW6+AX6) | BB6: =IF(ISBLANK(C6), "", AZ6+BA6) | BE6: =IF(ISBLANK(C6), "", BC6+BD6) | BH6: =IF(ISBLANK(C6), "", BF6+BG6) | BK6: =IF(ISBLANK(C6), "", BI6+BJ6) | BN6: =IF(ISBLANK(C6), "", BL6+BM6) | BQ6: =IF(ISBLANK(C6), "", BO6+BP6) | BT6: =IF(ISBLANK(C6), "", BR6+BS6) | BW6: =IF(ISBLANK(C6), "", BU6+BV6) | BZ6: =IF(ISBLANK(C6), "", BX6+BY6) | CC6: =IF(ISBLANK(C6), "", CA6+CB6) | CF6: =IF(ISBLANK(C6), "", CD6+CE6) | CI6: =IF(ISBLANK(C6), "", CG6+CH6) | CL6: =IF(ISBLANK(C6), "", CJ6+CK6) | CO6: =IF(ISBLANK(C6), "", CM6+CN6) | CP6: =IF(ISBLANK(C6), "", F6+I6+L6+O6+R6+U6+X6+AA6+AD6+AG6+AJ6+AM6+AP6+AS6+AV6+AY6+BB6+BE6+BH6+BK6+BN6+BQ6+BT6+BW6+BZ6+CC6+CF6+CI6+CL6+CO6) | CQ6: =IF(OR(ISBLANK(C6), CP6=""), "", ROUND((CP6/3000)*100, 1)) | CR6: =IF(OR(ISBLANK(C6), CP6=""), "", IF(AND(F6>=35, I6>=35, L6>=35, O6>=35, R6>=35, U6>=35, X6>=35, AA6>=35, AD6>=35, AG6>=35, AJ6>=35, AM6>=35, AP6>=35, AS6>=35, AV6>=35, AY6>=35, BB6>=35, BE6>=35, BH6>=35, BK6>=35, BN6>=35, BQ6>=35, BT6>=35, BW6>=35, BZ6>=35, CC6>=35, CF6>=35, CI6>=35, CL6>=35, CO6>=35), "PASS", "FAIL")) | CS6: =IF(OR(ISBLANK(C6), CR6=""), "", IF(CR6="FAIL", "F", IF(CQ6>=90, "A+", IF(CQ6>=80, "A", IF(CQ6>=70, "B", IF(CQ6>=50, "C", "D")))))) | CT6: =IF(OR(ISBLANK(C6), CP6=""), "", RANK(CP6, $CP$6:$CP$20))
F7: =IF(ISBLANK(C7), "", D7+E7) | I7: =IF(ISBLANK(C7), "", G7+H7) | L7: =IF(ISBLANK(C7), "", J7+K7) | O7: =IF(ISBLANK(C7), "", M7+N7) | R7: =IF(ISBLANK(C7), "", P7+Q7) | U7: =IF(ISBLANK(C7), "", S7+T7) | X7: =IF(ISBLANK(C7), "", V7+W7) | AA7: =IF(ISBLANK(C7), "", Y7+Z7) | AD7: =IF(ISBLANK(C7), "", AB7+AC7) | AG7: =IF(ISBLANK(C7), "", AE7+AF7) | AJ7: =IF(ISBLANK(C7), "", AH7+AI7) | AM7: =IF(ISBLANK(C7), "", AK7+AL7) | AP7: =IF(ISBLANK(C7), "", AN7+AO7) | AS7: =IF(ISBLANK(C7), "", AQ7+AR7) | AV7: =IF(ISBLANK(C7), "", AT7+AU7) | AY7: =IF(ISBLANK(C7), "", AW7+AX7) | BB7: =IF(ISBLANK(C7), "", AZ7+BA7) | BE7: =IF(ISBLANK(C7), "", BC7+BD7) | BH7: =IF(ISBLANK(C7), "", BF7+BG7) | BK7: =IF(ISBLANK(C7), "", BI7+BJ7) | BN7: =IF(ISBLANK(C7), "", BL7+BM7) | BQ7: =IF(ISBLANK(C7), "", BO7+BP7) | BT7: =IF(ISBLANK(C7), "", BR7+BS7) | BW7: =IF(ISBLANK(C7), "", BU7+BV7) | BZ7: =IF(ISBLANK(C7), "", BX7+BY7) | CC7: =IF(ISBLANK(C7), "", CA7+CB7) | CF7: =IF(ISBLANK(C7), "", CD7+CE7) | CI7: =IF(ISBLANK(C7), "", CG7+CH7) | CL7: =IF(ISBLANK(C7), "", CJ7+CK7) | CO7: =IF(ISBLANK(C7), "", CM7+CN7) | CP7: =IF(ISBLANK(C7), "", F7+I7+L7+O7+R7+U7+X7+AA7+AD7+AG7+AJ7+AM7+AP7+AS7+AV7+AY7+BB7+BE7+BH7+BK7+BN7+BQ7+BT7+BW7+BZ7+CC7+CF7+CI7+CL7+CO7) | CQ7: =IF(OR(ISBLANK(C7), CP7=""), "", ROUND((CP7/3000)*100, 1)) | CR7: =IF(OR(ISBLANK(C7), CP7=""), "", IF(AND(F7>=35, I7>=35, L7>=35, O7>=35, R7>=35, U7>=35, X7>=35, AA7>=35, AD7>=35, AG7>=35, AJ7>=35, AM7>=35, AP7>=35, AS7>=35, AV7>=35, AY7>=35, BB7>=35, BE7>=35, BH7>=35, BK7>=35, BN7>=35, BQ7>=35, BT7>=35, BW7>=35, BZ7>=35, CC7>=35, CF7>=35, CI7>=35, CL7>=35, CO7>=35), "PASS", "FAIL")) | CS7: =IF(OR(ISBLANK(C7), CR7=""), "", IF(CR7="FAIL", "F", IF(CQ7>=90, "A+", IF(CQ7>=80, "A", IF(CQ7>=70, "B", IF(CQ7>=50, "C", "D")))))) | CT7: =IF(OR(ISBLANK(C7), CP7=""), "", RANK(CP7, $CP$6:$CP$20))
F8: =IF(ISBLANK(C8), "", D8+E8) | I8: =IF(ISBLANK(C8), "", G8+H8) | L8: =IF(ISBLANK(C8), "", J8+K8) | O8: =IF(ISBLANK(C8), "", M8+N8) | R8: =IF(ISBLANK(C8), "", P8+Q8) | U8: =IF(ISBLANK(C8), "", S8+T8) | X8: =IF(ISBLANK(C8), "", V8+W8) | AA8: =IF(ISBLANK(C8), "", Y8+Z8) | AD8: =IF(ISBLANK(C8), "", AB8+AC8) | AG8: =IF(ISBLANK(C8), "", AE8+AF8) | AJ8: =IF(ISBLANK(C8), "", AH8+AI8) | AM8: =IF(ISBLANK(C8), "", AK8+AL8) | AP8: =IF(ISBLANK(C8), "", AN8+AO8) | AS8: =IF(ISBLANK(C8), "", AQ8+AR8) | AV8: =IF(ISBLANK(C8), "", AT8+AU8) | AY8: =IF(ISBLANK(C8), "", AW8+AX8) | BB8: =IF(ISBLANK(C8), "", AZ8+BA8) | BE8: =IF(ISBLANK(C8), "", BC8+BD8) | BH8: =IF(ISBLANK(C8), "", BF8+BG8) | BK8: =IF(ISBLANK(C8), "", BI8+BJ8) | BN8: =IF(ISBLANK(C8), "", BL8+BM8) | BQ8: =IF(ISBLANK(C8), "", BO8+BP8) | BT8: =IF(ISBLANK(C8), "", BR8+BS8) | BW8: =IF(ISBLANK(C8), "", BU8+BV8) | BZ8: =IF(ISBLANK(C8), "", BX8+BY8) | CC8: =IF(ISBLANK(C8), "", CA8+CB8) | CF8: =IF(ISBLANK(C8), "", CD8+CE8) | CI8: =IF(ISBLANK(C8), "", CG8+CH8) | CL8: =IF(ISBLANK(C8), "", CJ8+CK8) | CO8: =IF(ISBLANK(C8), "", CM8+CN8) | CP8: =IF(ISBLANK(C8), "", F8+I8+L8+O8+R8+U8+X8+AA8+AD8+AG8+AJ8+AM8+AP8+AS8+AV8+AY8+BB8+BE8+BH8+BK8+BN8+BQ8+BT8+BW8+BZ8+CC8+CF8+CI8+CL8+CO8) | CQ8: =IF(OR(ISBLANK(C8), CP8=""), "", ROUND((CP8/3000)*100, 1)) | CR8: =IF(OR(ISBLANK(C8), CP8=""), "", IF(AND(F8>=35, I8>=35, L8>=35, O8>=35, R8>=35, U8>=35, X8>=35, AA8>=35, AD8>=35, AG8>=35, AJ8>=35, AM8>=35, AP8>=35, AS8>=35, AV8>=35, AY8>=35, BB8>=35, BE8>=35, BH8>=35, BK8>=35, BN8>=35, BQ8>=35, BT8>=35, BW8>=35, BZ8>=35, CC8>=35, CF8>=35, CI8>=35, CL8>=35, CO8>=35), "PASS", "FAIL")) | CS8: =IF(OR(ISBLANK(C8), CR8=""), "", IF(CR8="FAIL", "F", IF(CQ8>=90, "A+", IF(CQ8>=80, "A", IF(CQ8>=70, "B", IF(CQ8>=50, "C", "D")))))) | CT8: =IF(OR(ISBLANK(C8), CP8=""), "", RANK(CP8, $CP$6:$CP$20))
F9: =IF(ISBLANK(C9), "", D9+E9) | I9: =IF(ISBLANK(C9), "", G9+H9) | L9: =IF(ISBLANK(C9), "", J9+K9) | O9: =IF(ISBLANK(C9), "", M9+N9) | R9: =IF(ISBLANK(C9), "", P9+Q9) | U9: =IF(ISBLANK(C9), "", S9+T9) | X9: =IF(ISBLANK(C9), "", V9+W9) | AA9: =IF(ISBLANK(C9), "", Y9+Z9) | AD9: =IF(ISBLANK(C9), "", AB9+AC9) | AG9: =IF(ISBLANK(C9), "", AE9+AF9) | AJ9: =IF(ISBLANK(C9), "", AH9+AI9) | AM9: =IF(ISBLANK(C9), "", AK9+AL9) | AP9: =IF(ISBLANK(C9), "", AN9+AO9) | AS9: =IF(ISBLANK(C9), "", AQ9+AR9) | AV9: =IF(ISBLANK(C9), "", AT9+AU9) | AY9: =IF(ISBLANK(C9), "", AW9+AX9) | BB9: =IF(ISBLANK(C9), "", AZ9+BA9) | BE9: =IF(ISBLANK(C9), "", BC9+BD9) | BH9: =IF(ISBLANK(C9), "", BF9+BG9) | BK9: =IF(ISBLANK(C9), "", BI9+BJ9) | BN9: =IF(ISBLANK(C9), "", BL9+BM9) | BQ9: =IF(ISBLANK(C9), "", BO9+BP9) | BT9: =IF(ISBLANK(C9), "", BR9+BS9) | BW9: =IF(ISBLANK(C9), "", BU9+BV9) | BZ9: =IF(ISBLANK(C9), "", BX9+BY9) | CC9: =IF(ISBLANK(C9), "", CA9+CB9) | CF9: =IF(ISBLANK(C9), "", CD9+CE9) | CI9: =IF(ISBLANK(C9), "", CG9+CH9) | CL9: =IF(ISBLANK(C9), "", CJ9+CK9) | CO9: =IF(ISBLANK(C9), "", CM9+CN9) | CP9: =IF(ISBLANK(C9), "", F9+I9+L9+O9+R9+U9+X9+AA9+AD9+AG9+AJ9+AM9+AP9+AS9+AV9+AY9+BB9+BE9+BH9+BK9+BN9+BQ9+BT9+BW9+BZ9+CC9+CF9+CI9+CL9+CO9) | CQ9: =IF(OR(ISBLANK(C9), CP9=""), "", ROUND((CP9/3000)*100, 1)) | CR9: =IF(OR(ISBLANK(C9), CP9=""), "", IF(AND(F9>=35, I9>=35, L9>=35, O9>=35, R9>=35, U9>=35, X9>=35, AA9>=35, AD9>=35, AG9>=35, AJ9>=35, AM9>=35, AP9>=35, AS9>=35, AV9>=35, AY9>=35, BB9>=35, BE9>=35, BH9>=35, BK9>=35, BN9>=35, BQ9>=35, BT9>=35, BW9>=35, BZ9>=35, CC9>=35, CF9>=35, CI9>=35, CL9>=35, CO9>=35), "PASS", "FAIL")) | CS9: =IF(OR(ISBLANK(C9), CR9=""), "", IF(CR9="FAIL", "F", IF(CQ9>=90, "A+", IF(CQ9>=80, "A", IF(CQ9>=70, "B", IF(CQ9>=50, "C", "D")))))) | CT9: =IF(OR(ISBLANK(C9), CP9=""), "", RANK(CP9, $CP$6:$CP$20))
F10: =IF(ISBLANK(C10), "", D10+E10) | I10: =IF(ISBLANK(C10), "", G10+H10) | L10: =IF(ISBLANK(C10), "", J10+K10) | O10: =IF(ISBLANK(C10), "", M10+N10) | R10: =IF(ISBLANK(C10), "", P10+Q10) | U10: =IF(ISBLANK(C10), "", S10+T10) | X10: =IF(ISBLANK(C10), "", V10+W10) | AA10: =IF(ISBLANK(C10), "", Y10+Z10) | AD10: =IF(ISBLANK(C10), "", AB10+AC10) | AG10: =IF(ISBLANK(C10), "", AE10+AF10) | AJ10: =IF(ISBLANK(C10), "", AH10+AI10) | AM10: =IF(ISBLANK(C10), "", AK10+AL10) | AP10: =IF(ISBLANK(C10), "", AN10+AO10) | AS10: =IF(ISBLANK(C10), "", AQ10+AR10) | AV10: =IF(ISBLANK(C10), "", AT10+AU10) | AY10: =IF(ISBLANK(C10), "", AW10+AX10) | BB10: =IF(ISBLANK(C10), "", AZ10+BA10) | BE10: =IF(ISBLANK(C10), "", BC10+BD10) | BH10: =IF(ISBLANK(C10), "", BF10+BG10) | BK10: =IF(ISBLANK(C10), "", BI10+BJ10) | BN10: =IF(ISBLANK(C10), "", BL10+BM10) | BQ10: =IF(ISBLANK(C10), "", BO10+BP10) | BT10: =IF(ISBLANK(C10), "", BR10+BS10) | BW10: =IF(ISBLANK(C10), "", BU10+BV10) | BZ10: =IF(ISBLANK(C10), "", BX10+BY10) | CC10: =IF(ISBLANK(C10), "", CA10+CB10) | CF10: =IF(ISBLANK(C10), "", CD10+CE10) | CI10: =IF(ISBLANK(C10), "", CG10+CH10) | CL10: =IF(ISBLANK(C10), "", CJ10+CK10) | CO10: =IF(ISBLANK(C10), "", CM10+CN10) | CP10: =IF(ISBLANK(C10), "", F10+I10+L10+O10+R10+U10+X10+AA10+AD10+AG10+AJ10+AM10+AP10+AS10+AV10+AY10+BB10+BE10+BH10+BK10+BN10+BQ10+BT10+BW10+BZ10+CC10+CF10+CI10+CL10+CO10) | CQ10: =IF(OR(ISBLANK(C10), CP10=""), "", ROUND((CP10/3000)*100, 1)) | CR10: =IF(OR(ISBLANK(C10), CP10=""), "", IF(AND(F10>=35, I10>=35, L10>=35, O10>=35, R10>=35, U10>=35, X10>=35, AA10>=35, AD10>=35, AG10>=35, AJ10>=35, AM10>=35, AP10>=35, AS10>=35, AV10>=35, AY10>=35, BB10>=35, BE10>=35, BH10>=35, BK10>=35, BN10>=35, BQ10>=35, BT10>=35, BW10>=35, BZ10>=35, CC10>=35, CF10>=35, CI10>=35, CL10>=35, CO10>=35), "PASS", "FAIL")) | CS10: =IF(OR(ISBLANK(C10), CR10=""), "", IF(CR10="FAIL", "F", IF(CQ10>=90, "A+", IF(CQ10>=80, "A", IF(CQ10>=70, "B", IF(CQ10>=50, "C", "D")))))) | CT10: =IF(OR(ISBLANK(C10), CP10=""), "", RANK(CP10, $CP$6:$CP$20))
F11: =IF(ISBLANK(C11), "", D11+E11) | I11: =IF(ISBLANK(C11), "", G11+H11) | L11: =IF(ISBLANK(C11), "", J11+K11) | O11: =IF(ISBLANK(C11), "", M11+N11) | R11: =IF(ISBLANK(C11), "", P11+Q11) | U11: =IF(ISBLANK(C11), "", S11+T11) | X11: =IF(ISBLANK(C11), "", V11+W11) | AA11: =IF(ISBLANK(C11), "", Y11+Z11) | AD11: =IF(ISBLANK(C11), "", AB11+AC11) | AG11: =IF(ISBLANK(C11), "", AE11+AF11) | AJ11: =IF(ISBLANK(C11), "", AH11+AI11) | AM11: =IF(ISBLANK(C11), "", AK11+AL11) | AP11: =IF(ISBLANK(C11), "", AN11+AO11) | AS11: =IF(ISBLANK(C11), "", AQ11+AR11) | AV11: =IF(ISBLANK(C11), "", AT11+AU11) | AY11: =IF(ISBLANK(C11), "", AW11+AX11) | BB11: =IF(ISBLANK(C11), "", AZ11+BA11) | BE11: =IF(ISBLANK(C11), "", BC11+BD11) | BH11: =IF(ISBLANK(C11), "", BF11+BG11) | BK11: =IF(ISBLANK(C11), "", BI11+BJ11) | BN11: =IF(ISBLANK(C11), "", BL11+BM11) | BQ11: =IF(ISBLANK(C11), "", BO11+BP11) | BT11: =IF(ISBLANK(C11), "", BR11+BS11) | BW11: =IF(ISBLANK(C11), "", BU11+BV11) | BZ11: =IF(ISBLANK(C11), "", BX11+BY11) | CC11: =IF(ISBLANK(C11), "", CA11+CB11) | CF11: =IF(ISBLANK(C11), "", CD11+CE11) | CI11: =IF(ISBLANK(C11), "", CG11+CH11) | CL11: =IF(ISBLANK(C11), "", CJ11+CK11) | CO11: =IF(ISBLANK(C11), "", CM11+CN11) | CP11: =IF(ISBLANK(C11), "", F11+I11+L11+O11+R11+U11+X11+AA11+AD11+AG11+AJ11+AM11+AP11+AS11+AV11+AY11+BB11+BE11+BH11+BK11+BN11+BQ11+BT11+BW11+BZ11+CC11+CF11+CI11+CL11+CO11) | CQ11: =IF(OR(ISBLANK(C11), CP11=""), "", ROUND((CP11/3000)*100, 1)) | CR11: =IF(OR(ISBLANK(C11), CP11=""), "", IF(AND(F11>=35, I11>=35, L11>=35, O11>=35, R11>=35, U11>=35, X11>=35, AA11>=35, AD11>=35, AG11>=35, AJ11>=35, AM11>=35, AP11>=35, AS11>=35, AV11>=35, AY11>=35, BB11>=35, BE11>=35, BH11>=35, BK11>=35, BN11>=35, BQ11>=35, BT11>=35, BW11>=35, BZ11>=35, CC11>=35, CF11>=35, CI11>=35, CL11>=35, CO11>=35), "PASS", "FAIL")) | CS11: =IF(OR(ISBLANK(C11), CR11=""), "", IF(CR11="FAIL", "F", IF(CQ11>=90, "A+", IF(CQ11>=80, "A", IF(CQ11>=70, "B", IF(CQ11>=50, "C", "D")))))) | CT11: =IF(OR(ISBLANK(C11), CP11=""), "", RANK(CP11, $CP$6:$CP$20))
F12: =IF(ISBLANK(C12), "", D12+E12) | I12: =IF(ISBLANK(C12), "", G12+H12) | L12: =IF(ISBLANK(C12), "", J12+K12) | O12: =IF(ISBLANK(C12), "", M12+N12) | R12: =IF(ISBLANK(C12), "", P12+Q12) | U12: =IF(ISBLANK(C12), "", S12+T12) | X12: =IF(ISBLANK(C12), "", V12+W12) | AA12: =IF(ISBLANK(C12), "", Y12+Z12) | AD12: =IF(ISBLANK(C12), "", AB12+AC12) | AG12: =IF(ISBLANK(C12), "", AE12+AF12) | AJ12: =IF(ISBLANK(C12), "", AH12+AI12) | AM12: =IF(ISBLANK(C12), "", AK12+AL12) | AP12: =IF(ISBLANK(C12), "", AN12+AO12) | AS12: =IF(ISBLANK(C12), "", AQ12+AR12) | AV12: =IF(ISBLANK(C12), "", AT12+AU12) | AY12: =IF(ISBLANK(C12), "", AW12+AX12) | BB12: =IF(ISBLANK(C12), "", AZ12+BA12) | BE12: =IF(ISBLANK(C12), "", BC12+BD12) | BH12: =IF(ISBLANK(C12), "", BF12+BG12) | BK12: =IF(ISBLANK(C12), "", BI12+BJ12) | BN12: =IF(ISBLANK(C12), "", BL12+BM12) | BQ12: =IF(ISBLANK(C12), "", BO12+BP12) | BT12: =IF(ISBLANK(C12), "", BR12+BS12) | BW12: =IF(ISBLANK(C12), "", BU12+BV12) | BZ12: =IF(ISBLANK(C12), "", BX12+BY12) | CC12: =IF(ISBLANK(C12), "", CA12+CB12) | CF12: =IF(ISBLANK(C12), "", CD12+CE12) | CI12: =IF(ISBLANK(C12), "", CG12+CH12) | CL12: =IF(ISBLANK(C12), "", CJ12+CK12) | CO12: =IF(ISBLANK(C12), "", CM12+CN12) | CP12: =IF(ISBLANK(C12), "", F12+I12+L12+O12+R12+U12+X12+AA12+AD12+AG12+AJ12+AM12+AP12+AS12+AV12+AY12+BB12+BE12+BH12+BK12+BN12+BQ12+BT12+BW12+BZ12+CC12+CF12+CI12+CL12+CO12) | CQ12: =IF(OR(ISBLANK(C12), CP12=""), "", ROUND((CP12/3000)*100, 1)) | CR12: =IF(OR(ISBLANK(C12), CP12=""), "", IF(AND(F12>=35, I12>=35, L12>=35, O12>=35, R12>=35, U12>=35, X12>=35, AA12>=35, AD12>=35, AG12>=35, AJ12>=35, AM12>=35, AP12>=35, AS12>=35, AV12>=35, AY12>=35, BB12>=35, BE12>=35, BH12>=35, BK12>=35, BN12>=35, BQ12>=35, BT12>=35, BW12>=35, BZ12>=35, CC12>=35, CF12>=35, CI12>=35, CL12>=35, CO12>=35), "PASS", "FAIL")) | CS12: =IF(OR(ISBLANK(C12), CR12=""), "", IF(CR12="FAIL", "F", IF(CQ12>=90, "A+", IF(CQ12>=80, "A", IF(CQ12>=70, "B", IF(CQ12>=50, "C", "D")))))) | CT12: =IF(OR(ISBLANK(C12), CP12=""), "", RANK(CP12, $CP$6:$CP$20))
F13: =IF(ISBLANK(C13), "", D13+E13) | I13: =IF(ISBLANK(C13), "", G13+H13) | L13: =IF(ISBLANK(C13), "", J13+K13) | O13: =IF(ISBLANK(C13), "", M13+N13) | R13: =IF(ISBLANK(C13), "", P13+Q13) | U13: =IF(ISBLANK(C13), "", S13+T13) | X13: =IF(ISBLANK(C13), "", V13+W13) | AA13: =IF(ISBLANK(C13), "", Y13+Z13) | AD13: =IF(ISBLANK(C13), "", AB13+AC13) | AG13: =IF(ISBLANK(C13), "", AE13+AF13) | AJ13: =IF(ISBLANK(C13), "", AH13+AI13) | AM13: =IF(ISBLANK(C13), "", AK13+AL13) | AP13: =IF(ISBLANK(C13), "", AN13+AO13) | AS13: =IF(ISBLANK(C13), "", AQ13+AR13) | AV13: =IF(ISBLANK(C13), "", AT13+AU13) | AY13: =IF(ISBLANK(C13), "", AW13+AX13) | BB13: =IF(ISBLANK(C13), "", AZ13+BA13) | BE13: =IF(ISBLANK(C13), "", BC13+BD13) | BH13: =IF(ISBLANK(C13), "", BF13+BG13) | BK13: =IF(ISBLANK(C13), "", BI13+BJ13) | BN13: =IF(ISBLANK(C13), "", BL13+BM13) | BQ13: =IF(ISBLANK(C13), "", BO13+BP13) | BT13: =IF(ISBLANK(C13), "", BR13+BS13) | BW13: =IF(ISBLANK(C13), "", BU13+BV13) | BZ13: =IF(ISBLANK(C13), "", BX13+BY13) | CC13: =IF(ISBLANK(C13), "", CA13+CB13) | CF13: =IF(ISBLANK(C13), "", CD13+CE13) | CI13: =IF(ISBLANK(C13), "", CG13+CH13) | CL13: =IF(ISBLANK(C13), "", CJ13+CK13) | CO13: =IF(ISBLANK(C13), "", CM13+CN13) | CP13: =IF(ISBLANK(C13), "", F13+I13+L13+O13+R13+U13+X13+AA13+AD13+AG13+AJ13+AM13+AP13+AS13+AV13+AY13+BB13+BE13+BH13+BK13+BN13+BQ13+BT13+BW13+BZ13+CC13+CF13+CI13+CL13+CO13) | CQ13: =IF(OR(ISBLANK(C13), CP13=""), "", ROUND((CP13/3000)*100, 1)) | CR13: =IF(OR(ISBLANK(C13), CP13=""), "", IF(AND(F13>=35, I13>=35, L13>=35, O13>=35, R13>=35, U13>=35, X13>=35, AA13>=35, AD13>=35, AG13>=35, AJ13>=35, AM13>=35, AP13>=35, AS13>=35, AV13>=35, AY13>=35, BB13>=35, BE13>=35, BH13>=35, BK13>=35, BN13>=35, BQ13>=35, BT13>=35, BW13>=35, BZ13>=35, CC13>=35, CF13>=35, CI13>=35, CL13>=35, CO13>=35), "PASS", "FAIL")) | CS13: =IF(OR(ISBLANK(C13), CR13=""), "", IF(CR13="FAIL", "F", IF(CQ13>=90, "A+", IF(CQ13>=80, "A", IF(CQ13>=70, "B", IF(CQ13>=50, "C", "D")))))) | CT13: =IF(OR(ISBLANK(C13), CP13=""), "", RANK(CP13, $CP$6:$CP$20))
F14: =IF(ISBLANK(C14), "", D14+E14) | I14: =IF(ISBLANK(C14), "", G14+H14) | L14: =IF(ISBLANK(C14), "", J14+K14) | O14: =IF(ISBLANK(C14), "", M14+N14) | R14: =IF(ISBLANK(C14), "", P14+Q14) | U14: =IF(ISBLANK(C14), "", S14+T14) | X14: =IF(ISBLANK(C14), "", V14+W14) | AA14: =IF(ISBLANK(C14), "", Y14+Z14) | AD14: =IF(ISBLANK(C14), "", AB14+AC14) | AG14: =IF(ISBLANK(C14), "", AE14+AF14) | AJ14: =IF(ISBLANK(C14), "", AH14+AI14) | AM14: =IF(ISBLANK(C14), "", AK14+AL14) | AP14: =IF(ISBLANK(C14), "", AN14+AO14) | AS14: =IF(ISBLANK(C14), "", AQ14+AR14) | AV14: =IF(ISBLANK(C14), "", AT14+AU14) | AY14: =IF(ISBLANK(C14), "", AW14+AX14) | BB14: =IF(ISBLANK(C14), "", AZ14+BA14) | BE14: =IF(ISBLANK(C14), "", BC14+BD14) | BH14: =IF(ISBLANK(C14), "", BF14+BG14) | BK14: =IF(ISBLANK(C14), "", BI14+BJ14) | BN14: =IF(ISBLANK(C14), "", BL14+BM14) | BQ14: =IF(ISBLANK(C14), "", BO14+BP14) | BT14: =IF(ISBLANK(C14), "", BR14+BS14) | BW14: =IF(ISBLANK(C14), "", BU14+BV14) | BZ14: =IF(ISBLANK(C14), "", BX14+BY14) | CC14: =IF(ISBLANK(C14), "", CA14+CB14) | CF14: =IF(ISBLANK(C14), "", CD14+CE14) | CI14: =IF(ISBLANK(C14), "", CG14+CH14) | CL14: =IF(ISBLANK(C14), "", CJ14+CK14) | CO14: =IF(ISBLANK(C14), "", CM14+CN14) | CP14: =IF(ISBLANK(C14), "", F14+I14+L14+O14+R14+U14+X14+AA14+AD14+AG14+AJ14+AM14+AP14+AS14+AV14+AY14+BB14+BE14+BH14+BK14+BN14+BQ14+BT14+BW14+BZ14+CC14+CF14+CI14+CL14+CO14) | CQ14: =IF(OR(ISBLANK(C14), CP14=""), "", ROUND((CP14/3000)*100, 1)) | CR14: =IF(OR(ISBLANK(C14), CP14=""), "", IF(AND(F14>=35, I14>=35, L14>=35, O14>=35, R14>=35, U14>=35, X14>=35, AA14>=35, AD14>=35, AG14>=35, AJ14>=35, AM14>=35, AP14>=35, AS14>=35, AV14>=35, AY14>=35, BB14>=35, BE14>=35, BH14>=35, BK14>=35, BN14>=35, BQ14>=35, BT14>=35, BW14>=35, BZ14>=35, CC14>=35, CF14>=35, CI14>=35, CL14>=35, CO14>=35), "PASS", "FAIL")) | CS14: =IF(OR(ISBLANK(C14), CR14=""), "", IF(CR14="FAIL", "F", IF(CQ14>=90, "A+", IF(CQ14>=80, "A", IF(CQ14>=70, "B", IF(CQ14>=50, "C", "D")))))) | CT14: =IF(OR(ISBLANK(C14), CP14=""), "", RANK(CP14, $CP$6:$CP$20))
F15: =IF(ISBLANK(C15), "", D15+E15) | I15: =IF(ISBLANK(C15), "", G15+H15) | L15: =IF(ISBLANK(C15), "", J15+K15) | O15: =IF(ISBLANK(C15), "", M15+N15) | R15: =IF(ISBLANK(C15), "", P15+Q15) | U15: =IF(ISBLANK(C15), "", S15+T15) | X15: =IF(ISBLANK(C15), "", V15+W15) | AA15: =IF(ISBLANK(C15), "", Y15+Z15) | AD15: =IF(ISBLANK(C15), "", AB15+AC15) | AG15: =IF(ISBLANK(C15), "", AE15+AF15) | AJ15: =IF(ISBLANK(C15), "", AH15+AI15) | AM15: =IF(ISBLANK(C15), "", AK15+AL15) | AP15: =IF(ISBLANK(C15), "", AN15+AO15) | AS15: =IF(ISBLANK(C15), "", AQ15+AR15) | AV15: =IF(ISBLANK(C15), "", AT15+AU15) | AY15: =IF(ISBLANK(C15), "", AW15+AX15) | BB15: =IF(ISBLANK(C15), "", AZ15+BA15) | BE15: =IF(ISBLANK(C15), "", BC15+BD15) | BH15: =IF(ISBLANK(C15), "", BF15+BG15) | BK15: =IF(ISBLANK(C15), "", BI15+BJ15) | BN15: =IF(ISBLANK(C15), "", BL15+BM15) | BQ15: =IF(ISBLANK(C15), "", BO15+BP15) | BT15: =IF(ISBLANK(C15), "", BR15+BS15) | BW15: =IF(ISBLANK(C15), "", BU15+BV15) | BZ15: =IF(ISBLANK(C15), "", BX15+BY15) | CC15: =IF(ISBLANK(C15), "", CA15+CB15) | CF15: =IF(ISBLANK(C15), "", CD15+CE15) | CI15: =IF(ISBLANK(C15), "", CG15+CH15) | CL15: =IF(ISBLANK(C15), "", CJ15+CK15) | CO15: =IF(ISBLANK(C15), "", CM15+CN15) | CP15: =IF(ISBLANK(C15), "", F15+I15+L15+O15+R15+U15+X15+AA15+AD15+AG15+AJ15+AM15+AP15+AS15+AV15+AY15+BB15+BE15+BH15+BK15+BN15+BQ15+BT15+BW15+BZ15+CC15+CF15+CI15+CL15+CO15) | CQ15: =IF(OR(ISBLANK(C15), CP15=""), "", ROUND((CP15/3000)*100, 1)) | CR15: =IF(OR(ISBLANK(C15), CP15=""), "", IF(AND(F15>=35, I15>=35, L15>=35, O15>=35, R15>=35, U15>=35, X15>=35, AA15>=35, AD15>=35, AG15>=35, AJ15>=35, AM15>=35, AP15>=35, AS15>=35, AV15>=35, AY15>=35, BB15>=35, BE15>=35, BH15>=35, BK15>=35, BN15>=35, BQ15>=35, BT15>=35, BW15>=35, BZ15>=35, CC15>=35, CF15>=35, CI15>=35, CL15>=35, CO15>=35), "PASS", "FAIL")) | CS15: =IF(OR(ISBLANK(C15), CR15=""), "", IF(CR15="FAIL", "F", IF(CQ15>=90, "A+", IF(CQ15>=80, "A", IF(CQ15>=70, "B", IF(CQ15>=50, "C", "D")))))) | CT15: =IF(OR(ISBLANK(C15), CP15=""), "", RANK(CP15, $CP$6:$CP$20))
F16: =IF(ISBLANK(C16), "", D16+E16) | I16: =IF(ISBLANK(C16), "", G16+H16) | L16: =IF(ISBLANK(C16), "", J16+K16) | O16: =IF(ISBLANK(C16), "", M16+N16) | R16: =IF(ISBLANK(C16), "", P16+Q16) | U16: =IF(ISBLANK(C16), "", S16+T16) | X16: =IF(ISBLANK(C16), "", V16+W16) | AA16: =IF(ISBLANK(C16), "", Y16+Z16) | AD16: =IF(ISBLANK(C16), "", AB16+AC16) | AG16: =IF(ISBLANK(C16), "", AE16+AF16) | AJ16: =IF(ISBLANK(C16), "", AH16+AI16) | AM16: =IF(ISBLANK(C16), "", AK16+AL16) | AP16: =IF(ISBLANK(C16), "", AN16+AO16) | AS16: =IF(ISBLANK(C16), "", AQ16+AR16) | AV16: =IF(ISBLANK(C16), "", AT16+AU16) | AY16: =IF(ISBLANK(C16), "", AW16+AX16) | BB16: =IF(ISBLANK(C16), "", AZ16+BA16) | BE16: =IF(ISBLANK(C16), "", BC16+BD16) | BH16: =IF(ISBLANK(C16), "", BF16+BG16) | BK16: =IF(ISBLANK(C16), "", BI16+BJ16) | BN16: =IF(ISBLANK(C16), "", BL16+BM16) | BQ16: =IF(ISBLANK(C16), "", BO16+BP16) | BT16: =IF(ISBLANK(C16), "", BR16+BS16) | BW16: =IF(ISBLANK(C16), "", BU16+BV16) | BZ16: =IF(ISBLANK(C16), "", BX16+BY16) | CC16: =IF(ISBLANK(C16), "", CA16+CB16) | CF16: =IF(ISBLANK(C16), "", CD16+CE16) | CI16: =IF(ISBLANK(C16), "", CG16+CH16) | CL16: =IF(ISBLANK(C16), "", CJ16+CK16) | CO16: =IF(ISBLANK(C16), "", CM16+CN16) | CP16: =IF(ISBLANK(C16), "", F16+I16+L16+O16+R16+U16+X16+AA16+AD16+AG16+AJ16+AM16+AP16+AS16+AV16+AY16+BB16+BE16+BH16+BK16+BN16+BQ16+BT16+BW16+BZ16+CC16+CF16+CI16+CL16+CO16) | CQ16: =IF(OR(ISBLANK(C16), CP16=""), "", ROUND((CP16/3000)*100, 1)) | CR16: =IF(OR(ISBLANK(C16), CP16=""), "", IF(AND(F16>=35, I16>=35, L16>=35, O16>=35, R16>=35, U16>=35, X16>=35, AA16>=35, AD16>=35, AG16>=35, AJ16>=35, AM16>=35, AP16>=35, AS16>=35, AV16>=35, AY16>=35, BB16>=35, BE16>=35, BH16>=35, BK16>=35, BN16>=35, BQ16>=35, BT16>=35, BW16>=35, BZ16>=35, CC16>=35, CF16>=35, CI16>=35, CL16>=35, CO16>=35), "PASS", "FAIL")) | CS16: =IF(OR(ISBLANK(C16), CR16=""), "", IF(CR16="FAIL", "F", IF(CQ16>=90, "A+", IF(CQ16>=80, "A", IF(CQ16>=70, "B", IF(CQ16>=50, "C", "D")))))) | CT16: =IF(OR(ISBLANK(C16), CP16=""), "", RANK(CP16, $CP$6:$CP$20))
F17: =IF(ISBLANK(C17), "", D17+E17) | I17: =IF(ISBLANK(C17), "", G17+H17) | L17: =IF(ISBLANK(C17), "", J17+K17) | O17: =IF(ISBLANK(C17), "", M17+N17) | R17: =IF(ISBLANK(C17), "", P17+Q17) | U17: =IF(ISBLANK(C17), "", S17+T17) | X17: =IF(ISBLANK(C17), "", V17+W17) | AA17: =IF(ISBLANK(C17), "", Y17+Z17) | AD17: =IF(ISBLANK(C17), "", AB17+AC17) | AG17: =IF(ISBLANK(C17), "", AE17+AF17) | AJ17: =IF(ISBLANK(C17), "", AH17+AI17) | AM17: =IF(ISBLANK(C17), "", AK17+AL17) | AP17: =IF(ISBLANK(C17), "", AN17+AO17) | AS17: =IF(ISBLANK(C17), "", AQ17+AR17) | AV17: =IF(ISBLANK(C17), "", AT17+AU17) | AY17: =IF(ISBLANK(C17), "", AW17+AX17) | BB17: =IF(ISBLANK(C17), "", AZ17+BA17) | BE17: =IF(ISBLANK(C17), "", BC17+BD17) | BH17: =IF(ISBLANK(C17), "", BF17+BG17) | BK17: =IF(ISBLANK(C17), "", BI17+BJ17) | BN17: =IF(ISBLANK(C17), "", BL17+BM17) | BQ17: =IF(ISBLANK(C17), "", BO17+BP17) | BT17: =IF(ISBLANK(C17), "", BR17+BS17) | BW17: =IF(ISBLANK(C17), "", BU17+BV17) | BZ17: =IF(ISBLANK(C17), "", BX17+BY17) | CC17: =IF(ISBLANK(C17), "", CA17+CB17) | CF17: =IF(ISBLANK(C17), "", CD17+CE17) | CI17: =IF(ISBLANK(C17), "", CG17+CH17) | CL17: =IF(ISBLANK(C17), "", CJ17+CK17) | CO17: =IF(ISBLANK(C17), "", CM17+CN17) | CP17: =IF(ISBLANK(C17), "", F17+I17+L17+O17+R17+U17+X17+AA17+AD17+AG17+AJ17+AM17+AP17+AS17+AV17+AY17+BB17+BE17+BH17+BK17+BN17+BQ17+BT17+BW17+BZ17+CC17+CF17+CI17+CL17+CO17) | CQ17: =IF(OR(ISBLANK(C17), CP17=""), "", ROUND((CP17/3000)*100, 1)) | CR17: =IF(OR(ISBLANK(C17), CP17=""), "", IF(AND(F17>=35, I17>=35, L17>=35, O17>=35, R17>=35, U17>=35, X17>=35, AA17>=35, AD17>=35, AG17>=35, AJ17>=35, AM17>=35, AP17>=35, AS17>=35, AV17>=35, AY17>=35, BB17>=35, BE17>=35, BH17>=35, BK17>=35, BN17>=35, BQ17>=35, BT17>=35, BW17>=35, BZ17>=35, CC17>=35, CF17>=35, CI17>=35, CL17>=35, CO17>=35), "PASS", "FAIL")) | CS17: =IF(OR(ISBLANK(C17), CR17=""), "", IF(CR17="FAIL", "F", IF(CQ17>=90, "A+", IF(CQ17>=80, "A", IF(CQ17>=70, "B", IF(CQ17>=50, "C", "D")))))) | CT17: =IF(OR(ISBLANK(C17), CP17=""), "", RANK(CP17, $CP$6:$CP$20))
F18: =IF(ISBLANK(C18), "", D18+E18) | I18: =IF(ISBLANK(C18), "", G18+H18) | L18: =IF(ISBLANK(C18), "", J18+K18) | O18: =IF(ISBLANK(C18), "", M18+N18) | R18: =IF(ISBLANK(C18), "", P18+Q18) | U18: =IF(ISBLANK(C18), "", S18+T18) | X18: =IF(ISBLANK(C18), "", V18+W18) | AA18: =IF(ISBLANK(C18), "", Y18+Z18) | AD18: =IF(ISBLANK(C18), "", AB18+AC18) | AG18: =IF(ISBLANK(C18), "", AE18+AF18) | AJ18: =IF(ISBLANK(C18), "", AH18+AI18) | AM18: =IF(ISBLANK(C18), "", AK18+AL18) | AP18: =IF(ISBLANK(C18), "", AN18+AO18) | AS18: =IF(ISBLANK(C18), "", AQ18+AR18) | AV18: =IF(ISBLANK(C18), "", AT18+AU18) | AY18: =IF(ISBLANK(C18), "", AW18+AX18) | BB18: =IF(ISBLANK(C18), "", AZ18+BA18) | BE18: =IF(ISBLANK(C18), "", BC18+BD18) | BH18: =IF(ISBLANK(C18), "", BF18+BG18) | BK18: =IF(ISBLANK(C18), "", BI18+BJ18) | BN18: =IF(ISBLANK(C18), "", BL18+BM18) | BQ18: =IF(ISBLANK(C18), "", BO18+BP18) | BT18: =IF(ISBLANK(C18), "", BR18+BS18) | BW18: =IF(ISBLANK(C18), "", BU18+BV18) | BZ18: =IF(ISBLANK(C18), "", BX18+BY18) | CC18: =IF(ISBLANK(C18), "", CA18+CB18) | CF18: =IF(ISBLANK(C18), "", CD18+CE18) | CI18: =IF(ISBLANK(C18), "", CG18+CH18) | CL18: =IF(ISBLANK(C18), "", CJ18+CK18) | CO18: =IF(ISBLANK(C18), "", CM18+CN18) | CP18: =IF(ISBLANK(C18), "", F18+I18+L18+O18+R18+U18+X18+AA18+AD18+AG18+AJ18+AM18+AP18+AS18+AV18+AY18+BB18+BE18+BH18+BK18+BN18+BQ18+BT18+BW18+BZ18+CC18+CF18+CI18+CL18+CO18) | CQ18: =IF(OR(ISBLANK(C18), CP18=""), "", ROUND((CP18/3000)*100, 1)) | CR18: =IF(OR(ISBLANK(C18), CP18=""), "", IF(AND(F18>=35, I18>=35, L18>=35, O18>=35, R18>=35, U18>=35, X18>=35, AA18>=35, AD18>=35, AG18>=35, AJ18>=35, AM18>=35, AP18>=35, AS18>=35, AV18>=35, AY18>=35, BB18>=35, BE18>=35, BH18>=35, BK18>=35, BN18>=35, BQ18>=35, BT18>=35, BW18>=35, BZ18>=35, CC18>=35, CF18>=35, CI18>=35, CL18>=35, CO18>=35), "PASS", "FAIL")) | CS18: =IF(OR(ISBLANK(C18), CR18=""), "", IF(CR18="FAIL", "F", IF(CQ18>=90, "A+", IF(CQ18>=80, "A", IF(CQ18>=70, "B", IF(CQ18>=50, "C", "D")))))) | CT18: =IF(OR(ISBLANK(C18), CP18=""), "", RANK(CP18, $CP$6:$CP$20))
... F20: =IF(ISBLANK(C20), "", D20+E20) | I20: =IF(ISBLANK(C20), "", G20+H20) | L20: =IF(ISBLANK(C20), "", J20+K20) | O20: =IF(ISBLANK(C20), "", M20+N20) | R20: =IF(ISBLANK(C20), "", P20+Q20) | U20: =IF(ISBLANK(C20), "", S20+T20) | X20: =IF(ISBLANK(C20), "", V20+W20) | AA20: =IF(ISBLANK(C20), "", Y20+Z20) | AD20: =IF(ISBLANK(C20), "", AB20+AC20) | AG20: =IF(ISBLANK(C20), "", AE20+AF20) | AJ20: =IF(ISBLANK(C20), "", AH20+AI20) | AM20: =IF(ISBLANK(C20), "", AK20+AL20) | AP20: =IF(ISBLANK(C20), "", AN20+AO20) | AS20: =IF(ISBLANK(C20), "", AQ20+AR20) | AV20: =IF(ISBLANK(C20), "", AT20+AU20) | AY20: =IF(ISBLANK(C20), "", AW20+AX20) | BB20: =IF(ISBLANK(C20), "", AZ20+BA20) | BE20: =IF(ISBLANK(C20), "", BC20+BD20) | BH20: =IF(ISBLANK(C20), "", BF20+BG20) | BK20: =IF(ISBLANK(C20), "", BI20+BJ20) | BN20: =IF(ISBLANK(C20), "", BL20+BM20) | BQ20: =IF(ISBLANK(C20), "", BO20+BP20) | BT20: =IF(ISBLANK(C20), "", BR20+BS20) | BW20: =IF(ISBLANK(C20), "", BU20+BV20) | BZ20: =IF(ISBLANK(C20), "", BX20+BY20) | CC20: =IF(ISBLANK(C20), "", CA20+CB20) | CF20: =IF(ISBLANK(C20), "", CD20+CE20) | CI20: =IF(ISBLANK(C20), "", CG20+CH20) | CL20: =IF(ISBLANK(C20), "", CJ20+CK20) | CO20: =IF(ISBLANK(C20), "", CM20+CN20) | CP20: =IF(ISBLANK(C20), "", F20+I20+L20+O20+R20+U20+X20+AA20+AD20+AG20+AJ20+AM20+AP20+AS20+AV20+AY20+BB20+BE20+BH20+BK20+BN20+BQ20+BT20+BW20+BZ20+CC20+CF20+CI20+CL20+CO20) | CQ20: =IF(OR(ISBLANK(C20), CP20=""), "", ROUND((CP20/3000)*100, 1)) | CR20: =IF(OR(ISBLANK(C20), CP20=""), "", IF(AND(F20>=35, I20>=35, L20>=35, O20>=35, R20>=35, U20>=35, X20>=35, AA20>=35, AD20>=35, AG20>=35, AJ20>=35, AM20>=35, AP20>=35, AS20>=35, AV20>=35, AY20>=35, BB20>=35, BE20>=35, BH20>=35, BK20>=35, BN20>=35, BQ20>=35, BT20>=35, BW20>=35, BZ20>=35, CC20>=35, CF20>=35, CI20>=35, CL20>=35, CO20>=35), "PASS", "FAIL")) | CS20: =IF(OR(ISBLANK(C20), CR20=""), "", IF(CR20="FAIL", "F", IF(CQ20>=90, "A+", IF(CQ20>=80, "A", IF(CQ20>=70, "B", IF(CQ20>=50, "C", "D")))))) | CT20: =IF(OR(ISBLANK(C20), CP20=""), "", RANK(CP20, $CP$6:$CP$20))
A23: CLASS AVERAGE | D23: =IF(COUNTA(C6:C20)>0, ROUND(AVERAGE(F6:F20), 1), "-") | G23: =IF(COUNTA(C6:C20)>0, ROUND(AVERAGE(I6:I20), 1), "-") | J23: =IF(COUNTA(C6:C20)>0, ROUND(AVERAGE(L6:L20), 1), "-") | M23: =IF(COUNTA(C6:C20)>0, ROUND(AVERAGE(O6:O20), 1), "-") | P23: =IF(COUNTA(C6:C20)>0, ROUND(AVERAGE(R6:R20), 1), "-") | S23: =IF(COUNTA(C6:C20)>0, ROUND(AVERAGE(U6:U20), 1), "-") | V23: =IF(COUNTA(C6:C20)>0, ROUND(AVERAGE(X6:X20), 1), "-") | Y23: =IF(COUNTA(C6:C20)>0, ROUND(AVERAGE(AA6:AA20), 1), "-") | AB23: =IF(COUNTA(C6:C20)>0, ROUND(AVERAGE(AD6:AD20), 1), "-") | AE23: =IF(COUNTA(C6:C20)>0, ROUND(AVERAGE(AG6:AG20), 1), "-") | AH23: =IF(COUNTA(C6:C20)>0, ROUND(AVERAGE(AJ6:AJ20), 1), "-") | AK23: =IF(COUNTA(C6:C20)>0, ROUND(AVERAGE(AM6:AM20), 1), "-") | AN23: =IF(COUNTA(C6:C20)>0, ROUND(AVERAGE(AP6:AP20), 1), "-") | AQ23: =IF(COUNTA(C6:C20)>0, ROUND(AVERAGE(AS6:AS20), 1), "-") | AT23: =IF(COUNTA(C6:C20)>0, ROUND(AVERAGE(AV6:AV20), 1), "-") | AW23: =IF(COUNTA(C6:C20)>0, ROUND(AVERAGE(AY6:AY20), 1), "-") | AZ23: =IF(COUNTA(C6:C20)>0, ROUND(AVERAGE(BB6:BB20), 1), "-") | BC23: =IF(COUNTA(C6:C20)>0, ROUND(AVERAGE(BE6:BE20), 1), "-") | BF23: =IF(COUNTA(C6:C20)>0, ROUND(AVERAGE(BH6:BH20), 1), "-") | BI23: =IF(COUNTA(C6:C20)>0, ROUND(AVERAGE(BK6:BK20), 1), "-") | BL23: =IF(COUNTA(C6:C20)>0, ROUND(AVERAGE(BN6:BN20), 1), "-") | BO23: =IF(COUNTA(C6:C20)>0, ROUND(AVERAGE(BQ6:BQ20), 1), "-") | BR23: =IF(COUNTA(C6:C20)>0, ROUND(AVERAGE(BT6:BT20), 1), "-") | BU23: =IF(COUNTA(C6:C20)>0, ROUND(AVERAGE(BW6:BW20), 1), "-") | BX23: =IF(COUNTA(C6:C20)>0, ROUND(AVERAGE(BZ6:BZ20), 1), "-") | CA23: =IF(COUNTA(C6:C20)>0, ROUND(AVERAGE(CC6:CC20), 1), "-") | CD23: =IF(COUNTA(C6:C20)>0, ROUND(AVERAGE(CF6:CF20), 1), "-") | CG23: =IF(COUNTA(C6:C20)>0, ROUND(AVERAGE(CI6:CI20), 1), "-") | CJ23: =IF(COUNTA(C6:C20)>0, ROUND(AVERAGE(CL6:CL20), 1), "-") | CM23: =IF(COUNTA(C6:C20)>0, ROUND(AVERAGE(CO6:CO20), 1), "-") | CP23: =IF(COUNTA(C6:C20)>0, ROUND(AVERAGE(CP6:CP20), 1), "-") | CQ23: =IF(COUNTA(C6:C20)>0, ROUND(AVERAGE(CQ6:CQ20), 1), "-")
A24: HIGHEST MARKS | D24: =IF(COUNTA(C6:C20)>0, MAX(F6:F20), "-") | G24: =IF(COUNTA(C6:C20)>0, MAX(I6:I20), "-") | J24: =IF(COUNTA(C6:C20)>0, MAX(L6:L20), "-") | M24: =IF(COUNTA(C6:C20)>0, MAX(O6:O20), "-") | P24: =IF(COUNTA(C6:C20)>0, MAX(R6:R20), "-") | S24: =IF(COUNTA(C6:C20)>0, MAX(U6:U20), "-") | V24: =IF(COUNTA(C6:C20)>0, MAX(X6:X20), "-") | Y24: =IF(COUNTA(C6:C20)>0, MAX(AA6:AA20), "-") | AB24: =IF(COUNTA(C6:C20)>0, MAX(AD6:AD20), "-") | AE24: =IF(COUNTA(C6:C20)>0, MAX(AG6:AG20), "-") | AH24: =IF(COUNTA(C6:C20)>0, MAX(AJ6:AJ20), "-") | AK24: =IF(COUNTA(C6:C20)>0, MAX(AM6:AM20), "-") | AN24: =IF(COUNTA(C6:C20)>0, MAX(AP6:AP20), "-") | AQ24: =IF(COUNTA(C6:C20)>0, MAX(AS6:AS20), "-") | AT24: =IF(COUNTA(C6:C20)>0, MAX(AV6:AV20), "-") | AW24: =IF(COUNTA(C6:C20)>0, MAX(AY6:AY20), "-") | AZ24: =IF(COUNTA(C6:C20)>0, MAX(BB6:BB20), "-") | BC24: =IF(COUNTA(C6:C20)>0, MAX(BE6:BE20), "-") | BF24: =IF(COUNTA(C6:C20)>0, MAX(BH6:BH20), "-") | BI24: =IF(COUNTA(C6:C20)>0, MAX(BK6:BK20), "-") | BL24: =IF(COUNTA(C6:C20)>0, MAX(BN6:BN20), "-") | BO24: =IF(COUNTA(C6:C20)>0, MAX(BQ6:BQ20), "-") | BR24: =IF(COUNTA(C6:C20)>0, MAX(BT6:BT20), "-") | BU24: =IF(COUNTA(C6:C20)>0, MAX(BW6:BW20), "-") | BX24: =IF(COUNTA(C6:C20)>0, MAX(BZ6:BZ20), "-") | CA24: =IF(COUNTA(C6:C20)>0, MAX(CC6:CC20), "-") | CD24: =IF(COUNTA(C6:C20)>0, MAX(CF6:CF20), "-") | CG24: =IF(COUNTA(C6:C20)>0, MAX(CI6:CI20), "-") | CJ24: =IF(COUNTA(C6:C20)>0, MAX(CL6:CL20), "-") | CM24: =IF(COUNTA(C6:C20)>0, MAX(CO6:CO20), "-") | CP24: =IF(COUNTA(C6:C20)>0, MAX(CP6:CP20), "-") | CQ24: =IF(COUNTA(C6:C20)>0, MAX(CQ6:CQ20), "-")
A25: LOWEST MARKS | D25: =IF(COUNTA(C6:C20)>0, MIN(F6:F20), "-") | G25: =IF(COUNTA(C6:C20)>0, MIN(I6:I20), "-") | J25: =IF(COUNTA(C6:C20)>0, MIN(L6:L20), "-") | M25: =IF(COUNTA(C6:C20)>0, MIN(O6:O20), "-") | P25: =IF(COUNTA(C6:C20)>0, MIN(R6:R20), "-") | S25: =IF(COUNTA(C6:C20)>0, MIN(U6:U20), "-") | V25: =IF(COUNTA(C6:C20)>0, MIN(X6:X20), "-") | Y25: =IF(COUNTA(C6:C20)>0, MIN(AA6:AA20), "-") | AB25: =IF(COUNTA(C6:C20)>0, MIN(AD6:AD20), "-") | AE25: =IF(COUNTA(C6:C20)>0, MIN(AG6:AG20), "-") | AH25: =IF(COUNTA(C6:C20)>0, MIN(AJ6:AJ20), "-") | AK25: =IF(COUNTA(C6:C20)>0, MIN(AM6:AM20), "-") | AN25: =IF(COUNTA(C6:C20)>0, MIN(AP6:AP20), "-") | AQ25: =IF(COUNTA(C6:C20)>0, MIN(AS6:AS20), "-") | AT25: =IF(COUNTA(C6:C20)>0, MIN(AV6:AV20), "-") | AW25: =IF(COUNTA(C6:C20)>0, MIN(AY6:AY20), "-") | AZ25: =IF(COUNTA(C6:C20)>0, MIN(BB6:BB20), "-") | BC25: =IF(COUNTA(C6:C20)>0, MIN(BE6:BE20), "-") | BF25: =IF(COUNTA(C6:C20)>0, MIN(BH6:BH20), "-") | BI25: =IF(COUNTA(C6:C20)>0, MIN(BK6:BK20), "-") | BL25: =IF(COUNTA(C6:C20)>0, MIN(BN6:BN20), "-") | BO25: =IF(COUNTA(C6:C20)>0, MIN(BQ6:BQ20), "-") | BR25: =IF(COUNTA(C6:C20)>0, MIN(BT6:BT20), "-") | BU25: =IF(COUNTA(C6:C20)>0, MIN(BW6:BW20), "-") | BX25: =IF(COUNTA(C6:C20)>0, MIN(BZ6:BZ20), "-") | CA25: =IF(COUNTA(C6:C20)>0, MIN(CC6:CC20), "-") | CD25: =IF(COUNTA(C6:C20)>0, MIN(CF6:CF20), "-") | CG25: =IF(COUNTA(C6:C20)>0, MIN(CI6:CI20), "-") | CJ25: =IF(COUNTA(C6:C20)>0, MIN(CL6:CL20), "-") | CM25: =IF(COUNTA(C6:C20)>0, MIN(CO6:CO20), "-") | CP25: =IF(COUNTA(C6:C20)>0, MIN(CP6:CP20), "-") | CQ25: =IF(COUNTA(C6:C20)>0, MIN(CQ6:CQ20), "-")
A26: TOTAL PASSED | D26: =COUNTIF(F6:F20, ">=35") | G26: =COUNTIF(I6:I20, ">=35") | J26: =COUNTIF(L6:L20, ">=35") | M26: =COUNTIF(O6:O20, ">=35") | P26: =COUNTIF(R6:R20, ">=35") | S26: =COUNTIF(U6:U20, ">=35") | V26: =COUNTIF(X6:X20, ">=35") | Y26: =COUNTIF(AA6:AA20, ">=35") | AB26: =COUNTIF(AD6:AD20, ">=35") | AE26: =COUNTIF(AG6:AG20, ">=35") | AH26: =COUNTIF(AJ6:AJ20, ">=35") | AK26: =COUNTIF(AM6:AM20, ">=35") | AN26: =COUNTIF(AP6:AP20, ">=35") | AQ26: =COUNTIF(AS6:AS20, ">=35") | AT26: =COUNTIF(AV6:AV20, ">=35") | AW26: =COUNTIF(AY6:AY20, ">=35") | AZ26: =COUNTIF(BB6:BB20, ">=35") | BC26: =COUNTIF(BE6:BE20, ">=35") | BF26: =COUNTIF(BH6:BH20, ">=35") | BI26: =COUNTIF(BK6:BK20, ">=35") | BL26: =COUNTIF(BN6:BN20, ">=35") | BO26: =COUNTIF(BQ6:BQ20, ">=35") | BR26: =COUNTIF(BT6:BT20, ">=35") | BU26: =COUNTIF(BW6:BW20, ">=35") | BX26: =COUNTIF(BZ6:BZ20, ">=35") | CA26: =COUNTIF(CC6:CC20, ">=35") | CD26: =COUNTIF(CF6:CF20, ">=35") | CG26: =COUNTIF(CI6:CI20, ">=35") | CJ26: =COUNTIF(CL6:CL20, ">=35") | CM26: =COUNTIF(CO6:CO20, ">=35") | CP26: =COUNTIF(CR6:CR20, "PASS")
A27: PASS PERCENTAGE (%) | D27: =IF(COUNTA(C6:C20)>0, ROUND((D26/COUNTA(C6:C20))*100, 1), "-") | G27: =IF(COUNTA(C6:C20)>0, ROUND((G26/COUNTA(C6:C20))*100, 1), "-") | J27: =IF(COUNTA(C6:C20)>0, ROUND((J26/COUNTA(C6:C20))*100, 1), "-") | M27: =IF(COUNTA(C6:C20)>0, ROUND((M26/COUNTA(C6:C20))*100, 1), "-") | P27: =IF(COUNTA(C6:C20)>0, ROUND((P26/COUNTA(C6:C20))*100, 1), "-") | S27: =IF(COUNTA(C6:C20)>0, ROUND((S26/COUNTA(C6:C20))*100, 1), "-") | V27: =IF(COUNTA(C6:C20)>0, ROUND((V26/COUNTA(C6:C20))*100, 1), "-") | Y27: =IF(COUNTA(C6:C20)>0, ROUND((Y26/COUNTA(C6:C20))*100, 1), "-") | AB27: =IF(COUNTA(C6:C20)>0, ROUND((AB26/COUNTA(C6:C20))*100, 1), "-") | AE27: =IF(COUNTA(C6:C20)>0, ROUND((AE26/COUNTA(C6:C20))*100, 1), "-") | AH27: =IF(COUNTA(C6:C20)>0, ROUND((AH26/COUNTA(C6:C20))*100, 1), "-") | AK27: =IF(COUNTA(C6:C20)>0, ROUND((AK26/COUNTA(C6:C20))*100, 1), "-") | AN27: =IF(COUNTA(C6:C20)>0, ROUND((AN26/COUNTA(C6:C20))*100, 1), "-") | AQ27: =IF(COUNTA(C6:C20)>0, ROUND((AQ26/COUNTA(C6:C20))*100, 1), "-") | AT27: =IF(COUNTA(C6:C20)>0, ROUND((AT26/COUNTA(C6:C20))*100, 1), "-") | AW27: =IF(COUNTA(C6:C20)>0, ROUND((AW26/COUNTA(C6:C20))*100, 1), "-") | AZ27: =IF(COUNTA(C6:C20)>0, ROUND((AZ26/COUNTA(C6:C20))*100, 1), "-") | BC27: =IF(COUNTA(C6:C20)>0, ROUND((BC26/COUNTA(C6:C20))*100, 1), "-") | BF27: =IF(COUNTA(C6:C20)>0, ROUND((BF26/COUNTA(C6:C20))*100, 1), "-") | BI27: =IF(COUNTA(C6:C20)>0, ROUND((BI26/COUNTA(C6:C20))*100, 1), "-") | BL27: =IF(COUNTA(C6:C20)>0, ROUND((BL26/COUNTA(C6:C20))*100, 1), "-") | BO27: =IF(COUNTA(C6:C20)>0, ROUND((BO26/COUNTA(C6:C20))*100, 1), "-") | BR27: =IF(COUNTA(C6:C20)>0, ROUND((BR26/COUNTA(C6:C20))*100, 1), "-") | BU27: =IF(COUNTA(C6:C20)>0, ROUND((BU26/COUNTA(C6:C20))*100, 1), "-") | BX27: =IF(COUNTA(C6:C20)>0, ROUND((BX26/COUNTA(C6:C20))*100, 1), "-") | CA27: =IF(COUNTA(C6:C20)>0, ROUND((CA26/COUNTA(C6:C20))*100, 1), "-") | CD27: =IF(COUNTA(C6:C20)>0, ROUND((CD26/COUNTA(C6:C20))*100, 1), "-") | CG27: =IF(COUNTA(C6:C20)>0, ROUND((CG26/COUNTA(C6:C20))*100, 1), "-") | CJ27: =IF(COUNTA(C6:C20)>0, ROUND((CJ26/COUNTA(C6:C20))*100, 1), "-") | CM27: =IF(COUNTA(C6:C20)>0, ROUND((CM26/COUNTA(C6:C20))*100, 1), "-") | CP27: =IF(COUNTA(C6:C20)>0, ROUND((CP26/COUNTA(C6:C20))*100, 1), "-")

Sheet 10-A_2
A1: EVAL AI (ADEM) — 10-A EXAMINATION MARK SHEET
A2: Academic Year: 2025–2026 | Class: 10-A | Total Subjects: 30 | Max Marks: 3000 | Pass: Min 35% in each subject
A4: S.No | B4: Roll No | C4: Student Name | D4: ART (100) | G4: ART (100) | J4: BIOLOGY (100) | M4: BIOLOGY (100) | P4: BIOLOGY (100) | S4: BIOLOGY (100) | V4: BOTANY (100) | Y4: BOTANY (100) | AB4: CHEMISTRY (100) | AE4: CHEMISTRY (100) | AH4: CHEMISTRY (100) | AK4: CHEMISTRY (100) | AN4: ENGLISH (100) | AQ4: HISTORY (100) | AT4: HISTORY (100) | AW4: MATH (100) | AZ4: MATH (100) | BC4: MATHEMATICS (100) | BF4: MATHEMATICS (100) | BI4: MATHS (100) | BL4: MATHS (100) | BO4: PHYSICS (100) | BR4: PHYSICS (100) | BU4: PHYSICS (100) | BX4: PHYSICS (100) | CA4: SUBJECT EVALSPLIT (100) | CD4: SUBJECT EVALSPLIT (100) | CG4: SUBJECT SPLITKEY (100) | CJ4: SUBJECT SPLITKEY (100) | CM4: MATH (100) | CP4: Grand Total (3000) | CQ4: Percentage (%) | CR4: Result | CS4: Grade | CT4: Class Rank
D5: Theory (80) | E5: Internal (20) | F5: Total (100) | G5: Theory (80) | H5: Internal (20) | I5: Total (100) | J5: Theory (80) | K5: Internal (20) | L5: Total (100) | M5: Theory (80) | N5: Internal (20) | O5: Total (100) | P5: Theory (80) | Q5: Internal (20) | R5: Total (100) | S5: Theory (80) | T5: Internal (20) | U5: Total (100) | V5: Theory (80) | W5: Internal (20) | X5: Total (100) | Y5: Theory (80) | Z5: Internal (20) | AA5: Total (100) | AB5: Theory (80) | AC5: Internal (20) | AD5: Total (100) | AE5: Theory (80) | AF5: Internal (20) | AG5: Total (100) | AH5: Theory (80) | AI5: Internal (20) | AJ5: Total (100) | AK5: Theory (80) | AL5: Internal (20) | AM5: Total (100) | AN5: Theory (80) | AO5: Internal (20) | AP5: Total (100) | AQ5: Theory (80) | AR5: Internal (20) | AS5: Total (100) | AT5: Theory (80) | AU5: Internal (20) | AV5: Total (100) | AW5: Theory (80) | AX5: Internal (20) | AY5: Total (100) | AZ5: Theory (80) | BA5: Internal (20) | BB5: Total (100) | BC5: Theory (80) | BD5: Internal (20) | BE5: Total (100) | BF5: Theory (80) | BG5: Internal (20) | BH5: Total (100) | BI5: Theory (80) | BJ5: Internal (20) | BK5: Total (100) | BL5: Theory (80) | BM5: Internal (20) | BN5: Total (100) | BO5: Theory (80) | BP5: Internal (20) | BQ5: Total (100) | BR5: Theory (80) | BS5: Internal (20) | BT5: Total (100) | BU5: Theory (80) | BV5: Internal (20) | BW5: Total (100) | BX5: Theory (80) | BY5: Internal (20) | BZ5: Total (100) | CA5: Theory (80) | CB5: Internal (20) | CC5: Total (100) | CD5: Theory (80) | CE5: Internal (20) | CF5: Total (100) | CG5: Theory (80) | CH5: Internal (20) | CI5: Total (100) | CJ5: Theory (80) | CK5: Internal (20) | CL5: Total (100) | CM5: Theory (80) | CN5: Internal (20) | CO5: Total (100)
A6: 1 | B6: 7 | C6: Asha | F6: =IF(ISBLANK(C6), "", D6+E6) | I6: =IF(ISBLANK(C6), "", G6+H6) | L6: =IF(ISBLANK(C6), "", J6+K6) | O6: =IF(ISBLANK(C6), "", M6+N6) | R6: =IF(ISBLANK(C6), "", P6+Q6) | S6: 9 | T6: 2 | U6: =IF(ISBLANK(C6), "", S6+T6) | X6: =IF(ISBLANK(C6), "", V6+W6) | AA6: =IF(ISBLANK(C6), "", Y6+Z6) | AD6: =IF(ISBLANK(C6), "", AB6+AC6) | AG6: =IF(ISBLANK(C6), "", AE6+AF6) | AJ6: =IF(ISBLANK(C6), "", AH6+AI6) | AM6: =IF(ISBLANK(C6), "", AK6+AL6) | AP6: =IF(ISBLANK(C6), "", AN6+AO6) | AS6: =IF(ISBLANK(C6), "", AQ6+AR6) | AV6: =IF(ISBLANK(C6), "", AT6+AU6) | AY6: =IF(ISBLANK(C6), "", AW6+AX6) | BB6: =IF(ISBLANK(C6), "", AZ6+BA6) | BE6: =IF(ISBLANK(C6), "", BC6+BD6) | BH6: =IF(ISBLANK(C6), "", BF6+BG6) | BK6: =IF(ISBLANK(C6), "", BI6+BJ6) | BN6: =IF(ISBLANK(C6), "", BL6+BM6) | BQ6: =IF(ISBLANK(C6), "", BO6+BP6) | BT6: =IF(ISBLANK(C6), "", BR6+BS6) | BW6: =IF(ISBLANK(C6), "", BU6+BV6) | BZ6: =IF(ISBLANK(C6), "", BX6+BY6) | CC6: =IF(ISBLANK(C6), "", CA6+CB6) | CF6: =IF(ISBLANK(C6), "", CD6+CE6) | CI6: =IF(ISBLANK(C6), "", CG6+CH6) | CL6: =IF(ISBLANK(C6), "", CJ6+CK6) | CO6: =IF(ISBLANK(C6), "", CM6+CN6) | CP6: =IF(ISBLANK(C6), "", F6+I6+L6+O6+R6+U6+X6+AA6+AD6+AG6+AJ6+AM6+AP6+AS6+AV6+AY6+BB6+BE6+BH6+BK6+BN6+BQ6+BT6+BW6+BZ6+CC6+CF6+CI6+CL6+CO6) | CQ6: =IF(OR(ISBLANK(C6), CP6=""), "", ROUND((CP6/3000)*100, 1)) | CR6: =IF(OR(ISBLANK(C6), CP6=""), "", IF(AND(F6>=35, I6>=35, L6>=35, O6>=35, R6>=35, U6>=35, X6>=35, AA6>=35, AD6>=35, AG6>=35, AJ6>=35, AM6>=35, AP6>=35, AS6>=35, AV6>=35, AY6>=35, BB6>=35, BE6>=35, BH6>=35, BK6>=35, BN6>=35, BQ6>=35, BT6>=35, BW6>=35, BZ6>=35, CC6>=35, CF6>=35, CI6>=35, CL6>=35, CO6>=35), "PASS", "FAIL")) | CS6: =IF(OR(ISBLANK(C6), CR6=""), "", IF(CR6="FAIL", "F", IF(CQ6>=90, "A+", IF(CQ6>=80, "A", IF(CQ6>=70, "B", IF(CQ6>=50, "C", "D")))))) | CT6: =IF(OR(ISBLANK(C6), CP6=""), "", RANK(CP6, $CP$6:$CP$20))
F7: =IF(ISBLANK(C7), "", D7+E7) | I7: =IF(ISBLANK(C7), "", G7+H7) | L7: =IF(ISBLANK(C7), "", J7+K7) | O7: =IF(ISBLANK(C7), "", M7+N7) | R7: =IF(ISBLANK(C7), "", P7+Q7) | U7: =IF(ISBLANK(C7), "", S7+T7) | X7: =IF(ISBLANK(C7), "", V7+W7) | AA7: =IF(ISBLANK(C7), "", Y7+Z7) | AD7: =IF(ISBLANK(C7), "", AB7+AC7) | AG7: =IF(ISBLANK(C7), "", AE7+AF7) | AJ7: =IF(ISBLANK(C7), "", AH7+AI7) | AM7: =IF(ISBLANK(C7), "", AK7+AL7) | AP7: =IF(ISBLANK(C7), "", AN7+AO7) | AS7: =IF(ISBLANK(C7), "", AQ7+AR7) | AV7: =IF(ISBLANK(C7), "", AT7+AU7) | AY7: =IF(ISBLANK(C7), "", AW7+AX7) | BB7: =IF(ISBLANK(C7), "", AZ7+BA7) | BE7: =IF(ISBLANK(C7), "", BC7+BD7) | BH7: =IF(ISBLANK(C7), "", BF7+BG7) | BK7: =IF(ISBLANK(C7), "", BI7+BJ7) | BN7: =IF(ISBLANK(C7), "", BL7+BM7) | BQ7: =IF(ISBLANK(C7), "", BO7+BP7) | BT7: =IF(ISBLANK(C7), "", BR7+BS7) | BW7: =IF(ISBLANK(C7), "", BU7+BV7) | BZ7: =IF(ISBLANK(C7), "", BX7+BY7) | CC7: =IF(ISBLANK(C7), "", CA7+CB7) | CF7: =IF(ISBLANK(C7), "", CD7+CE7) | CI7: =IF(ISBLANK(C7), "", CG7+CH7) | CL7: =IF(ISBLANK(C7), "", CJ7+CK7) | CO7: =IF(ISBLANK(C7), "", CM7+CN7) | CP7: =IF(ISBLANK(C7), "", F7+I7+L7+O7+R7+U7+X7+AA7+AD7+AG7+AJ7+AM7+AP7+AS7+AV7+AY7+BB7+BE7+BH7+BK7+BN7+BQ7+BT7+BW7+BZ7+CC7+CF7+CI7+CL7+CO7) | CQ7: =IF(OR(ISBLANK(C7), CP7=""), "", ROUND((CP7/3000)*100, 1)) | CR7: =IF(OR(ISBLANK(C7), CP7=""), "", IF(AND(F7>=35, I7>=35, L7>=35, O7>=35, R7>=35, U7>=35, X7>=35, AA7>=35, AD7>=35, AG7>=35, AJ7>=35, AM7>=35, AP7>=35, AS7>=35, AV7>=35, AY7>=35, BB7>=35, BE7>=35, BH7>=35, BK7>=35, BN7>=35, BQ7>=35, BT7>=35, BW7>=35, BZ7>=35, CC7>=35, CF7>=35, CI7>=35, CL7>=35, CO7>=35), "PASS", "FAIL")) | CS7: =IF(OR(ISBLANK(C7), CR7=""), "", IF(CR7="FAIL", "F", IF(CQ7>=90, "A+", IF(CQ7>=80, "A", IF(CQ7>=70, "B", IF(CQ7>=50, "C", "D")))))) | CT7: =IF(OR(ISBLANK(C7), CP7=""), "", RANK(CP7, $CP$6:$CP$20))
F8: =IF(ISBLANK(C8), "", D8+E8) | I8: =IF(ISBLANK(C8), "", G8+H8) | L8: =IF(ISBLANK(C8), "", J8+K8) | O8: =IF(ISBLANK(C8), "", M8+N8) | R8: =IF(ISBLANK(C8), "", P8+Q8) | U8: =IF(ISBLANK(C8), "", S8+T8) | X8: =IF(ISBLANK(C8), "", V8+W8) | AA8: =IF(ISBLANK(C8), "", Y8+Z8) | AD8: =IF(ISBLANK(C8), "", AB8+AC8) | AG8: =IF(ISBLANK(C8), "", AE8+AF8) | AJ8: =IF(ISBLANK(C8), "", AH8+AI8) | AM8: =IF(ISBLANK(C8), "", AK8+AL8) | AP8: =IF(ISBLANK(C8), "", AN8+AO8) | AS8: =IF(ISBLANK(C8), "", AQ8+AR8) | AV8: =IF(ISBLANK(C8), "", AT8+AU8) | AY8: =IF(ISBLANK(C8), "", AW8+AX8) | BB8: =IF(ISBLANK(C8), "", AZ8+BA8) | BE8: =IF(ISBLANK(C8), "", BC8+BD8) | BH8: =IF(ISBLANK(C8), "", BF8+BG8) | BK8: =IF(ISBLANK(C8), "", BI8+BJ8) | BN8: =IF(ISBLANK(C8), "", BL8+BM8) | BQ8: =IF(ISBLANK(C8), "", BO8+BP8) | BT8: =IF(ISBLANK(C8), "", BR8+BS8) | BW8: =IF(ISBLANK(C8), "", BU8+BV8) | BZ8: =IF(ISBLANK(C8), "", BX8+BY8) | CC8: =IF(ISBLANK(C8), "", CA8+CB8) | CF8: =IF(ISBLANK(C8), "", CD8+CE8) | CI8: =IF(ISBLANK(C8), "", CG8+CH8) | CL8: =IF(ISBLANK(C8), "", CJ8+CK8) | CO8: =IF(ISBLANK(C8), "", CM8+CN8) | CP8: =IF(ISBLANK(C8), "", F8+I8+L8+O8+R8+U8+X8+AA8+AD8+AG8+AJ8+AM8+AP8+AS8+AV8+AY8+BB8+BE8+BH8+BK8+BN8+BQ8+BT8+BW8+BZ8+CC8+CF8+CI8+CL8+CO8) | CQ8: =IF(OR(ISBLANK(C8), CP8=""), "", ROUND((CP8/3000)*100, 1)) | CR8: =IF(OR(ISBLANK(C8), CP8=""), "", IF(AND(F8>=35, I8>=35, L8>=35, O8>=35, R8>=35, U8>=35, X8>=35, AA8>=35, AD8>=35, AG8>=35, AJ8>=35, AM8>=35, AP8>=35, AS8>=35, AV8>=35, AY8>=35, BB8>=35, BE8>=35, BH8>=35, BK8>=35, BN8>=35, BQ8>=35, BT8>=35, BW8>=35, BZ8>=35, CC8>=35, CF8>=35, CI8>=35, CL8>=35, CO8>=35), "PASS", "FAIL")) | CS8: =IF(OR(ISBLANK(C8), CR8=""), "", IF(CR8="FAIL", "F", IF(CQ8>=90, "A+", IF(CQ8>=80, "A", IF(CQ8>=70, "B", IF(CQ8>=50, "C", "D")))))) | CT8: =IF(OR(ISBLANK(C8), CP8=""), "", RANK(CP8, $CP$6:$CP$20))
F9: =IF(ISBLANK(C9), "", D9+E9) | I9: =IF(ISBLANK(C9), "", G9+H9) | L9: =IF(ISBLANK(C9), "", J9+K9) | O9: =IF(ISBLANK(C9), "", M9+N9) | R9: =IF(ISBLANK(C9), "", P9+Q9) | U9: =IF(ISBLANK(C9), "", S9+T9) | X9: =IF(ISBLANK(C9), "", V9+W9) | AA9: =IF(ISBLANK(C9), "", Y9+Z9) | AD9: =IF(ISBLANK(C9), "", AB9+AC9) | AG9: =IF(ISBLANK(C9), "", AE9+AF9) | AJ9: =IF(ISBLANK(C9), "", AH9+AI9) | AM9: =IF(ISBLANK(C9), "", AK9+AL9) | AP9: =IF(ISBLANK(C9), "", AN9+AO9) | AS9: =IF(ISBLANK(C9), "", AQ9+AR9) | AV9: =IF(ISBLANK(C9), "", AT9+AU9) | AY9: =IF(ISBLANK(C9), "", AW9+AX9) | BB9: =IF(ISBLANK(C9), "", AZ9+BA9) | BE9: =IF(ISBLANK(C9), "", BC9+BD9) | BH9: =IF(ISBLANK(C9), "", BF9+BG9) | BK9: =IF(ISBLANK(C9), "", BI9+BJ9) | BN9: =IF(ISBLANK(C9), "", BL9+BM9) | BQ9: =IF(ISBLANK(C9), "", BO9+BP9) | BT9: =IF(ISBLANK(C9), "", BR9+BS9) | BW9: =IF(ISBLANK(C9), "", BU9+BV9) | BZ9: =IF(ISBLANK(C9), "", BX9+BY9) | CC9: =IF(ISBLANK(C9), "", CA9+CB9) | CF9: =IF(ISBLANK(C9), "", CD9+CE9) | CI9: =IF(ISBLANK(C9), "", CG9+CH9) | CL9: =IF(ISBLANK(C9), "", CJ9+CK9) | CO9: =IF(ISBLANK(C9), "", CM9+CN9) | CP9: =IF(ISBLANK(C9), "", F9+I9+L9+O9+R9+U9+X9+AA9+AD9+AG9+AJ9+AM9+AP9+AS9+AV9+AY9+BB9+BE9+BH9+BK9+BN9+BQ9+BT9+BW9+BZ9+CC9+CF9+CI9+CL9+CO9) | CQ9: =IF(OR(ISBLANK(C9), CP9=""), "", ROUND((CP9/3000)*100, 1)) | CR9: =IF(OR(ISBLANK(C9), CP9=""), "", IF(AND(F9>=35, I9>=35, L9>=35, O9>=35, R9>=35, U9>=35, X9>=35, AA9>=35, AD9>=35, AG9>=35, AJ9>=35, AM9>=35, AP9>=35, AS9>=35, AV9>=35, AY9>=35, BB9>=35, BE9>=35, BH9>=35, BK9>=35, BN9>=35, BQ9>=35, BT9>=35, BW9>=35, BZ9>=35, CC9>=35, CF9>=35, CI9>=35, CL9>=35, CO9>=35), "PASS", "FAIL")) | CS9: =IF(OR(ISBLANK(C9), CR9=""), "", IF(CR9="FAIL", "F", IF(CQ9>=90, "A+", IF(CQ9>=80, "A", IF(CQ9>=70, "B", IF(CQ9>=50, "C", "D")))))) | CT9: =IF(OR(ISBLANK(C9), CP9=""), "", RANK(CP9, $CP$6:$CP$20))
F10: =IF(ISBLANK(C10), "", D10+E10) | I10: =IF(ISBLANK(C10), "", G10+H10) | L10: =IF(ISBLANK(C10), "", J10+K10) | O10: =IF(ISBLANK(C10), "", M10+N10) | R10: =IF(ISBLANK(C10), "", P10+Q10) | U10: =IF(ISBLANK(C10), "", S10+T10) | X10: =IF(ISBLANK(C10), "", V10+W10) | AA10: =IF(ISBLANK(C10), "", Y10+Z10) | AD10: =IF(ISBLANK(C10), "", AB10+AC10) | AG10: =IF(ISBLANK(C10), "", AE10+AF10) | AJ10: =IF(ISBLANK(C10), "", AH10+AI10) | AM10: =IF(ISBLANK(C10), "", AK10+AL10) | AP10: =IF(ISBLANK(C10), "", AN10+AO10) | AS10: =IF(ISBLANK(C10), "", AQ10+AR10) | AV10: =IF(ISBLANK(C10), "", AT10+AU10) | AY10: =IF(ISBLANK(C10), "", AW10+AX10) | BB10: =IF(ISBLANK(C10), "", AZ10+BA10) | BE10: =IF(ISBLANK(C10), "", BC10+BD10) | BH10: =IF(ISBLANK(C10), "", BF10+BG10) | BK10: =IF(ISBLANK(C10), "", BI10+BJ10) | BN10: =IF(ISBLANK(C10), "", BL10+BM10) | BQ10: =IF(ISBLANK(C10), "", BO10+BP10) | BT10: =IF(ISBLANK(C10), "", BR10+BS10) | BW10: =IF(ISBLANK(C10), "", BU10+BV10) | BZ10: =IF(ISBLANK(C10), "", BX10+BY10) | CC10: =IF(ISBLANK(C10), "", CA10+CB10) | CF10: =IF(ISBLANK(C10), "", CD10+CE10) | CI10: =IF(ISBLANK(C10), "", CG10+CH10) | CL10: =IF(ISBLANK(C10), "", CJ10+CK10) | CO10: =IF(ISBLANK(C10), "", CM10+CN10) | CP10: =IF(ISBLANK(C10), "", F10+I10+L10+O10+R10+U10+X10+AA10+AD10+AG10+AJ10+AM10+AP10+AS10+AV10+AY10+BB10+BE10+BH10+BK10+BN10+BQ10+BT10+BW10+BZ10+CC10+CF10+CI10+CL10+CO10) | CQ10: =IF(OR(ISBLANK(C10), CP10=""), "", ROUND((CP10/3000)*100, 1)) | CR10: =IF(OR(ISBLANK(C10), CP10=""), "", IF(AND(F10>=35, I10>=35, L10>=35, O10>=35, R10>=35, U10>=35, X10>=35, AA10>=35, AD10>=35, AG10>=35, AJ10>=35, AM10>=35, AP10>=35, AS10>=35, AV10>=35, AY10>=35, BB10>=35, BE10>=35, BH10>=35, BK10>=35, BN10>=35, BQ10>=35, BT10>=35, BW10>=35, BZ10>=35, CC10>=35, CF10>=35, CI10>=35, CL10>=35, CO10>=35), "PASS", "FAIL")) | CS10: =IF(OR(ISBLANK(C10), CR10=""), "", IF(CR10="FAIL", "F", IF(CQ10>=90, "A+", IF(CQ10>=80, "A", IF(CQ10>=70, "B", IF(CQ10>=50, "C", "D")))))) | CT10: =IF(OR(ISBLANK(C10), CP10=""), "", RANK(CP10, $CP$6:$CP$20))
