Workbook

Sheet Overview
A1: EVAL AI (ADEM) — INSTITUTION MARK SHEET OVERVIEW
A2: Academic Year: 2025–2026 | Total Classes: 6 | Total Subjects: 6 | Auto-Consolidated Dashboard
A4: CLASS-WISE CONSOLIDATED PERFORMANCE SUMMARY
A5: S.No | B5: Class / Section | C5: Total Enrolled | D5: Passed | E5: Failed | F5: Pass Percentage | G5: Class Average (%)
A6: 1 | B6: Grade 10 | C6: =COUNTA('Grade 10'!C6:C20) | D6: =COUNTIF('Grade 10'!X6:X20, "PASS") | E6: =COUNTIF('Grade 10'!X6:X20, "FAIL") | F6: =IF(C6>0, ROUND((D6/C6)*100, 1), 0) | G6: =IF(C6>0, ROUND(AVERAGE('Grade 10'!W6:W20), 1), 0)
A7: 2 | B7: Grade 11 | C7: =COUNTA('Grade 11'!C6:C20) | D7: =COUNTIF('Grade 11'!X6:X20, "PASS") | E7: =COUNTIF('Grade 11'!X6:X20, "FAIL") | F7: =IF(C7>0, ROUND((D7/C7)*100, 1), 0) | G7: =IF(C7>0, ROUND(AVERAGE('Grade 11'!W6:W20), 1), 0)
A8: 3 | B8: Grade 11 | C8: =COUNTA('Grade 11_2'!C6:C20) | D8: =COUNTIF('Grade 11_2'!X6:X20, "PASS") | E8: =COUNTIF('Grade 11_2'!X6:X20, "FAIL") | F8: =IF(C8>0, ROUND((D8/C8)*100, 1), 0) | G8: =IF(C8>0, ROUND(AVERAGE('Grade 11_2'!W6:W20), 1), 0)
A9: 4 | B9: Grade 12 | C9: =COUNTA('Grade 12'!C6:C20) | D9: =COUNTIF('Grade 12'!X6:X20, "PASS") | E9: =COUNTIF('Grade 12'!X6:X20, "FAIL") | F9: =IF(C9>0, ROUND((D9/C9)*100, 1), 0) | G9: =IF(C9>0, ROUND(AVERAGE('Grade 12'!W6:W20), 1), 0)
A10: 5 | B10: Grade 9 | C10: =COUNTA('Grade 9'!C6:C20) | D10: =COUNTIF('Grade 9'!X6:X20, "PASS") | E10: =COUNTIF('Grade 9'!X6:X20, "FAIL") | F10: =IF(C10>0, ROUND((D10/C10)*100, 1), 0) | G10: =IF(C10>0, ROUND(AVERAGE('Grade 9'!W6:W20), 1), 0)
A11: 6 | B11: Grade 9 | C11: =COUNTA('Grade 9_2'!C6:C20) | D11: =COUNTIF('Grade 9_2'!X6:X20, "PASS") | E11: =COUNTIF('Grade 9_2'!X6:X20, "FAIL") | F11: =IF(C11>0, ROUND((D11/C11)*100, 1), 0) | G11: =IF(C11>0, ROUND(AVERAGE('Grade 9_2'!W6:W20), 1), 0)

Sheet Grade 10
A1: EVAL AI (ADEM) — GRADE 10 EXAMINATION MARK SHEET
A2: Academic Year: 2025–2026 | Class: Grade 10 | Total Subjects: 6 | Max Marks: 600 | Pass: Min 35% in each subject
A4: S.No | B4: Roll No | C4: Student Name | D4: BIOLOGY (100) | G4: BIOLOGY (100) | J4: CHEMISTRY (100) | M4: CHEMISTRY (100) | P4: MATHS (100) | S4: PHYSICS (100) | V4: Grand Total (600) | W4: Percentage (%) | X4: Result | Y4: Grade | Z4: Class Rank
D5: Theory (80) | E5: Internal (20) | F5: Total (100) | G5: Theory (80) | H5: Internal (20) | I5: Total (100) | J5: Theory (80) | K5: Internal (20) | L5: Total (100) | M5: Theory (80) | N5: Internal (20) | O5: Total (100) | P5: Theory (80) | Q5: Internal (20) | R5: Total (100) | S5: Theory (80) | T5: Internal (20) | U5: Total (100)
F6: =IF(ISBLANK(C6), "", D6+E6) | I6: =IF(ISBLANK(C6), "", G6+H6) | L6: =IF(ISBLANK(C6), "", J6+K6) | O6: =IF(ISBLANK(C6), "", M6+N6) | R6: =IF(ISBLANK(C6), "", P6+Q6) | U6: =IF(ISBLANK(C6), "", S6+T6) | V6: =IF(ISBLANK(C6), "", F6+I6+L6+O6+R6+U6) | W6: =IF(OR(ISBLANK(C6), V6=""), "", ROUND((V6/600)*100, 1)) | X6: =IF(OR(ISBLANK(C6), V6=""), "", IF(AND(F6>=35, I6>=35, L6>=35, O6>=35, R6>=35, U6>=35), "PASS", "FAIL")) | Y6: =IF(OR(ISBLANK(C6), X6=""), "", IF(X6="FAIL", "F", IF(W6>=90, "A+", IF(W6>=80, "A", IF(W6>=70, "B", IF(W6>=50, "C", "D")))))) | Z6: =IF(OR(ISBLANK(C6), V6=""), "", RANK(V6, $V$6:$V$20))
F7: =IF(ISBLANK(C7), "", D7+E7) | I7: =IF(ISBLANK(C7), "", G7+H7) | L7: =IF(ISBLANK(C7), "", J7+K7) | O7: =IF(ISBLANK(C7), "", M7+N7) | R7: =IF(ISBLANK(C7), "", P7+Q7) | U7: =IF(ISBLANK(C7), "", S7+T7) | V7: =IF(ISBLANK(C7), "", F7+I7+L7+O7+R7+U7) | W7: =IF(OR(ISBLANK(C7), V7=""), "", ROUND((V7/600)*100, 1)) | X7: =IF(OR(ISBLANK(C7), V7=""), "", IF(AND(F7>=35, I7>=35, L7>=35, O7>=35, R7>=35, U7>=35), "PASS", "FAIL")) | Y7: =IF(OR(ISBLANK(C7), X7=""), "", IF(X7="FAIL", "F", IF(W7>=90, "A+", IF(W7>=80, "A", IF(W7>=70, "B", IF(W7>=50, "C", "D")))))) | Z7: =IF(OR(ISBLANK(C7), V7=""), "", RANK(V7, $V$6:$V$20))
F8: =IF(ISBLANK(C8), "", D8+E8) | I8: =IF(ISBLANK(C8), "", G8+H8) | L8: =IF(ISBLANK(C8), "", J8+K8) | O8: =IF(ISBLANK(C8), "", M8+N8) | R8: =IF(ISBLANK(C8), "", P8+Q8) | U8: =IF(ISBLANK(C8), "", S8+T8) | V8: =IF(ISBLANK(C8), "", F8+I8+L8+O8+R8+U8) | W8: =IF(OR(ISBLANK(C8), V8=""), "", ROUND((V8/600)*100, 1)) | X8: =IF(OR(ISBLANK(C8), V8=""), "", IF(AND(F8>=35, I8>=35, L8>=35, O8>=35, R8>=35, U8>=35), "PASS", "FAIL")) | Y8: =IF(OR(ISBLANK(C8), X8=""), "", IF(X8="FAIL", "F", IF(W8>=90, "A+", IF(W8>=80, "A", IF(W8>=70, "B", IF(W8>=50, "C", "D")))))) | Z8: =IF(OR(ISBLANK(C8), V8=""), "", RANK(V8, $V$6:$V$20))
F9: =IF(ISBLANK(C9), "", D9+E9) | I9: =IF(ISBLANK(C9), "", G9+H9) | L9: =IF(ISBLANK(C9), "", J9+K9) | O9: =IF(ISBLANK(C9), "", M9+N9) | R9: =IF(ISBLANK(C9), "", P9+Q9) | U9: =IF(ISBLANK(C9), "", S9+T9) | V9: =IF(ISBLANK(C9), "", F9+I9+L9+O9+R9+U9) | W9: =IF(OR(ISBLANK(C9), V9=""), "", ROUND((V9/600)*100, 1)) | X9: =IF(OR(ISBLANK(C9), V9=""), "", IF(AND(F9>=35, I9>=35, L9>=35, O9>=35, R9>=35, U9>=35), "PASS", "FAIL")) | Y9: =IF(OR(ISBLANK(C9), X9=""), "", IF(X9="FAIL", "F", IF(W9>=90, "A+", IF(W9>=80, "A", IF(W9>=70, "B", IF(W9>=50, "C", "D")))))) | Z9: =IF(OR(ISBLANK(C9), V9=""), "", RANK(V9, $V$6:$V$20))
F10: =IF(ISBLANK(C10), "", D10+E10) | I10: =IF(ISBLANK(C10), "", G10+H10) | L10: =IF(ISBLANK(C10), "", J10+K10) | O10: =IF(ISBLANK(C10), "", M10+N10) | R10: =IF(ISBLANK(C10), "", P10+Q10) | U10: =IF(ISBLANK(C10), "", S10+T10) | V10: =IF(ISBLANK(C10), "", F10+I10+L10+O10+R10+U10) | W10: =IF(OR(ISBLANK(C10), V10=""), "", ROUND((V10/600)*100, 1)) | X10: =IF(OR(ISBLANK(C10), V10=""), "", IF(AND(F10>=35, I10>=35, L10>=35, O10>=35, R10>=35, U10>=35), "PASS", "FAIL")) | Y10: =IF(OR(ISBLANK(C10), X10=""), "", IF(X10="FAIL", "F", IF(W10>=90, "A+", IF(W10>=80, "A", IF(W10>=70, "B", IF(W10>=50, "C", "D")))))) | Z10: =IF(OR(ISBLANK(C10), V10=""), "", RANK(V10, $V$6:$V$20))
F11: =IF(ISBLANK(C11), "", D11+E11) | I11: =IF(ISBLANK(C11), "", G11+H11) | L11: =IF(ISBLANK(C11), "", J11+K11) | O11: =IF(ISBLANK(C11), "", M11+N11) | R11: =IF(ISBLANK(C11), "", P11+Q11) | U11: =IF(ISBLANK(C11), "", S11+T11) | V11: =IF(ISBLANK(C11), "", F11+I11+L11+O11+R11+U11) | W11: =IF(OR(ISBLANK(C11), V11=""), "", ROUND((V11/600)*100, 1)) | X11: =IF(OR(ISBLANK(C11), V11=""), "", IF(AND(F11>=35, I11>=35, L11>=35, O11>=35, R11>=35, U11>=35), "PASS", "FAIL")) | Y11: =IF(OR(ISBLANK(C11), X11=""), "", IF(X11="FAIL", "F", IF(W11>=90, "A+", IF(W11>=80, "A", IF(W11>=70, "B", IF(W11>=50, "C", "D")))))) | Z11: =IF(OR(ISBLANK(C11), V11=""), "", RANK(V11, $V$6:$V$20))
F12: =IF(ISBLANK(C12), "", D12+E12) | I12: =IF(ISBLANK(C12), "", G12+H12) | L12: =IF(ISBLANK(C12), "", J12+K12) | O12: =IF(ISBLANK(C12), "", M12+N12) | R12: =IF(ISBLANK(C12), "", P12+Q12) | U12: =IF(ISBLANK(C12), "", S12+T12) | V12: =IF(ISBLANK(C12), "", F12+I12+L12+O12+R12+U12) | W12: =IF(OR(ISBLANK(C12), V12=""), "", ROUND((V12/600)*100, 1)) | X12: =IF(OR(ISBLANK(C12), V12=""), "", IF(AND(F12>=35, I12>=35, L12>=35, O12>=35, R12>=35, U12>=35), "PASS", "FAIL")) | Y12: =IF(OR(ISBLANK(C12), X12=""), "", IF(X12="FAIL", "F", IF(W12>=90, "A+", IF(W12>=80, "A", IF(W12>=70, "B", IF(W12>=50, "C", "D")))))) | Z12: =IF(OR(ISBLANK(C12), V12=""), "", RANK(V12, $V$6:$V$20))
F13: =IF(ISBLANK(C13), "", D13+E13) | I13: =IF(ISBLANK(C13), "", G13+H13) | L13: =IF(ISBLANK(C13), "", J13+K13) | O13: =IF(ISBLANK(C13), "", M13+N13) | R13: =IF(ISBLANK(C13), "", P13+Q13) | U13: =IF(ISBLANK(C13), "", S13+T13) | V13: =IF(ISBLANK(C13), "", F13+I13+L13+O13+R13+U13) | W13: =IF(OR(ISBLANK(C13), V13=""), "", ROUND((V13/600)*100, 1)) | X13: =IF(OR(ISBLANK(C13), V13=""), "", IF(AND(F13>=35, I13>=35, L13>=35, O13>=35, R13>=35, U13>=35), "PASS", "FAIL")) | Y13: =IF(OR(ISBLANK(C13), X13=""), "", IF(X13="FAIL", "F", IF(W13>=90, "A+", IF(W13>=80, "A", IF(W13>=70, "B", IF(W13>=50, "C", "D")))))) | Z13: =IF(OR(ISBLANK(C13), V13=""), "", RANK(V13, $V$6:$V$20))
F14: =IF(ISBLANK(C14), "", D14+E14) | I14: =IF(ISBLANK(C14), "", G14+H14) | L14: =IF(ISBLANK(C14), "", J14+K14) | O14: =IF(ISBLANK(C14), "", M14+N14) | R14: =IF(ISBLANK(C14), "", P14+Q14) | U14: =IF(ISBLANK(C14), "", S14+T14) | V14: =IF(ISBLANK(C14), "", F14+I14+L14+O14+R14+U14) | W14: =IF(OR(ISBLANK(C14), V14=""), "", ROUND((V14/600)*100, 1)) | X14: =IF(OR(ISBLANK(C14), V14=""), "", IF(AND(F14>=35, I14>=35, L14>=35, O14>=35, R14>=35, U14>=35), "PASS", "FAIL")) | Y14: =IF(OR(ISBLANK(C14), X14=""), "", IF(X14="FAIL", "F", IF(W14>=90, "A+", IF(W14>=80, "A", IF(W14>=70, "B", IF(W14>=50, "C", "D")))))) | Z14: =IF(OR(ISBLANK(C14), V14=""), "", RANK(V14, $V$6:$V$20))
F15: =IF(ISBLANK(C15), "", D15+E15) | I15: =IF(ISBLANK(C15), "", G15+H15) | L15: =IF(ISBLANK(C15), "", J15+K15) | O15: =IF(ISBLANK(C15), "", M15+N15) | R15: =IF(ISBLANK(C15), "", P15+Q15) | U15: =IF(ISBLANK(C15), "", S15+T15) | V15: =IF(ISBLANK(C15), "", F15+I15+L15+O15+R15+U15) | W15: =IF(OR(ISBLANK(C15), V15=""), "", ROUND((V15/600)*100, 1)) | X15: =IF(OR(ISBLANK(C15), V15=""), "", IF(AND(F15>=35, I15>=35, L15>=35, O15>=35, R15>=35, U15>=35), "PASS", "FAIL")) | Y15: =IF(OR(ISBLANK(C15), X15=""), "", IF(X15="FAIL", "F", IF(W15>=90, "A+", IF(W15>=80, "A", IF(W15>=70, "B", IF(W15>=50, "C", "D")))))) | Z15: =IF(OR(ISBLANK(C15), V15=""), "", RANK(V15, $V$6:$V$20))
F16: =IF(ISBLANK(C16), "", D16+E16) | I16: =IF(ISBLANK(C16), "", G16+H16) | L16: =IF(ISBLANK(C16), "", J16+K16) | O16: =IF(ISBLANK(C16), "", M16+N16) | R16: =IF(ISBLANK(C16), "", P16+Q16) | U16: =IF(ISBLANK(C16), "", S16+T16) | V16: =IF(ISBLANK(C16), "", F16+I16+L16+O16+R16+U16) | W16: =IF(OR(ISBLANK(C16), V16=""), "", ROUND((V16/600)*100, 1)) | X16: =IF(OR(ISBLANK(C16), V16=""), "", IF(AND(F16>=35, I16>=35, L16>=35, O16>=35, R16>=35, U16>=35), "PASS", "FAIL")) | Y16: =IF(OR(ISBLANK(C16), X16=""), "", IF(X16="FAIL", "F", IF(W16>=90, "A+", IF(W16>=80, "A", IF(W16>=70, "B", IF(W16>=50, "C", "D")))))) | Z16: =IF(OR(ISBLANK(C16), V16=""), "", RANK(V16, $V$6:$V$20))
F17: =IF(ISBLANK(C17), "", D17+E17) | I17: =IF(ISBLANK(C17), "", G17+H17) | L17: =IF(ISBLANK(C17), "", J17+K17) | O17: =IF(ISBLANK(C17), "", M17+N17) | R17: =IF(ISBLANK(C17), "", P17+Q17) | U17: =IF(ISBLANK(C17), "", S17+T17) | V17: =IF(ISBLANK(C17), "", F17+I17+L17+O17+R17+U17) | W17: =IF(OR(ISBLANK(C17), V17=""), "", ROUND((V17/600)*100, 1)) | X17: =IF(OR(ISBLANK(C17), V17=""), "", IF(AND(F17>=35, I17>=35, L17>=35, O17>=35, R17>=35, U17>=35), "PASS", "FAIL")) | Y17: =IF(OR(ISBLANK(C17), X17=""), "", IF(X17="FAIL", "F", IF(W17>=90, "A+", IF(W17>=80, "A", IF(W17>=70, "B", IF(W17>=50, "C", "D")))))) | Z17: =IF(OR(ISBLANK(C17), V17=""), "", RANK(V17, $V$6:$V$20))
... F20: =IF(ISBLANK(C20), "", D20+E20) | I20: =IF(ISBLANK(C20), "", G20+H20) | L20: =IF(ISBLANK(C20), "", J20+K20) | O20: =IF(ISBLANK(C20), "", M20+N20) | R20: =IF(ISBLANK(C20), "", P20+Q20) | U20: =IF(ISBLANK(C20), "", S20+T20) | V20: =IF(ISBLANK(C20), "", F20+I20+L20+O20+R20+U20) | W20: =IF(OR(ISBLANK(C20), V20=""), "", ROUND((V20/600)*100, 1)) | X20: =IF(OR(ISBLANK(C20), V20=""), "", IF(AND(F20>=35, I20>=35, L20>=35, O20>=35, R20>=35, U20>=35), "PASS", "FAIL")) | Y20: =IF(OR(ISBLANK(C20), X20=""), "", IF(X20="FAIL", "F", IF(W20>=90, "A+", IF(W20>=80, "A", IF(W20>=70, "B", IF(W20>=50, "C", "D")))))) | Z20: =IF(OR(ISBLANK(C20), V20=""), "", RANK(V20, $V$6:$V$20))
A23: CLASS AVERAGE | D23: =IF(COUNTA(C6:C20)>0, ROUND(AVERAGE(F6:F20), 1), "-") | G23: =IF(COUNTA(C6:C20)>0, ROUND(AVERAGE(I6:I20), 1), "-") | J23: =IF(COUNTA(C6:C20)>0, ROUND(AVERAGE(L6:L20), 1), "-") | M23: =IF(COUNTA(C6:C20)>0, ROUND(AVERAGE(O6:O20), 1), "-") | P23: =IF(COUNTA(C6:C20)>0, ROUND(AVERAGE(R6:R20), 1), "-") | S23: =IF(COUNTA(C6:C20)>0, ROUND(AVERAGE(U6:U20), 1), "-") | V23: =IF(COUNTA(C6:C20)>0, ROUND(AVERAGE(V6:V20), 1), "-") | W23: =IF(COUNTA(C6:C20)>0, ROUND(AVERAGE(W6:W20), 1), "-")
A24: HIGHEST MARKS | D24: =IF(COUNTA(C6:C20)>0, MAX(F6:F20), "-") | G24: =IF(COUNTA(C6:C20)>0, MAX(I6:I20), "-") | J24: =IF(COUNTA(C6:C20)>0, MAX(L6:L20), "-") | M24: =IF(COUNTA(C6:C20)>0, MAX(O6:O20), "-") | P24: =IF(COUNTA(C6:C20)>0, MAX(R6:R20), "-") | S24: =IF(COUNTA(C6:C20)>0, MAX(U6:U20), "-") | V24: =IF(COUNTA(C6:C20)>0, MAX(V6:V20), "-") | W24: =IF(COUNTA(C6:C20)>0, MAX(W6:W20), "-")
A25: LOWEST MARKS | D25: =IF(COUNTA(C6:C20)>0, MIN(F6:F20), "-") | G25: =IF(COUNTA(C6:C20)>0, MIN(I6:I20), "-") | J25: =IF(COUNTA(C6:C20)>0, MIN(L6:L20), "-") | M25: =IF(COUNTA(C6:C20)>0, MIN(O6:O20), "-") | P25: =IF(COUNTA(C6:C20)>0, MIN(R6:R20), "-") | S25: =IF(COUNTA(C6:C20)>0, MIN(U6:U20), "-") | V25: =IF(COUNTA(C6:C20)>0, MIN(V6:V20), "-") | W25: =IF(COUNTA(C6:C20)>0, MIN(W6:W20), "-")
A26: TOTAL PASSED | D26: =COUNTIF(F6:F20, ">=35") | G26: =COUNTIF(I6:I20, ">=35") | J26: =COUNTIF(L6:L20, ">=35") | M26: =COUNTIF(O6:O20, ">=35") | P26: =COUNTIF(R6:R20, ">=35") | S26: =COUNTIF(U6:U20, ">=35") | V26: =COUNTIF(X6:X20, "PASS")
A27: PASS PERCENTAGE (%) | D27: =IF(COUNTA(C6:C20)>0, ROUND((D26/COUNTA(C6:C20))*100, 1), "-") | G27: =IF(COUNTA(C6:C20)>0, ROUND((G26/COUNTA(C6:C20))*100, 1), "-") | J27: =IF(COUNTA(C6:C20)>0, ROUND((J26/COUNTA(C6:C20))*100, 1), "-") | M27: =IF(COUNTA(C6:C20)>0, ROUND((M26/COUNTA(C6:C20))*100, 1), "-") | P27: =IF(COUNTA(C6:C20)>0, ROUND((P26/COUNTA(C6:C20))*100, 1), "-") | S27: =IF(COUNTA(C6:C20)>0, ROUND((S26/COUNTA(C6:C20))*100, 1), "-") | V27: =IF(COUNTA(C6:C20)>0, ROUND((V26/COUNTA(C6:C20))*100, 1), "-")

Sheet Grade 11
A1: EVAL AI (ADEM) — GRADE 11 EXAMINATION MARK SHEET
A2: Academic Year: 2025–2026 | Class: Grade 11 | Total Subjects: 6 | Max Marks: 600 | Pass: Min 35% in each subject
A4: S.No | B4: Roll No | C4: Student Name | D4: BIOLOGY (100) | G4: BIOLOGY (100) | J4: CHEMISTRY (100) | M4: CHEMISTRY (100) | P4: MATHS (100) | S4: PHYSICS (100) | V4: Grand Total (600) | W4: Percentage (%) | X4: Result | Y4: Grade | Z4: Class Rank
D5: Theory (80) | E5: Internal (20) | F5: Total (100) | G5: Theory (80) | H5: Internal (20) | I5: Total (100) | J5: Theory (80) | K5: Internal (20) | L5: Total (100) | M5: Theory (80) | N5: Internal (20) | O5: Total (100) | P5: Theory (80) | Q5: Internal (20) | R5: Total (100) | S5: Theory (80) | T5: Internal (20) | U5: Total (100)
F6: =IF(ISBLANK(C6), "", D6+E6) | I6: =IF(ISBLANK(C6), "", G6+H6) | L6: =IF(ISBLANK(C6), "", J6+K6) | O6: =IF(ISBLANK(C6), "", M6+N6) | R6: =IF(ISBLANK(C6), "", P6+Q6) | U6: =IF(ISBLANK(C6), "", S6+T6) | V6: =IF(ISBLANK(C6), "", F6+I6+L6+O6+R6+U6) | W6: =IF(OR(ISBLANK(C6), V6=""), "", ROUND((V6/600)*100, 1)) | X6: =IF(OR(ISBLANK(C6), V6=""), "", IF(AND(F6>=35, I6>=35, L6>=35, O6>=35, R6>=35, U6>=35), "PASS", "FAIL")) | Y6: =IF(OR(ISBLANK(C6), X6=""), "", IF(X6="FAIL", "F", IF(W6>=90, "A+", IF(W6>=80, "A", IF(W6>=70, "B", IF(W6>=50, "C", "D")))))) | Z6: =IF(OR(ISBLANK(C6), V6=""), "", RANK(V6, $V$6:$V$20))
F7: =IF(ISBLANK(C7), "", D7+E7) | I7: =IF(ISBLANK(C7), "", G7+H7) | L7: =IF(ISBLANK(C7), "", J7+K7) | O7: =IF(ISBLANK(C7), "", M7+N7) | R7: =IF(ISBLANK(C7), "", P7+Q7) | U7: =IF(ISBLANK(C7), "", S7+T7) | V7: =IF(ISBLANK(C7), "", F7+I7+L7+O7+R7+U7) | W7: =IF(OR(ISBLANK(C7), V7=""), "", ROUND((V7/600)*100, 1)) | X7: =IF(OR(ISBLANK(C7), V7=""), "", IF(AND(F7>=35, I7>=35, L7>=35, O7>=35, R7>=35, U7>=35), "PASS", "FAIL")) | Y7: =IF(OR(ISBLANK(C7), X7=""), "", IF(X7="FAIL", "F", IF(W7>=90, "A+", IF(W7>=80, "A", IF(W7>=70, "B", IF(W7>=50, "C", "D")))))) | Z7: =IF(OR(ISBLANK(C7), V7=""), "", RANK(V7, $V$6:$V$20))
F8: =IF(ISBLANK(C8), "", D8+E8) | I8: =IF(ISBLANK(C8), "", G8+H8) | L8: =IF(ISBLANK(C8), "", J8+K8) | O8: =IF(ISBLANK(C8), "", M8+N8) | R8: =IF(ISBLANK(C8), "", P8+Q8) | U8: =IF(ISBLANK(C8), "", S8+T8) | V8: =IF(ISBLANK(C8), "", F8+I8+L8+O8+R8+U8) | W8: =IF(OR(ISBLANK(C8), V8=""), "", ROUND((V8/600)*100, 1)) | X8: =IF(OR(ISBLANK(C8), V8=""), "", IF(AND(F8>=35, I8>=35, L8>=35, O8>=35, R8>=35, U8>=35), "PASS", "FAIL")) | Y8: =IF(OR(ISBLANK(C8), X8=""), "", IF(X8="FAIL", "F", IF(W8>=90, "A+", IF(W8>=80, "A", IF(W8>=70, "B", IF(W8>=50, "C", "D")))))) | Z8: =IF(OR(ISBLANK(C8), V8=""), "", RANK(V8, $V$6:$V$20))
F9: =IF(ISBLANK(C9), "", D9+E9) | I9: =IF(ISBLANK(C9), "", G9+H9) | L9: =IF(ISBLANK(C9), "", J9+K9) | O9: =IF(ISBLANK(C9), "", M9+N9) | R9: =IF(ISBLANK(C9), "", P9+Q9) | U9: =IF(ISBLANK(C9), "", S9+T9) | V9: =IF(ISBLANK(C9), "", F9+I9+L9+O9+R9+U9) | W9: =IF(OR(ISBLANK(C9), V9=""), "", ROUND((V9/600)*100, 1)) | X9: =IF(OR(ISBLANK(C9), V9=""), "", IF(AND(F9>=35, I9>=35, L9>=35, O9>=35, R9>=35, U9>=35), "PASS", "FAIL")) | Y9: =IF(OR(ISBLANK(C9), X9=""), "", IF(X9="FAIL", "F", IF(W9>=90, "A+", IF(W9>=80, "A", IF(W9>=70, "B", IF(W9>=50, "C", "D")))))) | Z9: =IF(OR(ISBLANK(C9), V9=""), "", RANK(V9, $V$6:$V$20))
F10: =IF(ISBLANK(C10), "", D10+E10) | I10: =IF(ISBLANK(C10), "", G10+H10) | L10: =IF(ISBLANK(C10), "", J10+K10) | O10: =IF(ISBLANK(C10), "", M10+N10) | R10: =IF(ISBLANK(C10), "", P10+Q10) | U10: =IF(ISBLANK(C10), "", S10+T10) | V10: =IF(ISBLANK(C10), "", F10+I10+L10+O10+R10+U10) | W10: =IF(OR(ISBLANK(C10), V10=""), "", ROUND((V10/600)*100, 1)) | X10: =IF(OR(ISBLANK(C10), V10=""), "", IF(AND(F10>=35, I10>=35, L10>=35, O10>=35, R10>=35, U10>=35), "PASS", "FAIL")) | Y10: =IF(OR(ISBLANK(C10), X10=""), "", IF(X10="FAIL", "F", IF(W10>=90, "A+", IF(W10>=80, "A", IF(W10>=70, "B", IF(W10>=50, "C", "D")))))) | Z10: =IF(OR(ISBLANK(C10), V10=""), "", RANK(V10, $V$6:$V$20))
F11: =IF(ISBLANK(C11), "", D11+E11) | I11: =IF(ISBLANK(C11), "", G11+H11) | L11: =IF(ISBLANK(C11), "", J11+K11) | O11: =IF(ISBLANK(C11), "", M11+N11) | R11: =IF(ISBLANK(C11), "", P11+Q11) | U11: =IF(ISBLANK(C11), "", S11+T11) | V11: =IF(ISBLANK(C11), "", F11+I11+L11+O11+R11+U11) | W11: =IF(OR(ISBLANK(C11), V11=""), "", ROUND((V11/600)*100, 1)) | X11: =IF(OR(ISBLANK(C11), V11=""), "", IF(AND(F11>=35, I11>=35, L11>=35, O11>=35, R11>=35, U11>=35), "PASS", "FAIL")) | Y11: =IF(OR(ISBLANK(C11), X11=""), "", IF(X11="FAIL", "F", IF(W11>=90, "A+", IF(W11>=80, "A", IF(W11>=70, "B", IF(W11>=50, "C", "D")))))) | Z11: =IF(OR(ISBLANK(C11), V11=""), "", RANK(V11, $V$6:$V$20))
F12: =IF(ISBLANK(C12), "", D12+E12) | I12: =IF(ISBLANK(C12), "", G12+H12) | L12: =IF(ISBLANK(C12), "", J12+K12) | O12: =IF(ISBLANK(C12), "", M12+N12) | R12: =IF(ISBLANK(C12), "", P12+Q12) | U12: =IF(ISBLANK(C12), "", S12+T12) | V12: =IF(ISBLANK(C12), "", F12+I12+L12+O12+R12+U12) | W12: =IF(OR(ISBLANK(C12), V12=""), "", ROUND((V12/600)*100, 1)) | X12: =IF(OR(ISBLANK(C12), V12=""), "", IF(AND(F12>=35, I12>=35, L12>=35, O12>=35, R12>=35, U12>=35), "PASS", "FAIL")) | Y12: =IF(OR(ISBLANK(C12), X12=""), "", IF(X12="FAIL", "F", IF(W12>=90, "A+", IF(W12>=80, "A", IF(W12>=70, "B", IF(W12>=50, "C", "D")))))) | Z12: =IF(OR(ISBLANK(C12), V12=""), "", RANK(V12, $V$6:$V$20))
F13: =IF(ISBLANK(C13), "", D13+E13) | I13: =IF(ISBLANK(C13), "", G13+H13) | L13: =IF(ISBLANK(C13), "", J13+K13) | O13: =IF(ISBLANK(C13), "", M13+N13) | R13: =IF(ISBLANK(C13), "", P13+Q13) | U13: =IF(ISBLANK(C13), "", S13+T13) | V13: =IF(ISBLANK(C13), "", F13+I13+L13+O13+R13+U13) | W13: =IF(OR(ISBLANK(C13), V13=""), "", ROUND((V13/600)*100, 1)) | X13: =IF(OR(ISBLANK(C13), V13=""), "", IF(AND(F13>=35, I13>=35, L13>=35, O13>=35, R13>=35, U13>=35), "PASS", "FAIL")) | Y13: =IF(OR(ISBLANK(C13), X13=""), "", IF(X13="FAIL", "F", IF(W13>=90, "A+", IF(W13>=80, "A", IF(W13>=70, "B", IF(W13>=50, "C", "D")))))) | Z13: =IF(OR(ISBLANK(C13), V13=""), "", RANK(V13, $V$6:$V$20))
F14: =IF(ISBLANK(C14), "", D14+E14) | I14: =IF(ISBLANK(C14), "", G14+H14) | L14: =IF(ISBLANK(C14), "", J14+K14) | O14: =IF(ISBLANK(C14), "", M14+N14) | R14: =IF(ISBLANK(C14), "", P14+Q14) | U14: =IF(ISBLANK(C14), "", S14+T14) | V14: =IF(ISBLANK(C14), "", F14+I14+L14+O14+R14+U14) | W14: =IF(OR(ISBLANK(C14), V14=""), "", ROUND((V14/600)*100, 1)) | X14: =IF(OR(ISBLANK(C14), V14=""), "", IF(AND(F14>=35, I14>=35, L14>=35, O14>=35, R14>=35, U14>=35), "PASS", "FAIL")) | Y14: =IF(OR(ISBLANK(C14), X14=""), "", IF(X14="FAIL", "F", IF(W14>=90, "A+", IF(W14>=80, "A", IF(W14>=70, "B", IF(W14>=50, "C", "D")))))) | Z14: =IF(OR(ISBLANK(C14), V14=""), "", RANK(V14, $V$6:$V$20))
F15: =IF(ISBLANK(C15), "", D15+E15) | I15: =IF(ISBLANK(C15), "", G15+H15) | L15: =IF(ISBLANK(C15), "", J15+K15) | O15: =IF(ISBLANK(C15), "", M15+N15) | R15: =IF(ISBLANK(C15), "", P15+Q15) | U15: =IF(ISBLANK(C15), "", S15+T15) | V15: =IF(ISBLANK(C15), "", F15+I15+L15+O15+R15+U15) | W15: =IF(OR(ISBLANK(C15), V15=""), "", ROUND((V15/600)*100, 1)) | X15: =IF(OR(ISBLANK(C15), V15=""), "", IF(AND(F15>=35, I15>=35, L15>=35, O15>=35, R15>=35, U15>=35), "PASS", "FAIL")) | Y15: =IF(OR(ISBLANK(C15), X15=""), "", IF(X15="FAIL", "F", IF(W15>=90, "A+", IF(W15>=80, "A", IF(W15>=70, "B", IF(W15>=50, "C", "D")))))) | Z15: =IF(OR(ISBLANK(C15), V15=""), "", RANK(V15, $V$6:$V$20))
F16: =IF(ISBLANK(C16), "", D16+E16) | I16: =IF(ISBLANK(C16), "", G16+H16) | L16: =IF(ISBLANK(C16), "", J16+K16) | O16: =IF(ISBLANK(C16), "", M16+N16) | R16: =IF(ISBLANK(C16), "", P16+Q16) | U16: =IF(ISBLANK(C16), "", S16+T16) | V16: =IF(ISBLANK(C16), "", F16+I16+L16+O16+R16+U16) | W16: =IF(OR(ISBLANK(C16), V16=""), "", ROUND((V16/600)*100, 1)) | X16: =IF(OR(ISBLANK(C16), V16=""), "", IF(AND(F16>=35, I16>=35, L16>=35, O16>=35, R16>=35, U16>=35), "PASS", "FAIL")) | Y16: =IF(OR(ISBLANK(C16), X16=""), "", IF(X16="FAIL", "F", IF(W16>=90, "A+", IF(W16>=80, "A", IF(W16>=70, "B", IF(W16>=50, "C", "D")))))) | Z16: =IF(OR(ISBLANK(C16), V16=""), "", RANK(V16, $V$6:$V$20))
F17: =IF(ISBLANK(C17), "", D17+E17) | I17: =IF(ISBLANK(C17), "", G17+H17) | L17: =IF(ISBLANK(C17), "", J17+K17) | O17: =IF(ISBLANK(C17), "", M17+N17) | R17: =IF(ISBLANK(C17), "", P17+Q17) | U17: =IF(ISBLANK(C17), "", S17+T17) | V17: =IF(ISBLANK(C17), "", F17+I17+L17+O17+R17+U17) | W17: =IF(OR(ISBLANK(C17), V17=""), "", ROUND((V17/600)*100, 1)) | X17: =IF(OR(ISBLANK(C17), V17=""), "", IF(AND(F17>=35, I17>=35, L17>=35, O17>=35, R17>=35, U17>=35), "PASS", "FAIL")) | Y17: =IF(OR(ISBLANK(C17), X17=""), "", IF(X17="FAIL", "F", IF(W17>=90, "A+", IF(W17>=80, "A", IF(W17>=70, "B", IF(W17>=50, "C", "D")))))) | Z17: =IF(OR(ISBLANK(C17), V17=""), "", RANK(V17, $V$6:$V$20))
... F20: =IF(ISBLANK(C20), "", D20+E20) | I20: =IF(ISBLANK(C20), "", G20+H20) | L20: =IF(ISBLANK(C20), "", J20+K20) | O20: =IF(ISBLANK(C20), "", M20+N20) | R20: =IF(ISBLANK(C20), "", P20+Q20) | U20: =IF(ISBLANK(C20), "", S20+T20) | V20: =IF(ISBLANK(C20), "", F20+I20+L20+O20+R20+U20) | W20: =IF(OR(ISBLANK(C20), V20=""), "", ROUND((V20/600)*100, 1)) | X20: =IF(OR(ISBLANK(C20), V20=""), "", IF(AND(F20>=35, I20>=35, L20>=35, O20>=35, R20>=35, U20>=35), "PASS", "FAIL")) | Y20: =IF(OR(ISBLANK(C20), X20=""), "", IF(X20="FAIL", "F", IF(W20>=90, "A+", IF(W20>=80, "A", IF(W20>=70, "B", IF(W20>=50, "C", "D")))))) | Z20: =IF(OR(ISBLANK(C20), V20=""), "", RANK(V20, $V$6:$V$20))
A23: CLASS AVERAGE | D23: =IF(COUNTA(C6:C20)>0, ROUND(AVERAGE(F6:F20), 1), "-") | G23: =IF(COUNTA(C6:C20)>0, ROUND(AVERAGE(I6:I20), 1), "-") | J23: =IF(COUNTA(C6:C20)>0, ROUND(AVERAGE(L6:L20), 1), "-") | M23: =IF(COUNTA(C6:C20)>0, ROUND(AVERAGE(O6:O20), 1), "-") | P23: =IF(COUNTA(C6:C20)>0, ROUND(AVERAGE(R6:R20), 1), "-") | S23: =IF(COUNTA(C6:C20)>0, ROUND(AVERAGE(U6:U20), 1), "-") | V23: =IF(COUNTA(C6:C20)>0, ROUND(AVERAGE(V6:V20), 1), "-") | W23: =IF(COUNTA(C6:C20)>0, ROUND(AVERAGE(W6:W20), 1), "-")
A24: HIGHEST MARKS | D24: =IF(COUNTA(C6:C20)>0, MAX(F6:F20), "-") | G24: =IF(COUNTA(C6:C20)>0, MAX(I6:I20), "-") | J24: =IF(COUNTA(C6:C20)>0, MAX(L6:L20), "-") | M24: =IF(COUNTA(C6:C20)>0, MAX(O6:O20), "-") | P24: =IF(COUNTA(C6:C20)>0, MAX(R6:R20), "-") | S24: =IF(COUNTA(C6:C20)>0, MAX(U6:U20), "-") | V24: =IF(COUNTA(C6:C20)>0, MAX(V6:V20), "-") | W24: =IF(COUNTA(C6:C20)>0, MAX(W6:W20), "-")
A25: LOWEST MARKS | D25: =IF(COUNTA(C6:C20)>0, MIN(F6:F20), "-") | G25: =IF(COUNTA(C6:C20)>0, MIN(I6:I20), "-") | J25: =IF(COUNTA(C6:C20)>0, MIN(L6:L20), "-") | M25: =IF(COUNTA(C6:C20)>0, MIN(O6:O20), "-") | P25: =IF(COUNTA(C6:C20)>0, MIN(R6:R20), "-") | S25: =IF(COUNTA(C6:C20)>0, MIN(U6:U20), "-") | V25: =IF(COUNTA(C6:C20)>0, MIN(V6:V20), "-") | W25: =IF(COUNTA(C6:C20)>0, MIN(W6:W20), "-")
A26: TOTAL PASSED | D26: =COUNTIF(F6:F20, ">=35") | G26: =COUNTIF(I6:I20, ">=35") | J26: =COUNTIF(L6:L20, ">=35") | M26: =COUNTIF(O6:O20, ">=35") | P26: =COUNTIF(R6:R20, ">=35") | S26: =COUNTIF(U6:U20, ">=35") | V26: =COUNTIF(X6:X20, "PASS")
A27: PASS PERCENTAGE (%) | D27: =IF(COUNTA(C6:C20)>0, ROUND((D26/COUNTA(C6:C20))*100, 1), "-") | G27: =IF(COUNTA(C6:C20)>0, ROUND((G26/COUNTA(C6:C20))*100, 1), "-") | J27: =IF(COUNTA(C6:C20)>0, ROUND((J26/COUNTA(C6:C20))*100, 1), "-") | M27: =IF(COUNTA(C6:C20)>0, ROUND((M26/COUNTA(C6:C20))*100, 1), "-") | P27: =IF(COUNTA(C6:C20)>0, ROUND((P26/COUNTA(C6:C20))*100, 1), "-") | S27: =IF(COUNTA(C6:C20)>0, ROUND((S26/COUNTA(C6:C20))*100, 1), "-") | V27: =IF(COUNTA(C6:C20)>0, ROUND((V26/COUNTA(C6:C20))*100, 1), "-")

Sheet Grade 11_2
A1: EVAL AI (ADEM) — GRADE 11 EXAMINATION MARK SHEET
A2: Academic Year: 2025–2026 | Class: Grade 11 | Total Subjects: 6 | Max Marks: 600 | Pass: Min 35% in each subject
A4: S.No | B4: Roll No | C4: Student Name | D4: BIOLOGY (100) | G4: BIOLOGY (100) | J4: CHEMISTRY (100) | M4: CHEMISTRY (100) | P4: MATHS (100) | S4: PHYSICS (100) | V4: Grand Total (600) | W4: Percentage (%) | X4: Result | Y4: Grade | Z4: Class Rank
D5: Theory (80) | E5: Internal (20) | F5: Total (100) | G5: Theory (80) | H5: Internal (20) | I5: Total (100) | J5: Theory (80) | K5: Internal (20) | L5: Total (100) | M5: Theory (80) | N5: Internal (20) | O5: Total (100) | P5: Theory (80) | Q5: Internal (20) | R5: Total (100) | S5: Theory (80) | T5: Internal (20) | U5: Total (100)
F6: =IF(ISBLANK(C6), "", D6+E6) | I6: =IF(ISBLANK(C6), "", G6+H6) | L6: =IF(ISBLANK(C6), "", J6+K6) | O6: =IF(ISBLANK(C6), "", M6+N6) | R6: =IF(ISBLANK(C6), "", P6+Q6) | U6: =IF(ISBLANK(C6), "", S6+T6) | V6: =IF(ISBLANK(C6), "", F6+I6+L6+O6+R6+U6) | W6: =IF(OR(ISBLANK(C6), V6=""), "", ROUND((V6/600)*100, 1)) | X6: =IF(OR(ISBLANK(C6), V6=""), "", IF(AND(F6>=35, I6>=35, L6>=35, O6>=35, R6>=35, U6>=35), "PASS", "FAIL")) | Y6: =IF(OR(ISBLANK(C6), X6=""), "", IF(X6="FAIL", "F", IF(W6>=90, "A+", IF(W6>=80, "A", IF(W6>=70, "B", IF(W6>=50, "C", "D")))))) | Z6: =IF(OR(ISBLANK(C6), V6=""), "", RANK(V6, $V$6:$V$20))
F7: =IF(ISBLANK(C7), "", D7+E7) | I7: =IF(ISBLANK(C7), "", G7+H7) | L7: =IF(ISBLANK(C7), "", J7+K7) | O7: =IF(ISBLANK(C7), "", M7+N7) | R7: =IF(ISBLANK(C7), "", P7+Q7) | U7: =IF(ISBLANK(C7), "", S7+T7) | V7: =IF(ISBLANK(C7), "", F7+I7+L7+O7+R7+U7) | W7: =IF(OR(ISBLANK(C7), V7=""), "", ROUND((V7/600)*100, 1)) | X7: =IF(OR(ISBLANK(C7), V7=""), "", IF(AND(F7>=35, I7>=35, L7>=35, O7>=35, R7>=35, U7>=35), "PASS", "FAIL")) | Y7: =IF(OR(ISBLANK(C7), X7=""), "", IF(X7="FAIL", "F", IF(W7>=90, "A+", IF(W7>=80, "A", IF(W7>=70, "B", IF(W7>=50, "C", "D")))))) | Z7: =IF(OR(ISBLANK(C7), V7=""), "", RANK(V7, $V$6:$V$20))
F8: =IF(ISBLANK(C8), "", D8+E8) | I8: =IF(ISBLANK(C8), "", G8+H8) | L8: =IF(ISBLANK(C8), "", J8+K8) | O8: =IF(ISBLANK(C8), "", M8+N8) | R8: =IF(ISBLANK(C8), "", P8+Q8) | U8: =IF(ISBLANK(C8), "", S8+T8) | V8: =IF(ISBLANK(C8), "", F8+I8+L8+O8+R8+U8) | W8: =IF(OR(ISBLANK(C8), V8=""), "", ROUND((V8/600)*100, 1)) | X8: =IF(OR(ISBLANK(C8), V8=""), "", IF(AND(F8>=35, I8>=35, L8>=35, O8>=35, R8>=35, U8>=35), "PASS", "FAIL")) | Y8: =IF(OR(ISBLANK(C8), X8=""), "", IF(X8="FAIL", "F", IF(W8>=90, "A+", IF(W8>=80, "A", IF(W8>=70, "B", IF(W8>=50, "C", "D")))))) | Z8: =IF(OR(ISBLANK(C8), V8=""), "", RANK(V8, $V$6:$V$20))
F9: =IF(ISBLANK(C9), "", D9+E9) | I9: =IF(ISBLANK(C9), "", G9+H9) | L9: =IF(ISBLANK(C9), "", J9+K9) | O9: =IF(ISBLANK(C9), "", M9+N9) | R9: =IF(ISBLANK(C9), "", P9+Q9) | U9: =IF(ISBLANK(C9), "", S9+T9) | V9: =IF(ISBLANK(C9), "", F9+I9+L9+O9+R9+U9) | W9: =IF(OR(ISBLANK(C9), V9=""), "", ROUND((V9/600)*100, 1)) | X9: =IF(OR(ISBLANK(C9), V9=""), "", IF(AND(F9>=35, I9>=35, L9>=35, O9>=35, R9>=35, U9>=35), "PASS", "FAIL")) | Y9: =IF(OR(ISBLANK(C9), X9=""), "", IF(X9="FAIL", "F", IF(W9>=90, "A+", IF(W9>=80, "A", IF(W9>=70, "B", IF(W9>=50, "C", "D")))))) | Z9: =IF(OR(ISBLANK(C9), V9=""), "", RANK(V9, $V$6:$V$20))
F10: =IF(ISBLANK(C10), "", D10+E10) | I10: =IF(ISBLANK(C10), "", G10+H10) | L10: =IF(ISBLANK(C10), "", J10+K10) | O10: =IF(ISBLANK(C10), "", M10+N10) | R10: =IF(ISBLANK(C10), "", P10+Q10) | U10: =IF(ISBLANK(C10), "", S10+T10) | V10: =IF(ISBLANK(C10), "", F10+I10+L10+O10+R10+U10) | W10: =IF(OR(ISBLANK(C10), V10=""), "", ROUND((V10/600)*100, 1)) | X10: =IF(OR(ISBLANK(C10), V10=""), "", IF(AND(F10>=35, I10>=35, L10>=35, O10>=35, R10>=35, U10>=35), "PASS", "FAIL")) | Y10: =IF(OR(ISBLANK(C10), X10=""), "", IF(X10="FAIL", "F", IF(W10>=90, "A+", IF(W10>=80, "A", IF(W10>=70, "B", IF(W10>=50, "C", "D")))))) | Z10: =IF(OR(ISBLANK(C10), V10=""), "", RANK(V10, $V$6:$V$20))
F11: =IF(ISBLANK(C11), "", D11+E11) | I11: =IF(ISBLANK(C11), "", G11+H11) | L11: =IF(ISBLANK(C11), "", J11+K11) | O11: =IF(ISBLANK(C11), "", M11+N11) | R11: =IF(ISBLANK(C11), "", P11+Q11) | U11: =IF(ISBLANK(C11), "", S11+T11) | V11: =IF(ISBLANK(C11), "", F11+I11+L11+O11+R11+U11) | W11: =IF(OR(ISBLANK(C11), V11=""), "", ROUND((V11/600)*100, 1)) | X11: =IF(OR(ISBLANK(C11), V11=""), "", IF(AND(F11>=35, I11>=35, L11>=35, O11>=35, R11>=35, U11>=35), "PASS", "FAIL")) | Y11: =IF(OR(ISBLANK(C11), X11=""), "", IF(X11="FAIL", "F", IF(W11>=90, "A+", IF(W11>=80, "A", IF(W11>=70, "B", IF(W11>=50, "C", "D")))))) | Z11: =IF(OR(ISBLANK(C11), V11=""), "", RANK(V11, $V$6:$V$20))
F12: =IF(ISBLANK(C12), "", D12+E12) | I12: =IF(ISBLANK(C12), "", G12+H12) | L12: =IF(ISBLANK(C12), "", J12+K12) | O12: =IF(ISBLANK(C12), "", M12+N12) | R12: =IF(ISBLANK(C12), "", P12+Q12) | U12: =IF(ISBLANK(C12), "", S12+T12) | V12: =IF(ISBLANK(C12), "", F12+I12+L12+O12+R12+U12) | W12: =IF(OR(ISBLANK(C12), V12=""), "", ROUND((V12/600)*100, 1)) | X12: =IF(OR(ISBLANK(C12), V12=""), "", IF(AND(F12>=35, I12>=35, L12>=35, O12>=35, R12>=35, U12>=35), "PASS", "FAIL")) | Y12: =IF(OR(ISBLANK(C12), X12=""), "", IF(X12="FAIL", "F", IF(W12>=90, "A+", IF(W12>=80, "A", IF(W12>=70, "B", IF(W12>=50, "C", "D")))))) | Z12: =IF(OR(ISBLANK(C12), V12=""), "", RANK(V12, $V$6:$V$20))
F13: =IF(ISBLANK(C13), "", D13+E13) | I13: =IF(ISBLANK(C13), "", G13+H13) | L13: =IF(ISBLANK(C13), "", J13+K13) | O13: =IF(ISBLANK(C13), "", M13+N13) | R13: =IF(ISBLANK(C13), "", P13+Q13) | U13: =IF(ISBLANK(C13), "", S13+T13) | V13: =IF(ISBLANK(C13), "", F13+I13+L13+O13+R13+U13) | W13: =IF(OR(ISBLANK(C13), V13=""), "", ROUND((V13/600)*100, 1)) | X13: =IF(OR(ISBLANK(C13), V13=""), "", IF(AND(F13>=35, I13>=35, L13>=35, O13>=35, R13>=35, U13>=35), "PASS", "FAIL")) | Y13: =IF(OR(ISBLANK(C13), X13=""), "", IF(X13="FAIL", "F", IF(W13>=90, "A+", IF(W13>=80, "A", IF(W13>=70, "B", IF(W13>=50, "C", "D")))))) | Z13: =IF(OR(ISBLANK(C13), V13=""), "", RANK(V13, $V$6:$V$20))
F14: =IF(ISBLANK(C14), "", D14+E14) | I14: =IF(ISBLANK(C14), "", G14+H14) | L14: =IF(ISBLANK(C14), "", J14+K14) | O14: =IF(ISBLANK(C14), "", M14+N14) | R14: =IF(ISBLANK(C14), "", P14+Q14) | U14: =IF(ISBLANK(C14), "", S14+T14) | V14: =IF(ISBLANK(C14), "", F14+I14+L14+O14+R14+U14) | W14: =IF(OR(ISBLANK(C14), V14=""), "", ROUND((V14/600)*100, 1)) | X14: =IF(OR(ISBLANK(C14), V14=""), "", IF(AND(F14>=35, I14>=35, L14>=35, O14>=35, R14>=35, U14>=35), "PASS", "FAIL")) | Y14: =IF(OR(ISBLANK(C14), X14=""), "", IF(X14="FAIL", "F", IF(W14>=90, "A+", IF(W14>=80, "A", IF(W14>=70, "B", IF(W14>=50, "C", "D")))))) | Z14: =IF(OR(ISBLANK(C14), V14=""), "", RANK(V14, $V$6:$V$20))
F15: =IF(ISBLANK(C15), "", D15+E15) | I15: =IF(ISBLANK(C15), "", G15+H15) | L15: =IF(ISBLANK(C15), "", J15+K15) | O15: =IF(ISBLANK(C15), "", M15+N15) | R15: =IF(ISBLANK(C15), "", P15+Q15) | U15: =IF(ISBLANK(C15), "", S15+T15) | V15: =IF(ISBLANK(C15), "", F15+I15+L15+O15+R15+U15) | W15: =IF(OR(ISBLANK(C15), V15=""), "", ROUND((V15/600)*100, 1)) | X15: =IF(OR(ISBLANK(C15), V15=""), "", IF(AND(F15>=35, I15>=35, L15>=35, O15>=35, R15>=35, U15>=35), "PASS", "FAIL")) | Y15: =IF(OR(ISBLANK(C15), X15=""), "", IF(X15="FAIL", "F", IF(W15>=90, "A+", IF(W15>=80, "A", IF(W15>=70, "B", IF(W15>=50, "C", "D")))))) | Z15: =IF(OR(ISBLANK(C15), V15=""), "", RANK(V15, $V$6:$V$20))
F16: =IF(ISBLANK(C16), "", D16+E16) | I16: =IF(ISBLANK(C16), "", G16+H16) | L16: =IF(ISBLANK(C16), "", J16+K16) | O16: =IF(ISBLANK(C16), "", M16+N16) | R16: =IF(ISBLANK(C16), "", P16+Q16) | U16: =IF(ISBLANK(C16), "", S16+T16) | V16: =IF(ISBLANK(C16), "", F16+I16+L16+O16+R16+U16) | W16: =IF(OR(ISBLANK(C16), V16=""), "", ROUND((V16/600)*100, 1)) | X16: =IF(OR(ISBLANK(C16), V16=""), "", IF(AND(F16>=35, I16>=35, L16>=35, O16>=35, R16>=35, U16>=35), "PASS", "FAIL")) | Y16: =IF(OR(ISBLANK(C16), X16=""), "", IF(X16="FAIL", "F", IF(W16>=90, "A+", IF(W16>=80, "A", IF(W16>=70, "B", IF(W16>=50, "C", "D")))))) | Z16: =IF(OR(ISBLANK(C16), V16=""), "", RANK(V16, $V$6:$V$20))
F17: =IF(ISBLANK(C17), "", D17+E17) | I17: =IF(ISBLANK(C17), "", G17+H17) | L17: =IF(ISBLANK(C17), "", J17+K17) | O17: =IF(ISBLANK(C17), "", M17+N17) | R17: =IF(ISBLANK(C17), "", P17+Q17) | U17: =IF(ISBLANK(C17), "", S17+T17) | V17: =IF(ISBLANK(C17), "", F17+I17+L17+O17+R17+U17) | W17: =IF(OR(ISBLANK(C17), V17=""), "", ROUND((V17/600)*100, 1)) | X17: =IF(OR(ISBLANK(C17), V17=""), "", IF(AND(F17>=35, I17>=35, L17>=35, O17>=35, R17>=35, U17>=35), "PASS", "FAIL")) | Y17: =IF(OR(ISBLANK(C17), X17=""), "", IF(X17="FAIL", "F", IF(W17>=90, "A+", IF(W17>=80, "A", IF(W17>=70, "B", IF(W17>=50, "C", "D")))))) | Z17: =IF(OR(ISBLANK(C17), V17=""), "", RANK(V17, $V$6:$V$20))
... F20: =IF(ISBLANK(C20), "", D20+E20) | I20: =IF(ISBLANK(C20), "", G20+H20) | L20: =IF(ISBLANK(C20), "", J20+K20) | O20: =IF(ISBLANK(C20), "", M20+N20) | R20: =IF(ISBLANK(C20), "", P20+Q20) | U20: =IF(ISBLANK(C20), "", S20+T20) | V20: =IF(ISBLANK(C20), "", F20+I20+L20+O20+R20+U20) | W20: =IF(OR(ISBLANK(C20), V20=""), "", ROUND((V20/600)*100, 1)) | X20: =IF(OR(ISBLANK(C20), V20=""), "", IF(AND(F20>=35, I20>=35, L20>=35, O20>=35, R20>=35, U20>=35), "PASS", "FAIL")) | Y20: =IF(OR(ISBLANK(C20), X20=""), "", IF(X20="FAIL", "F", IF(W20>=90, "A+", IF(W20>=80, "A", IF(W20>=70, "B", IF(W20>=50, "C", "D")))))) | Z20: =IF(OR(ISBLANK(C20), V20=""), "", RANK(V20, $V$6:$V$20))
A23: CLASS AVERAGE | D23: =IF(COUNTA(C6:C20)>0, ROUND(AVERAGE(F6:F20), 1), "-") | G23: =IF(COUNTA(C6:C20)>0, ROUND(AVERAGE(I6:I20), 1), "-") | J23: =IF(COUNTA(C6:C20)>0, ROUND(AVERAGE(L6:L20), 1), "-") | M23: =IF(COUNTA(C6:C20)>0, ROUND(AVERAGE(O6:O20), 1), "-") | P23: =IF(COUNTA(C6:C20)>0, ROUND(AVERAGE(R6:R20), 1), "-") | S23: =IF(COUNTA(C6:C20)>0, ROUND(AVERAGE(U6:U20), 1), "-") | V23: =IF(COUNTA(C6:C20)>0, ROUND(AVERAGE(V6:V20), 1), "-") | W23: =IF(COUNTA(C6:C20)>0, ROUND(AVERAGE(W6:W20), 1), "-")
A24: HIGHEST MARKS | D24: =IF(COUNTA(C6:C20)>0, MAX(F6:F20), "-") | G24: =IF(COUNTA(C6:C20)>0, MAX(I6:I20), "-") | J24: =IF(COUNTA(C6:C20)>0, MAX(L6:L20), "-") | M24: =IF(COUNTA(C6:C20)>0, MAX(O6:O20), "-") | P24: =IF(COUNTA(C6:C20)>0, MAX(R6:R20), "-") | S24: =IF(COUNTA(C6:C20)>0, MAX(U6:U20), "-") | V24: =IF(COUNTA(C6:C20)>0, MAX(V6:V20), "-") | W24: =IF(COUNTA(C6:C20)>0, MAX(W6:W20), "-")
A25: LOWEST MARKS | D25: =IF(COUNTA(C6:C20)>0, MIN(F6:F20), "-") | G25: =IF(COUNTA(C6:C20)>0, MIN(I6:I20), "-") | J25: =IF(COUNTA(C6:C20)>0, MIN(L6:L20), "-") | M25: =IF(COUNTA(C6:C20)>0, MIN(O6:O20), "-") | P25: =IF(COUNTA(C6:C20)>0, MIN(R6:R20), "-") | S25: =IF(COUNTA(C6:C20)>0, MIN(U6:U20), "-") | V25: =IF(COUNTA(C6:C20)>0, MIN(V6:V20), "-") | W25: =IF(COUNTA(C6:C20)>0, MIN(W6:W20), "-")
A26: TOTAL PASSED | D26: =COUNTIF(F6:F20, ">=35") | G26: =COUNTIF(I6:I20, ">=35") | J26: =COUNTIF(L6:L20, ">=35") | M26: =COUNTIF(O6:O20, ">=35") | P26: =COUNTIF(R6:R20, ">=35") | S26: =COUNTIF(U6:U20, ">=35") | V26: =COUNTIF(X6:X20, "PASS")
A27: PASS PERCENTAGE (%) | D27: =IF(COUNTA(C6:C20)>0, ROUND((D26/COUNTA(C6:C20))*100, 1), "-") | G27: =IF(COUNTA(C6:C20)>0, ROUND((G26/COUNTA(C6:C20))*100, 1), "-") | J27: =IF(COUNTA(C6:C20)>0, ROUND((J26/COUNTA(C6:C20))*100, 1), "-") | M27: =IF(COUNTA(C6:C20)>0, ROUND((M26/COUNTA(C6:C20))*100, 1), "-") | P27: =IF(COUNTA(C6:C20)>0, ROUND((P26/COUNTA(C6:C20))*100, 1), "-") | S27: =IF(COUNTA(C6:C20)>0, ROUND((S26/COUNTA(C6:C20))*100, 1), "-") | V27: =IF(COUNTA(C6:C20)>0, ROUND((V26/COUNTA(C6:C20))*100, 1), "-")

Sheet Grade 12
A1: EVAL AI (ADEM) — GRADE 12 EXAMINATION MARK SHEET
A2: Academic Year: 2025–2026 | Class: Grade 12 | Total Subjects: 6 | Max Marks: 600 | Pass: Min 35% in each subject
A4: S.No | B4: Roll No | C4: Student Name | D4: BIOLOGY (100) | G4: BIOLOGY (100) | J4: CHEMISTRY (100) | M4: CHEMISTRY (100) | P4: MATHS (100) | S4: PHYSICS (100) | V4: Grand Total (600) | W4: Percentage (%) | X4: Result | Y4: Grade | Z4: Class Rank
D5: Theory (80) | E5: Internal (20) | F5: Total (100) | G5: Theory (80) | H5: Internal (20) | I5: Total (100) | J5: Theory (80) | K5: Internal (20) | L5: Total (100) | M5: Theory (80) | N5: Internal (20) | O5: Total (100) | P5: Theory (80) | Q5: Internal (20) | R5: Total (100) | S5: Theory (80) | T5: Internal (20) | U5: Total (100)
F6: =IF(ISBLANK(C6), "", D6+E6) | I6: =IF(ISBLANK(C6), "", G6+H6) | L6: =IF(ISBLANK(C6), "", J6+K6) | O6: =IF(ISBLANK(C6), "", M6+N6) | R6: =IF(ISBLANK(C6), "", P6+Q6) | U6: =IF(ISBLANK(C6), "", S6+T6) | V6: =IF(ISBLANK(C6), "", F6+I6+L6+O6+R6+U6) | W6: =IF(OR(ISBLANK(C6), V6=""), "", ROUND((V6/600)*100, 1)) | X6: =IF(OR(ISBLANK(C6), V6=""), "", IF(AND(F6>=35, I6>=35, L6>=35, O6>=35, R6>=35, U6>=35), "PASS", "FAIL")) | Y6: =IF(OR(ISBLANK(C6), X6=""), "", IF(X6="FAIL", "F", IF(W6>=90, "A+", IF(W6>=80, "A", IF(W6>=70, "B", IF(W6>=50, "C", "D")))))) | Z6: =IF(OR(ISBLANK(C6), V6=""), "", RANK(V6, $V$6:$V$20))
F7: =IF(ISBLANK(C7), "", D7+E7) | I7: =IF(ISBLANK(C7), "", G7+H7) | L7: =IF(ISBLANK(C7), "", J7+K7) | O7: =IF(ISBLANK(C7), "", M7+N7) | R7: =IF(ISBLANK(C7), "", P7+Q7) | U7: =IF(ISBLANK(C7), "", S7+T7) | V7: =IF(ISBLANK(C7), "", F7+I7+L7+O7+R7+U7) | W7: =IF(OR(ISBLANK(C7), V7=""), "", ROUND((V7/600)*100, 1)) | X7: =IF(OR(ISBLANK(C7), V7=""), "", IF(AND(F7>=35, I7>=35, L7>=35, O7>=35, R7>=35, U7>=35), "PASS", "FAIL")) | Y7: =IF(OR(ISBLANK(C7), X7=""), "", IF(X7="FAIL", "F", IF(W7>=90, "A+", IF(W7>=80, "A", IF(W7>=70, "B", IF(W7>=50, "C", "D")))))) | Z7: =IF(OR(ISBLANK(C7), V7=""), "", RANK(V7, $V$6:$V$20))
F8: =IF(ISBLANK(C8), "", D8+E8) | I8: =IF(ISBLANK(C8), "", G8+H8) | L8: =IF(ISBLANK(C8), "", J8+K8) | O8: =IF(ISBLANK(C8), "", M8+N8) | R8: =IF(ISBLANK(C8), "", P8+Q8) | U8: =IF(ISBLANK(C8), "", S8+T8) | V8: =IF(ISBLANK(C8), "", F8+I8+L8+O8+R8+U8) | W8: =IF(OR(ISBLANK(C8), V8=""), "", ROUND((V8/600)*100, 1)) | X8: =IF(OR(ISBLANK(C8), V8=""), "", IF(AND(F8>=35, I8>=35, L8>=35, O8>=35, R8>=35, U8>=35), "PASS", "FAIL")) | Y8: =IF(OR(ISBLANK(C8), X8=""), "", IF(X8="FAIL", "F", IF(W8>=90, "A+", IF(W8>=80, "A", IF(W8>=70, "B", IF(W8>=50, "C", "D")))))) | Z8: =IF(OR(ISBLANK(C8), V8=""), "", RANK(V8, $V$6:$V$20))
F9: =IF(ISBLANK(C9), "", D9+E9) | I9: =IF(ISBLANK(C9), "", G9+H9) | L9: =IF(ISBLANK(C9), "", J9+K9) | O9: =IF(ISBLANK(C9), "", M9+N9) | R9: =IF(ISBLANK(C9), "", P9+Q9) | U9: =IF(ISBLANK(C9), "", S9+T9) | V9: =IF(ISBLANK(C9), "", F9+I9+L9+O9+R9+U9) | W9: =IF(OR(ISBLANK(C9), V9=""), "", ROUND((V9/600)*100, 1)) | X9: =IF(OR(ISBLANK(C9), V9=""), "", IF(AND(F9>=35, I9>=35, L9>=35, O9>=35, R9>=35, U9>=35), "PASS", "FAIL")) | Y9: =IF(OR(ISBLANK(C9), X9=""), "", IF(X9="FAIL", "F", IF(W9>=90, "A+", IF(W9>=80, "A", IF(W9>=70, "B", IF(W9>=50, "C", "D")))))) | Z9: =IF(OR(ISBLANK(C9), V9=""), "", RANK(V9, $V$6:$V$20))
F10: =IF(ISBLANK(C10), "", D10+E10) | I10: =IF(ISBLANK(C10), "", G10+H10) | L10: =IF(ISBLANK(C10), "", J10+K10) | O10: =IF(ISBLANK(C10), "", M10+N10) | R10: =IF(ISBLANK(C10), "", P10+Q10) | U10: =IF(ISBLANK(C10), "", S10+T10) | V10: =IF(ISBLANK(C10), "", F10+I10+L10+O10+R10+U10) | W10: =IF(OR(ISBLANK(C10), V10=""), "", ROUND((V10/600)*100, 1)) | X10: =IF(OR(ISBLANK(C10), V10=""), "", IF(AND(F10>=35, I10>=35, L10>=35, O10>=35, R10>=35, U10>=35), "PASS", "FAIL")) | Y10: =IF(OR(ISBLANK(C10), X10=""), "", IF(X10="FAIL", "F", IF(W10>=90, "A+", IF(W10>=80, "A", IF(W10>=70, "B", IF(W10>=50, "C", "D")))))) | Z10: =IF(OR(ISBLANK(C10), V10=""), "", RANK(V10, $V$6:$V$20))
F11: =IF(ISBLANK(C11), "", D11+E11) | I11: =IF(ISBLANK(C11), "", G11+H11) | L11: =IF(ISBLANK(C11), "", J11+K11) | O11: =IF(ISBLANK(C11), "", M11+N11) | R11: =IF(ISBLANK(C11), "", P11+Q11) | U11: =IF(ISBLANK(C11), "", S11+T11) | V11: =IF(ISBLANK(C11), "", F11+I11+L11+O11+R11+U11) | W11: =IF(OR(ISBLANK(C11), V11=""), "", ROUND((V11/600)*100, 1)) | X11: =IF(OR(ISBLANK(C11), V11=""), "", IF(AND(F11>=35, I11>=35, L11>=35, O11>=35, R11>=35, U11>=35), "PASS", "FAIL")) | Y11: =IF(OR(ISBLANK(C11), X11=""), "", IF(X11="FAIL", "F", IF(W11>=90, "A+", IF(W11>=80, "A", IF(W11>=70, "B", IF(W11>=50, "C", "D")))))) | Z11: =IF(OR(ISBLANK(C11), V11=""), "", RANK(V11, $V$6:$V$20))
F12: =IF(ISBLANK(C12), "", D12+E12) | I12: =IF(ISBLANK(C12), "", G12+H12) | L12: =IF(ISBLANK(C12), "", J12+K12) | O12: =IF(ISBLANK(C12), "", M12+N12) | R12: =IF(ISBLANK(C12), "", P12+Q12) | U12: =IF(ISBLANK(C12), "", S12+T12) | V12: =IF(ISBLANK(C12), "", F12+I12+L12+O12+R12+U12) | W12: =IF(OR(ISBLANK(C12), V12=""), "", ROUND((V12/600)*100, 1)) | X12: =IF(OR(ISBLANK(C12), V12=""), "", IF(AND(F12>=35, I12>=35, L12>=35, O12>=35, R12>=35, U12>=35), "PASS", "FAIL")) | Y12: =IF(OR(ISBLANK(C12), X12=""), "", IF(X12="FAIL", "F", IF(W12>=90, "A+", IF(W12>=80, "A", IF(W12>=70, "B", IF(W12>=50, "C", "D")))))) | Z12: =IF(OR(ISBLANK(C12), V12=""), "", RANK(V12, $V$6:$V$20))
F13: =IF(ISBLANK(C13), "", D13+E13) | I13: =IF(ISBLANK(C13), "", G13+H13) | L13: =IF(ISBLANK(C13), "", J13+K13) | O13: =IF(ISBLANK(C13), "", M13+N13) | R13: =IF(ISBLANK(C13), "", P13+Q13) | U13: =IF(ISBLANK(C13), "", S13+T13) | V13: =IF(ISBLANK(C13), "", F13+I13+L13+O13+R13+U13) | W13: =IF(OR(ISBLANK(C13), V13=""), "", ROUND((V13/600)*100, 1)) | X13: =IF(OR(ISBLANK(C13), V13=""), "", IF(AND(F13>=35, I13>=35, L13>=35, O13>=35, R13>=35, U13>=35), "PASS", "FAIL")) | Y13: =IF(OR(ISBLANK(C13), X13=""), "", IF(X13="FAIL", "F", IF(W13>=90, "A+", IF(W13>=80, "A", IF(W13>=70, "B", IF(W13>=50, "C", "D")))))) | Z13: =IF(OR(ISBLANK(C13), V13=""), "", RANK(V13, $V$6:$V$20))
F14: =IF(ISBLANK(C14), "", D14+E14) | I14: =IF(ISBLANK(C14), "", G14+H14) | L14: =IF(ISBLANK(C14), "", J14+K14) | O14: =IF(ISBLANK(C14), "", M14+N14) | R14: =IF(ISBLANK(C14), "", P14+Q14) | U14: =IF(ISBLANK(C14), "", S14+T14) | V14: =IF(ISBLANK(C14), "", F14+I14+L14+O14+R14+U14) | W14: =IF(OR(ISBLANK(C14), V14=""), "", ROUND((V14/600)*100, 1)) | X14: =IF(OR(ISBLANK(C14), V14=""), "", IF(AND(F14>=35, I14>=35, L14>=35, O14>=35, R14>=35, U14>=35), "PASS", "FAIL")) | Y14: =IF(OR(ISBLANK(C14), X14=""), "", IF(X14="FAIL", "F", IF(W14>=90, "A+", IF(W14>=80, "A", IF(W14>=70, "B", IF(W14>=50, "C", "D")))))) | Z14: =IF(OR(ISBLANK(C14), V14=""), "", RANK(V14, $V$6:$V$20))
F15: =IF(ISBLANK(C15), "", D15+E15) | I15: =IF(ISBLANK(C15), "", G15+H15) | L15: =IF(ISBLANK(C15), "", J15+K15) | O15: =IF(ISBLANK(C15), "", M15+N15) | R15: =IF(ISBLANK(C15), "", P15+Q15) | U15: =IF(ISBLANK(C15), "", S15+T15) | V15: =IF(ISBLANK(C15), "", F15+I15+L15+O15+R15+U15) | W15: =IF(OR(ISBLANK(C15), V15=""), "", ROUND((V15/600)*100, 1)) | X15: =IF(OR(ISBLANK(C15), V15=""), "", IF(AND(F15>=35, I15>=35, L15>=35, O15>=35, R15>=35, U15>=35), "PASS", "FAIL")) | Y15: =IF(OR(ISBLANK(C15), X15=""), "", IF(X15="FAIL", "F", IF(W15>=90, "A+", IF(W15>=80, "A", IF(W15>=70, "B", IF(W15>=50, "C", "D")))))) | Z15: =IF(OR(ISBLANK(C15), V15=""), "", RANK(V15, $V$6:$V$20))
F16: =IF(ISBLANK(C16), "", D16+E16) | I16: =IF(ISBLANK(C16), "", G16+H16) | L16: =IF(ISBLANK(C16), "", J16+K16) | O16: =IF(ISBLANK(C16), "", M16+N16) | R16: =IF(ISBLANK(C16), "", P16+Q16) | U16: =IF(ISBLANK(C16), "", S16+T16) | V16: =IF(ISBLANK(C16), "", F16+I16+L16+O16+R16+U16) | W16: =IF(OR(ISBLANK(C16), V16=""), "", ROUND((V16/600)*100, 1)) | X16: =IF(OR(ISBLANK(C16), V16=""), "", IF(AND(F16>=35, I16>=35, L16>=35, O16>=35, R16>=35, U16>=35), "PASS", "FAIL")) | Y16: =IF(OR(ISBLANK(C16), X16=""), "", IF(X16="FAIL", "F", IF(W16>=90, "A+", IF(W16>=80, "A", IF(W16>=70, "B", IF(W16>=50, "C", "D")))))) | Z16: =IF(OR(ISBLANK(C16), V16=""), "", RANK(V16, $V$6:$V$20))
F17: =IF(ISBLANK(C17), "", D17+E17) | I17: =IF(ISBLANK(C17), "", G17+H17) | L17: =IF(ISBLANK(C17), "", J17+K17) | O17: =IF(ISBLANK(C17), "", M17+N17) | R17: =IF(ISBLANK(C17), "", P17+Q17) | U17: =IF(ISBLANK(C17), "", S17+T17) | V17: =IF(ISBLANK(C17), "", F17+I17+L17+O17+R17+U17) | W17: =IF(OR(ISBLANK(C17), V17=""), "", ROUND((V17/600)*100, 1)) | X17: =IF(OR(ISBLANK(C17), V17=""), "", IF(AND(F17>=35, I17>=35, L17>=35, O17>=35, R17>=35, U17>=35), "PASS", "FAIL")) | Y17: =IF(OR(ISBLANK(C17), X17=""), "", IF(X17="FAIL", "F", IF(W17>=90, "A+", IF(W17>=80, "A", IF(W17>=70, "B", IF(W17>=50, "C", "D")))))) | Z17: =IF(OR(ISBLANK(C17), V17=""), "", RANK(V17, $V$6:$V$20))
... F20: =IF(ISBLANK(C20), "", D20+E20) | I20: =IF(ISBLANK(C20), "", G20+H20) | L20: =IF(ISBLANK(C20), "", J20+K20) | O20: =IF(ISBLANK(C20), "", M20+N20) | R20: =IF(ISBLANK(C20), "", P20+Q20) | U20: =IF(ISBLANK(C20), "", S20+T20) | V20: =IF(ISBLANK(C20), "", F20+I20+L20+O20+R20+U20) | W20: =IF(OR(ISBLANK(C20), V20=""), "", ROUND((V20/600)*100, 1)) | X20: =IF(OR(ISBLANK(C20), V20=""), "", IF(AND(F20>=35, I20>=35, L20>=35, O20>=35, R20>=35, U20>=35), "PASS", "FAIL")) | Y20: =IF(OR(ISBLANK(C20), X20=""), "", IF(X20="FAIL", "F", IF(W20>=90, "A+", IF(W20>=80, "A", IF(W20>=70, "B", IF(W20>=50, "C", "D")))))) | Z20: =IF(OR(ISBLANK(C20), V20=""), "", RANK(V20, $V$6:$V$20))
A23: CLASS AVERAGE | D23: =IF(COUNTA(C6:C20)>0, ROUND(AVERAGE(F6:F20), 1), "-") | G23: =IF(COUNTA(C6:C20)>0, ROUND(AVERAGE(I6:I20), 1), "-") | J23: =IF(COUNTA(C6:C20)>0, ROUND(AVERAGE(L6:L20), 1), "-") | M23: =IF(COUNTA(C6:C20)>0, ROUND(AVERAGE(O6:O20), 1), "-") | P23: =IF(COUNTA(C6:C20)>0, ROUND(AVERAGE(R6:R20), 1), "-") | S23: =IF(COUNTA(C6:C20)>0, ROUND(AVERAGE(U6:U20), 1), "-") | V23: =IF(COUNTA(C6:C20)>0, ROUND(AVERAGE(V6:V20), 1), "-") | W23: =IF(COUNTA(C6:C20)>0, ROUND(AVERAGE(W6:W20), 1), "-")
A24: HIGHEST MARKS | D24: =IF(COUNTA(C6:C20)>0, MAX(F6:F20), "-") | G24: =IF(COUNTA(C6:C20)>0, MAX(I6:I20), "-") | J24: =IF(COUNTA(C6:C20)>0, MAX(L6:L20), "-") | M24: =IF(COUNTA(C6:C20)>0, MAX(O6:O20), "-") | P24: =IF(COUNTA(C6:C20)>0, MAX(R6:R20), "-") | S24: =IF(COUNTA(C6:C20)>0, MAX(U6:U20), "-") | V24: =IF(COUNTA(C6:C20)>0, MAX(V6:V20), "-") | W24: =IF(COUNTA(C6:C20)>0, MAX(W6:W20), "-")
A25: LOWEST MARKS | D25: =IF(COUNTA(C6:C20)>0, MIN(F6:F20), "-") | G25: =IF(COUNTA(C6:C20)>0, MIN(I6:I20), "-") | J25: =IF(COUNTA(C6:C20)>0, MIN(L6:L20), "-") | M25: =IF(COUNTA(C6:C20)>0, MIN(O6:O20), "-") | P25: =IF(COUNTA(C6:C20)>0, MIN(R6:R20), "-") | S25: =IF(COUNTA(C6:C20)>0, MIN(U6:U20), "-") | V25: =IF(COUNTA(C6:C20)>0, MIN(V6:V20), "-") | W25: =IF(COUNTA(C6:C20)>0, MIN(W6:W20), "-")
A26: TOTAL PASSED | D26: =COUNTIF(F6:F20, ">=35") | G26: =COUNTIF(I6:I20, ">=35") | J26: =COUNTIF(L6:L20, ">=35") | M26: =COUNTIF(O6:O20, ">=35") | P26: =COUNTIF(R6:R20, ">=35") | S26: =COUNTIF(U6:U20, ">=35") | V26: =COUNTIF(X6:X20, "PASS")
A27: PASS PERCENTAGE (%) | D27: =IF(COUNTA(C6:C20)>0, ROUND((D26/COUNTA(C6:C20))*100, 1), "-") | G27: =IF(COUNTA(C6:C20)>0, ROUND((G26/COUNTA(C6:C20))*100, 1), "-") | J27: =IF(COUNTA(C6:C20)>0, ROUND((J26/COUNTA(C6:C20))*100, 1), "-") | M27: =IF(COUNTA(C6:C20)>0, ROUND((M26/COUNTA(C6:C20))*100, 1), "-") | P27: =IF(COUNTA(C6:C20)>0, ROUND((P26/COUNTA(C6:C20))*100, 1), "-") | S27: =IF(COUNTA(C6:C20)>0, ROUND((S26/COUNTA(C6:C20))*100, 1), "-") | V27: =IF(COUNTA(C6:C20)>0, ROUND((V26/COUNTA(C6:C20))*100, 1), "-")

Sheet Grade 9
A1: EVAL AI (ADEM) — GRADE 9 EXAMINATION MARK SHEET
A2: Academic Year: 2025–2026 | Class: Grade 9 | Total Subjects: 6 | Max Marks: 600 | Pass: Min 35% in each subject
A4: S.No | B4: Roll No | C4: Student Name | D4: BIOLOGY (100) | G4: BIOLOGY (100) | J4: CHEMISTRY (100) | M4: CHEMISTRY (100) | P4: MATHS (100) | S4: PHYSICS (100) | V4: Grand Total (600) | W4: Percentage (%) | X4: Result | Y4: Grade | Z4: Class Rank
D5: Theory (80) | E5: Internal (20) | F5: Total (100) | G5: Theory (80) | H5: Internal (20) | I5: Total (100) | J5: Theory (80) | K5: Internal (20) | L5: Total (100) | M5: Theory (80) | N5: Internal (20) | O5: Total (100) | P5: Theory (80) | Q5: Internal (20) | R5: Total (100) | S5: Theory (80) | T5: Internal (20) | U5: Total (100)
F6: =IF(ISBLANK(C6), "", D6+E6) | I6: =IF(ISBLANK(C6), "", G6+H6) | L6: =IF(ISBLANK(C6), "", J6+K6) | O6: =IF(ISBLANK(C6), "", M6+N6) | R6: =IF(ISBLANK(C6), "", P6+Q6) | U6: =IF(ISBLANK(C6), "", S6+T6) | V6: =IF(ISBLANK(C6), "", F6+I6+L6+O6+R6+U6) | W6: =IF(OR(ISBLANK(C6), V6=""), "", ROUND((V6/600)*100, 1)) | X6: =IF(OR(ISBLANK(C6), V6=""), "", IF(AND(F6>=35, I6>=35, L6>=35, O6>=35, R6>=35, U6>=35), "PASS", "FAIL")) | Y6: =IF(OR(ISBLANK(C6), X6=""), "", IF(X6="FAIL", "F", IF(W6>=90, "A+", IF(W6>=80, "A", IF(W6>=70, "B", IF(W6>=50, "C", "D")))))) | Z6: =IF(OR(ISBLANK(C6), V6=""), "", RANK(V6, $V$6:$V$20))
F7: =IF(ISBLANK(C7), "", D7+E7) | I7: =IF(ISBLANK(C7), "", G7+H7) | L7: =IF(ISBLANK(C7), "", J7+K7) | O7: =IF(ISBLANK(C7), "", M7+N7) | R7: =IF(ISBLANK(C7), "", P7+Q7) | U7: =IF(ISBLANK(C7), "", S7+T7) | V7: =IF(ISBLANK(C7), "", F7+I7+L7+O7+R7+U7) | W7: =IF(OR(ISBLANK(C7), V7=""), "", ROUND((V7/600)*100, 1)) | X7: =IF(OR(ISBLANK(C7), V7=""), "", IF(AND(F7>=35, I7>=35, L7>=35, O7>=35, R7>=35, U7>=35), "PASS", "FAIL")) | Y7: =IF(OR(ISBLANK(C7), X7=""), "", IF(X7="FAIL", "F", IF(W7>=90, "A+", IF(W7>=80, "A", IF(W7>=70, "B", IF(W7>=50, "C", "D")))))) | Z7: =IF(OR(ISBLANK(C7), V7=""), "", RANK(V7, $V$6:$V$20))
F8: =IF(ISBLANK(C8), "", D8+E8) | I8: =IF(ISBLANK(C8), "", G8+H8) | L8: =IF(ISBLANK(C8), "", J8+K8) | O8: =IF(ISBLANK(C8), "", M8+N8) | R8: =IF(ISBLANK(C8), "", P8+Q8) | U8: =IF(ISBLANK(C8), "", S8+T8) | V8: =IF(ISBLANK(C8), "", F8+I8+L8+O8+R8+U8) | W8: =IF(OR(ISBLANK(C8), V8=""), "", ROUND((V8/600)*100, 1)) | X8: =IF(OR(ISBLANK(C8), V8=""), "", IF(AND(F8>=35, I8>=35, L8>=35, O8>=35, R8>=35, U8>=35), "PASS", "FAIL")) | Y8: =IF(OR(ISBLANK(C8), X8=""), "", IF(X8="FAIL", "F", IF(W8>=90, "A+", IF(W8>=80, "A", IF(W8>=70, "B", IF(W8>=50, "C", "D")))))) | Z8: =IF(OR(ISBLANK(C8), V8=""), "", RANK(V8, $V$6:$V$20))
F9: =IF(ISBLANK(C9), "", D9+E9) | I9: =IF(ISBLANK(C9), "", G9+H9) | L9: =IF(ISBLANK(C9), "", J9+K9) | O9: =IF(ISBLANK(C9), "", M9+N9) | R9: =IF(ISBLANK(C9), "", P9+Q9) | U9: =IF(ISBLANK(C9), "", S9+T9) | V9: =IF(ISBLANK(C9), "", F9+I9+L9+O9+R9+U9) | W9: =IF(OR(ISBLANK(C9), V9=""), "", ROUND((V9/600)*100, 1)) | X9: =IF(OR(ISBLANK(C9), V9=""), "", IF(AND(F9>=35, I9>=35, L9>=35, O9>=35, R9>=35, U9>=35), "PASS", "FAIL")) | Y9: =IF(OR(ISBLANK(C9), X9=""), "", IF(X9="FAIL", "F", IF(W9>=90, "A+", IF(W9>=80, "A", IF(W9>=70, "B", IF(W9>=50, "C", "D")))))) | Z9: =IF(OR(ISBLANK(C9), V9=""), "", RANK(V9, $V$6:$V$20))
F10: =IF(ISBLANK(C10), "", D10+E10) | I10: =IF(ISBLANK(C10), "", G10+H10) | L10: =IF(ISBLANK(C10), "", J10+K10) | O10: =IF(ISBLANK(C10), "", M10+N10) | R10: =IF(ISBLANK(C10), "", P10+Q10) | U10: =IF(ISBLANK(C10), "", S10+T10) | V10: =IF(ISBLANK(C10), "", F10+I10+L10+O10+R10+U10) | W10: =IF(OR(ISBLANK(C10), V10=""), "", ROUND((V10/600)*100, 1)) | X10: =IF(OR(ISBLANK(C10), V10=""), "", IF(AND(F10>=35, I10>=35, L10>=35, O10>=35, R10>=35, U10>=35), "PASS", "FAIL")) | Y10: =IF(OR(ISBLANK(C10), X10=""), "", IF(X10="FAIL", "F", IF(W10>=90, "A+", IF(W10>=80, "A", IF(W10>=70, "B", IF(W10>=50, "C", "D")))))) | Z10: =IF(OR(ISBLANK(C10), V10=""), "", RANK(V10, $V$6:$V$20))
F11: =IF(ISBLANK(C11), "", D11+E11) | I11: =IF(ISBLANK(C11), "", G11+H11) | L11: =IF(ISBLANK(C11), "", J11+K11) | O11: =IF(ISBLANK(C11), "", M11+N11) | R11: =IF(ISBLANK(C11), "", P11+Q11) | U11: =IF(ISBLANK(C11), "", S11+T11) | V11: =IF(ISBLANK(C11), "", F11+I11+L11+O11+R11+U11) | W11: =IF(OR(ISBLANK(C11), V11=""), "", ROUND((V11/600)*100, 1)) | X11: =IF(OR(ISBLANK(C11), V11=""), "", IF(AND(F11>=35, I11>=35, L11>=35, O11>=35, R11>=35, U11>=35), "PASS", "FAIL")) | Y11: =IF(OR(ISBLANK(C11), X11=""), "", IF(X11="FAIL", "F", IF(W11>=90, "A+", IF(W11>=80, "A", IF(W11>=70, "B", IF(W11>=50, "C", "D")))))) | Z11: =IF(OR(ISBLANK(C11), V11=""), "", RANK(V11, $V$6:$V$20))
F12: =IF(ISBLANK(C12), "", D12+E12) | I12: =IF(ISBLANK(C12), "", G12+H12) | L12: =IF(ISBLANK(C12), "", J12+K12) | O12: =IF(ISBLANK(C12), "", M12+N12) | R12: =IF(ISBLANK(C12), "", P12+Q12) | U12: =IF(ISBLANK(C12), "", S12+T12) | V12: =IF(ISBLANK(C12), "", F12+I12+L12+O12+R12+U12) | W12: =IF(OR(ISBLANK(C12), V12=""), "", ROUND((V12/600)*100, 1)) | X12: =IF(OR(ISBLANK(C12), V12=""), "", IF(AND(F12>=35, I12>=35, L12>=35, O12>=35, R12>=35, U12>=35), "PASS", "FAIL")) | Y12: =IF(OR(ISBLANK(C12), X12=""), "", IF(X12="FAIL", "F", IF(W12>=90, "A+", IF(W12>=80, "A", IF(W12>=70, "B", IF(W12>=50, "C", "D")))))) | Z12: =IF(OR(ISBLANK(C12), V12=""), "", RANK(V12, $V$6:$V$20))
F13: =IF(ISBLANK(C13), "", D13+E13) | I13: =IF(ISBLANK(C13), "", G13+H13) | L13: =IF(ISBLANK(C13), "", J13+K13) | O13: =IF(ISBLANK(C13), "", M13+N13) | R13: =IF(ISBLANK(C13), "", P13+Q13) | U13: =IF(ISBLANK(C13), "", S13+T13) | V13: =IF(ISBLANK(C13), "", F13+I13+L13+O13+R13+U13) | W13: =IF(OR(ISBLANK(C13), V13=""), "", ROUND((V13/600)*100, 1)) | X13: =IF(OR(ISBLANK(C13), V13=""), "", IF(AND(F13>=35, I13>=35, L13>=35, O13>=35, R13>=35, U13>=35), "PASS", "FAIL")) | Y13: =IF(OR(ISBLANK(C13), X13=""), "", IF(X13="FAIL", "F", IF(W13>=90, "A+", IF(W13>=80, "A", IF(W13>=70, "B", IF(W13>=50, "C", "D")))))) | Z13: =IF(OR(ISBLANK(C13), V13=""), "", RANK(V13, $V$6:$V$20))
F14: =IF(ISBLANK(C14), "", D14+E14) | I14: =IF(ISBLANK(C14), "", G14+H14) | L14: =IF(ISBLANK(C14), "", J14+K14) | O14: =IF(ISBLANK(C14), "", M14+N14) | R14: =IF(ISBLANK(C14), "", P14+Q14) | U14: =IF(ISBLANK(C14), "", S14+T14) | V14: =IF(ISBLANK(C14), "", F14+I14+L14+O14+R14+U14) | W14: =IF(OR(ISBLANK(C14), V14=""), "", ROUND((V14/600)*100, 1)) | X14: =IF(OR(ISBLANK(C14), V14=""), "", IF(AND(F14>=35, I14>=35, L14>=35, O14>=35, R14>=35, U14>=35), "PASS", "FAIL")) | Y14: =IF(OR(ISBLANK(C14), X14=""), "", IF(X14="FAIL", "F", IF(W14>=90, "A+", IF(W14>=80, "A", IF(W14>=70, "B", IF(W14>=50, "C", "D")))))) | Z14: =IF(OR(ISBLANK(C14), V14=""), "", RANK(V14, $V$6:$V$20))
F15: =IF(ISBLANK(C15), "", D15+E15) | I15: =IF(ISBLANK(C15), "", G15+H15) | L15: =IF(ISBLANK(C15), "", J15+K15) | O15: =IF(ISBLANK(C15), "", M15+N15) | R15: =IF(ISBLANK(C15), "", P15+Q15) | U15: =IF(ISBLANK(C15), "", S15+T15) | V15: =IF(ISBLANK(C15), "", F15+I15+L15+O15+R15+U15) | W15: =IF(OR(ISBLANK(C15), V15=""), "", ROUND((V15/600)*100, 1)) | X15: =IF(OR(ISBLANK(C15), V15=""), "", IF(AND(F15>=35, I15>=35, L15>=35, O15>=35, R15>=35, U15>=35), "PASS", "FAIL")) | Y15: =IF(OR(ISBLANK(C15), X15=""), "", IF(X15="FAIL", "F", IF(W15>=90, "A+", IF(W15>=80, "A", IF(W15>=70, "B", IF(W15>=50, "C", "D")))))) | Z15: =IF(OR(ISBLANK(C15), V15=""), "", RANK(V15, $V$6:$V$20))
F16: =IF(ISBLANK(C16), "", D16+E16) | I16: =IF(ISBLANK(C16), "", G16+H16) | L16: =IF(ISBLANK(C16), "", J16+K16) | O16: =IF(ISBLANK(C16), "", M16+N16) | R16: =IF(ISBLANK(C16), "", P16+Q16) | U16: =IF(ISBLANK(C16), "", S16+T16) | V16: =IF(ISBLANK(C16), "", F16+I16+L16+O16+R16+U16) | W16: =IF(OR(ISBLANK(C16), V16=""), "", ROUND((V16/600)*100, 1)) | X16: =IF(OR(ISBLANK(C16), V16=""), "", IF(AND(F16>=35, I16>=35, L16>=35, O16>=35, R16>=35, U16>=35), "PASS", "FAIL")) | Y16: =IF(OR(ISBLANK(C16), X16=""), "", IF(X16="FAIL", "F", IF(W16>=90, "A+", IF(W16>=80, "A", IF(W16>=70, "B", IF(W16>=50, "C", "D")))))) | Z16: =IF(OR(ISBLANK(C16), V16=""), "", RANK(V16, $V$6:$V$20))
F17: =IF(ISBLANK(C17), "", D17+E17) | I17: =IF(ISBLANK(C17), "", G17+H17) | L17: =IF(ISBLANK(C17), "", J17+K17) | O17: =IF(ISBLANK(C17), "", M17+N17) | R17: =IF(ISBLANK(C17), "", P17+Q17) | U17: =IF(ISBLANK(C17), "", S17+T17) | V17: =IF(ISBLANK(C17), "", F17+I17+L17+O17+R17+U17) | W17: =IF(OR(ISBLANK(C17), V17=""), "", ROUND((V17/600)*100, 1)) | X17: =IF(OR(ISBLANK(C17), V17=""), "", IF(AND(F17>=35, I17>=35, L17>=35, O17>=35, R17>=35, U17>=35), "PASS", "FAIL")) | Y17: =IF(OR(ISBLANK(C17), X17=""), "", IF(X17="FAIL", "F", IF(W17>=90, "A+", IF(W17>=80, "A", IF(W17>=70, "B", IF(W17>=50, "C", "D")))))) | Z17: =IF(OR(ISBLANK(C17), V17=""), "", RANK(V17, $V$6:$V$20))
... F20: =IF(ISBLANK(C20), "", D20+E20) | I20: =IF(ISBLANK(C20), "", G20+H20) | L20: =IF(ISBLANK(C20), "", J20+K20) | O20: =IF(ISBLANK(C20), "", M20+N20) | R20: =IF(ISBLANK(C20), "", P20+Q20) | U20: =IF(ISBLANK(C20), "", S20+T20) | V20: =IF(ISBLANK(C20), "", F20+I20+L20+O20+R20+U20) | W20: =IF(OR(ISBLANK(C20), V20=""), "", ROUND((V20/600)*100, 1)) | X20: =IF(OR(ISBLANK(C20), V20=""), "", IF(AND(F20>=35, I20>=35, L20>=35, O20>=35, R20>=35, U20>=35), "PASS", "FAIL")) | Y20: =IF(OR(ISBLANK(C20), X20=""), "", IF(X20="FAIL", "F", IF(W20>=90, "A+", IF(W20>=80, "A", IF(W20>=70, "B", IF(W20>=50, "C", "D")))))) | Z20: =IF(OR(ISBLANK(C20), V20=""), "", RANK(V20, $V$6:$V$20))
A23: CLASS AVERAGE | D23: =IF(COUNTA(C6:C20)>0, ROUND(AVERAGE(F6:F20), 1), "-") | G23: =IF(COUNTA(C6:C20)>0, ROUND(AVERAGE(I6:I20), 1), "-") | J23: =IF(COUNTA(C6:C20)>0, ROUND(AVERAGE(L6:L20), 1), "-") | M23: =IF(COUNTA(C6:C20)>0, ROUND(AVERAGE(O6:O20), 1), "-") | P23: =IF(COUNTA(C6:C20)>0, ROUND(AVERAGE(R6:R20), 1), "-") | S23: =IF(COUNTA(C6:C20)>0, ROUND(AVERAGE(U6:U20), 1), "-") | V23: =IF(COUNTA(C6:C20)>0, ROUND(AVERAGE(V6:V20), 1), "-") | W23: =IF(COUNTA(C6:C20)>0, ROUND(AVERAGE(W6:W20), 1), "-")
A24: HIGHEST MARKS | D24: =IF(COUNTA(C6:C20)>0, MAX(F6:F20), "-") | G24: =IF(COUNTA(C6:C20)>0, MAX(I6:I20), "-") | J24: =IF(COUNTA(C6:C20)>0, MAX(L6:L20), "-") | M24: =IF(COUNTA(C6:C20)>0, MAX(O6:O20), "-") | P24: =IF(COUNTA(C6:C20)>0, MAX(R6:R20), "-") | S24: =IF(COUNTA(C6:C20)>0, MAX(U6:U20), "-") | V24: =IF(COUNTA(C6:C20)>0, MAX(V6:V20), "-") | W24: =IF(COUNTA(C6:C20)>0, MAX(W6:W20), "-")
A25: LOWEST MARKS | D25: =IF(COUNTA(C6:C20)>0, MIN(F6:F20), "-") | G25: =IF(COUNTA(C6:C20)>0, MIN(I6:I20), "-") | J25: =IF(COUNTA(C6:C20)>0, MIN(L6:L20), "-") | M25: =IF(COUNTA(C6:C20)>0, MIN(O6:O20), "-") | P25: =IF(COUNTA(C6:C20)>0, MIN(R6:R20), "-") | S25: =IF(COUNTA(C6:C20)>0, MIN(U6:U20), "-") | V25: =IF(COUNTA(C6:C20)>0, MIN(V6:V20), "-") | W25: =IF(COUNTA(C6:C20)>0, MIN(W6:W20), "-")
A26: TOTAL PASSED | D26: =COUNTIF(F6:F20, ">=35") | G26: =COUNTIF(I6:I20, ">=35") | J26: =COUNTIF(L6:L20, ">=35") | M26: =COUNTIF(O6:O20, ">=35") | P26: =COUNTIF(R6:R20, ">=35") | S26: =COUNTIF(U6:U20, ">=35") | V26: =COUNTIF(X6:X20, "PASS")
A27: PASS PERCENTAGE (%) | D27: =IF(COUNTA(C6:C20)>0, ROUND((D26/COUNTA(C6:C20))*100, 1), "-") | G27: =IF(COUNTA(C6:C20)>0, ROUND((G26/COUNTA(C6:C20))*100, 1), "-") | J27: =IF(COUNTA(C6:C20)>0, ROUND((J26/COUNTA(C6:C20))*100, 1), "-") | M27: =IF(COUNTA(C6:C20)>0, ROUND((M26/COUNTA(C6:C20))*100, 1), "-") | P27: =IF(COUNTA(C6:C20)>0, ROUND((P26/COUNTA(C6:C20))*100, 1), "-") | S27: =IF(COUNTA(C6:C20)>0, ROUND((S26/COUNTA(C6:C20))*100, 1), "-") | V27: =IF(COUNTA(C6:C20)>0, ROUND((V26/COUNTA(C6:C20))*100, 1), "-")

Sheet Grade 9_2
A1: EVAL AI (ADEM) — GRADE 9 EXAMINATION MARK SHEET
A2: Academic Year: 2025–2026 | Class: Grade 9 | Total Subjects: 6 | Max Marks: 600 | Pass: Min 35% in each subject
A4: S.No | B4: Roll No | C4: Student Name | D4: BIOLOGY (100) | G4: BIOLOGY (100) | J4: CHEMISTRY (100) | M4: CHEMISTRY (100) | P4: MATHS (100) | S4: PHYSICS (100) | V4: Grand Total (600) | W4: Percentage (%) | X4: Result | Y4: Grade | Z4: Class Rank
D5: Theory (80) | E5: Internal (20) | F5: Total (100) | G5: Theory (80) | H5: Internal (20) | I5: Total (100) | J5: Theory (80) | K5: Internal (20) | L5: Total (100) | M5: Theory (80) | N5: Internal (20) | O5: Total (100) | P5: Theory (80) | Q5: Internal (20) | R5: Total (100) | S5: Theory (80) | T5: Internal (20) | U5: Total (100)
F6: =IF(ISBLANK(C6), "", D6+E6) | I6: =IF(ISBLANK(C6), "", G6+H6) | L6: =IF(ISBLANK(C6), "", J6+K6) | O6: =IF(ISBLANK(C6), "", M6+N6) | R6: =IF(ISBLANK(C6), "", P6+Q6) | U6: =IF(ISBLANK(C6), "", S6+T6) | V6: =IF(ISBLANK(C6), "", F6+I6+L6+O6+R6+U6) | W6: =IF(OR(ISBLANK(C6), V6=""), "", ROUND((V6/600)*100, 1)) | X6: =IF(OR(ISBLANK(C6), V6=""), "", IF(AND(F6>=35, I6>=35, L6>=35, O6>=35, R6>=35, U6>=35), "PASS", "FAIL")) | Y6: =IF(OR(ISBLANK(C6), X6=""), "", IF(X6="FAIL", "F", IF(W6>=90, "A+", IF(W6>=80, "A", IF(W6>=70, "B", IF(W6>=50, "C", "D")))))) | Z6: =IF(OR(ISBLANK(C6), V6=""), "", RANK(V6, $V$6:$V$20))
